Workbook
Name AlertThreshold: Control!$B$8
Name AsOfDate: Control!$B$6
Name CalcInWeek: Calc!$D$5:$D$198
Name FleetActionablePct: Prediction!$I$8
Name FleetPrecisionPct: Prediction!$F$8
Name HangarHoursPerWeek: Control!$B$7
Name SourceFolder: Control!$B$5
Name ValidationRange: Validation!$E$6:$E$21
Name ValidationSummary: Validation!$C$23

Sheet README
A1: MERIDIAN UAV SERVICES -- FLEET MAINTENANCE CONTROL
A3: THE QUESTION
A4: Is this fleet inside its maintenance intervals? Both answers on the Dashboard are correct. They are the same components, the same intervals and the same day, and they differ only in the unit the interval is measured in.
A6: HOW TO READ IT
A7: Control Four cells. Two of them change the answer: hangar hours per week, and the alert threshold.
A8: Dashboard The headline comparison, computed here in Excel from the component extract. Nothing on it is pasted.
A9: Bases The cut the fleet average hides. StressRatio explains the rest of the row.
A10: Action Queue What to do this week, cut at the capacity on Control.
A11: Prediction What the alarm is worth at the threshold on Control -- accuracy and usefulness side by side.
A12: Validation Sixteen figures recomputed in Excel and reconciled against SQL.
A13: Data_* The extracts, loaded through Power Query and kept complete.
A15: TRY THIS
... A25: Meridian UAV Services is a fictional UAV operator. All data is synthetic and generated by the scripts in the sql\ folder. Degradation behaviour is modelled on publicly described characteristics of rotating machinery. No confidential data is used and no claim is made about any real aircraft, operator or manufacturer.

Sheet Dashboard
A1: IS THIS FLEET INSIDE ITS MAINTENANCE INTERVALS?
A2: ="Reporting date " & AsOfDate & " | both figures below are computed in this workbook from the component extract, not copied from SQL." -> Reporting date 46295 | both figures below are computed in this workbook from the component extract, not copied from SQL.
A4: THE SAME COMPONENTS, THE SAME INTERVALS, THE SAME DAY
A5: MEASURE | B5: VALUE | C5: WHAT IT ACTUALLY MEANS
A6: Compliant on FLIGHT HOURS | B6: =COUNTIFS(tWear[IsOverdueByHours],0)/COUNTA(tWear[InstallKey]) -> 0.99725275 | C6: What the maintenance system reports. The hour meter is what it enforces against.
A7: Compliant on STRESS HOURS | B7: =COUNTIFS(tWear[IsOverdueByStress],0)/COUNTA(tWear[InstallKey]) -> 0.68406593 | C7: The same interval measured in the unit the wear actually accrues in.
A8: The gap | B8: =B6-B7 -> 0.31318681 | C8: Components past due that no current report shows.
A10: An hour is not a unit of wear. An hour of mountain survey at 22kg and an hour of coastal survey at 12kg damage a rotor bearing by very different amounts, and an hour of circuit training produces ten landings where cargo relay produces one. The interval is enforced in hours because that is what the hour meter produces.
A13: WHAT THAT MEANS IN COMPONENTS
A14: MEASURE | B14: COUNT | C14: NOTE
A15: Components fitted | B15: =COUNTA(tWear[InstallKey]) -> 364 | C15: The population every percentage above is over.
A16: Past due on stress, inside hour limit | B16: =COUNTIFS(tWear[IsHiddenOverdue],1) -> 114 | C16: Invisible to every report the operator currently runs.
A17: ...of which flight-critical | B17: =COUNTIFS(tWear[IsHiddenOverdue],1,tWear[Criticality],"FlightCritical") -> 89 | C17: Failure grounds the aircraft.
A18: Past due on stress (all) | B18: =COUNTIFS(tWear[IsOverdueByStress],1) -> 115 | C18: Including those the hour meter can already see.
A19: Past due on flight hours | B19: =COUNTIFS(tWear[IsOverdueByHours],1) -> 1 | C19: What the maintenance system is chasing today.
A21: FLEET SCORECARD -- against the targets in Ref_FleetTargets
A22: METRIC | B22: VALUE | C22: TARGET | D22: WARN | E22: STATUS
A23: StressCompliancePct | B23: =INDEX(tKPI[MetricValue],MATCH(A23,tKPI[MetricName],0)) -> 68.41 | C23: =INDEX(tTargets[TargetValue],MATCH(A23,tTargets[MetricName],0)) -> 100 | D23: =INDEX(tTargets[WarningValue],MATCH(A23,tTargets[MetricName],0)) -> 95 | E23: =IF(INDEX(tTargets[Direction],MATCH(A23,tTargets[MetricName],0))="HigherBetter",IF(B23>=C23,"Green",IF(B23>=D23,"Amber","Red")),IF(B23<=C23,"Green",IF(B23<=D23,"Amber","Red"))) -> Red
A24: HourCompliancePct | B24: =INDEX(tKPI[MetricValue],MATCH(A24,tKPI[MetricName],0)) -> 99.73 | C24: =INDEX(tTargets[TargetValue],MATCH(A24,tTargets[MetricName],0)) -> 100 | D24: =INDEX(tTargets[WarningValue],MATCH(A24,tTargets[MetricName],0)) -> 95 | E24: =IF(INDEX(tTargets[Direction],MATCH(A24,tTargets[MetricName],0))="HigherBetter",IF(B24>=C24,"Green",IF(B24>=D24,"Amber","Red")),IF(B24<=C24,"Green",IF(B24<=D24,"Amber","Red"))) -> Amber
A25: OverdueFlightCritical | B25: =INDEX(tKPI[MetricValue],MATCH(A25,tKPI[MetricName],0)) -> 90 | C25: =INDEX(tTargets[TargetValue],MATCH(A25,tTargets[MetricName],0)) -> 0 | D25: =INDEX(tTargets[WarningValue],MATCH(A25,tTargets[MetricName],0)) -> 2 | E25: =IF(INDEX(tTargets[Direction],MATCH(A25,tTargets[MetricName],0))="HigherBetter",IF(B25>=C25,"Green",IF(B25>=D25,"Amber","Red")),IF(B25<=C25,"Green",IF(B25<=D25,"Amber","Red"))) -> Red
A26: UnscheduledRatePct | B26: =INDEX(tKPI[MetricValue],MATCH(A26,tKPI[MetricName],0)) -> 36.13 | C26: =INDEX(tTargets[TargetValue],MATCH(A26,tTargets[MetricName],0)) -> 15 | D26: =INDEX(tTargets[WarningValue],MATCH(A26,tTargets[MetricName],0)) -> 25 | E26: =IF(INDEX(tTargets[Direction],MATCH(A26,tTargets[MetricName],0))="HigherBetter",IF(B26>=C26,"Green",IF(B26>=D26,"Amber","Red")),IF(B26<=C26,"Green",IF(B26<=D26,"Amber","Red"))) -> Red
A27: AirframeAvailabilityPct | B27: =INDEX(tKPI[MetricValue],MATCH(A27,tKPI[MetricName],0)) -> 92.86 | C27: =INDEX(tTargets[TargetValue],MATCH(A27,tTargets[MetricName],0)) -> 85 | D27: =INDEX(tTargets[WarningValue],MATCH(A27,tTargets[MetricName],0)) -> 75 | E27: =IF(INDEX(tTargets[Direction],MATCH(A27,tTargets[MetricName],0))="HigherBetter",IF(B27>=C27,"Green",IF(B27>=D27,"Amber","Red")),IF(B27<=C27,"Green",IF(B27<=D27,"Amber","Red"))) -> Green
A30: THE WEEK -- recomputed here from the hangar hours on Control
A31: MEASURE | B31: VALUE | C31: NOTE
A32: Jobs outstanding | B32: =COUNTA(tQueue[PriorityRank]) -> 194 | C32: Across the whole fleet.
A33: Hangar hours to clear | B33: =SUM(tQueue[JobHours]) -> 682.5 | C33: A procurement action costs no bay time and carries zero hours.
A34: Schedulable this week | B34: =SUM(CalcInWeek) -> 26 | C34: Where the cumulative hours cross the capacity on Control.
A35: Weeks at current capacity | B35: =SUM(tQueue[JobHours])/HangarHoursPerWeek -> 5.6875 | C35: Change the capacity cell and this moves.
A36: Ground and replace now | B36: =COUNTIFS(tQueue[ActionCode],"GROUND_AND_REPLACE") -> 90 | C36: Flight-critical and already past its stress interval.
A37: Order a part now | B37: =COUNTIFS(tQueue[ActionCode],"ORDER_PART_NOW") -> 25 | C37: A purchase order, not a bay. Different person, different day.

Sheet Bases
A1: THE FLEET AVERAGE DESCRIBES NONE OF THE FOUR BASES
A2: StressRatio is stress hours accrued per logged flight hour. Read across: the hour meter cannot tell these bases apart, and the work they fly is not comparable.
A4: Base | B4: Airframes | C4: Stress / flight hr | D4: Hour compliance % | E4: Stress compliance % | F4: Gap (pts) | G4: Hidden overdue | H4: Unscheduled %
A5: =INDEX(tBase[BaseCode],MATCH(SMALL(tBase[StressCompliancePct],1),tBase[StressCompliancePct],0)) -> PORT | B5: =INDEX(tBase[Airframes],MATCH($A5,tBase[BaseCode],0)) -> 7 | C5: =INDEX(tBase[StressRatio],MATCH($A5,tBase[BaseCode],0)) -> 2.004 | D5: =INDEX(tBase[HourCompliancePct],MATCH($A5,tBase[BaseCode],0)) -> 98.9 | E5: =INDEX(tBase[StressCompliancePct],MATCH($A5,tBase[BaseCode],0)) -> 57.14 | F5: =D5-E5 -> 41.76 | G5: =INDEX(tBase[HiddenOverdue],MATCH($A5,tBase[BaseCode],0)) -> 38 | H5: =INDEX(tBase[UnscheduledRatePct],MATCH($A5,tBase[BaseCode],0)) -> 40.14
A6: =INDEX(tBase[BaseCode],MATCH(SMALL(tBase[StressCompliancePct],2),tBase[StressCompliancePct],0)) -> ACADEMY | B6: =INDEX(tBase[Airframes],MATCH($A6,tBase[BaseCode],0)) -> 4 | C6: =INDEX(tBase[StressRatio],MATCH($A6,tBase[BaseCode],0)) -> 1.8594 | D6: =INDEX(tBase[HourCompliancePct],MATCH($A6,tBase[BaseCode],0)) -> 100 | E6: =INDEX(tBase[StressCompliancePct],MATCH($A6,tBase[BaseCode],0)) -> 57.69 | F6: =D6-E6 -> 42.31 | G6: =INDEX(tBase[HiddenOverdue],MATCH($A6,tBase[BaseCode],0)) -> 22 | H6: =INDEX(tBase[UnscheduledRatePct],MATCH($A6,tBase[BaseCode],0)) -> 41.67
A7: =INDEX(tBase[BaseCode],MATCH(SMALL(tBase[StressCompliancePct],3),tBase[StressCompliancePct],0)) -> HIGHLND | B7: =INDEX(tBase[Airframes],MATCH($A7,tBase[BaseCode],0)) -> 7 | C7: =INDEX(tBase[StressRatio],MATCH($A7,tBase[BaseCode],0)) -> 2.1532 | D7: =INDEX(tBase[HourCompliancePct],MATCH($A7,tBase[BaseCode],0)) -> 100 | E7: =INDEX(tBase[StressCompliancePct],MATCH($A7,tBase[BaseCode],0)) -> 62.64 | F7: =D7-E7 -> 37.36 | G7: =INDEX(tBase[HiddenOverdue],MATCH($A7,tBase[BaseCode],0)) -> 34 | H7: =INDEX(tBase[UnscheduledRatePct],MATCH($A7,tBase[BaseCode],0)) -> 51.01
A8: =INDEX(tBase[BaseCode],MATCH(SMALL(tBase[StressCompliancePct],4),tBase[StressCompliancePct],0)) -> COASTAL | B8: =INDEX(tBase[Airframes],MATCH($A8,tBase[BaseCode],0)) -> 10 | C8: =INDEX(tBase[StressRatio],MATCH($A8,tBase[BaseCode],0)) -> 1.1741 | D8: =INDEX(tBase[HourCompliancePct],MATCH($A8,tBase[BaseCode],0)) -> 100 | E8: =INDEX(tBase[StressCompliancePct],MATCH($A8,tBase[BaseCode],0)) -> 84.62 | F8: =D8-E8 -> 15.38 | G8: =INDEX(tBase[HiddenOverdue],MATCH($A8,tBase[BaseCode],0)) -> 20 | H8: =INDEX(tBase[UnscheduledRatePct],MATCH($A8,tBase[BaseCode],0)) -> 17.86
A10: Highland and Port are not worse-run bases; they fly mountain and cargo work, which is what the multiplier measures. The Academy is the one worth pausing on: it flies the lightest payloads and the fewest hours in the fleet, and circuit training produces so many landings that it wears its aircraft harder than the cargo hub.

Sheet Action Queue
A1: WHAT TO DO THIS WEEK
A2: ="Capacity " & TEXT(HangarHoursPerWeek,"#,##0") & " hangar hours. SQL ranks the queue; the Within-week column is recomputed in this workbook." -> Capacity 120 hangar hours. SQL ranks the queue; the Within-week column is recomputed in this workbook.
A4: Rank | B4: Tail | C4: Base | D4: Component | E4: Pos | F4: Criticality | G4: % hour interval | H4: % stress interval | I4: Projected hrs to limit | J4: Part lead (h) | K4: Action | L4: Job hrs | M4: Cumulative | N4: Within week
A5: 1 | B5: =INDEX(tQueue[TailNumber],MATCH($A5,tQueue[PriorityRank],0)) -> MU-008 | C5: =INDEX(tQueue[BaseCode],MATCH($A5,tQueue[PriorityRank],0)) -> HIGHLND | D5: =INDEX(tQueue[ComponentCode],MATCH($A5,tQueue[PriorityRank],0)) -> MOTOR-ESC | E5: =INDEX(tQueue[PositionNo],MATCH($A5,tQueue[PriorityRank],0)) -> 2 | F5: =INDEX(tQueue[Criticality],MATCH($A5,tQueue[PriorityRank],0)) -> FlightCritical | G5: =INDEX(tQueue[PctOfHourInterval],MATCH($A5,tQueue[PriorityRank],0)) -> 93.15 | H5: =INDEX(tQueue[PctOfStressInterval],MATCH($A5,tQueue[PriorityRank],0)) -> 201.08 | I5: =INDEX(tQueue[ProjectedFlightHoursToStressLimit],MATCH($A5,tQueue[PriorityRank],0)) -> -87.5 | J5: =INDEX(tQueue[LeadTimeFlightHours],MATCH($A5,tQueue[PriorityRank],0)) -> 12 | K5: =INDEX(tQueue[ActionCode],MATCH($A5,tQueue[PriorityRank],0)) -> GROUND_AND_REPLACE | L5: =INDEX(tQueue[JobHours],MATCH($A5,tQueue[PriorityRank],0)) -> 4.5 | M5: =INDEX(Calc!$C$5:$C$198,MATCH($A5,Calc!$A$5:$A$198,0)) -> 4.5 | N5: =IF(M5<=HangarHoursPerWeek,"yes","-") -> yes
A6: 2 | B6: =INDEX(tQueue[TailNumber],MATCH($A6,tQueue[PriorityRank],0)) -> MU-008 | C6: =INDEX(tQueue[BaseCode],MATCH($A6,tQueue[PriorityRank],0)) -> HIGHLND | D6: =INDEX(tQueue[ComponentCode],MATCH($A6,tQueue[PriorityRank],0)) -> ROTOR-ASSY | E6: =INDEX(tQueue[PositionNo],MATCH($A6,tQueue[PriorityRank],0)) -> 2 | F6: =INDEX(tQueue[Criticality],MATCH($A6,tQueue[PriorityRank],0)) -> FlightCritical | G6: =INDEX(tQueue[PctOfHourInterval],MATCH($A6,tQueue[PriorityRank],0)) -> 93.16 | H6: =INDEX(tQueue[PctOfStressInterval],MATCH($A6,tQueue[PriorityRank],0)) -> 205.46 | I6: =INDEX(tQueue[ProjectedFlightHoursToStressLimit],MATCH($A6,tQueue[PriorityRank],0)) -> -68.47 | J6: =INDEX(tQueue[LeadTimeFlightHours],MATCH($A6,tQueue[PriorityRank],0)) -> 18 | K6: =INDEX(tQueue[ActionCode],MATCH($A6,tQueue[PriorityRank],0)) -> GROUND_AND_REPLACE | L6: =INDEX(tQueue[JobHours],MATCH($A6,tQueue[PriorityRank],0)) -> 4.5 | M6: =INDEX(Calc!$C$5:$C$198,MATCH($A6,Calc!$A$5:$A$198,0)) -> 9 | N6: =IF(M6<=HangarHoursPerWeek,"yes","-") -> yes
A7: 3 | B7: =INDEX(tQueue[TailNumber],MATCH($A7,tQueue[PriorityRank],0)) -> MU-002 | C7: =INDEX(tQueue[BaseCode],MATCH($A7,tQueue[PriorityRank],0)) -> HIGHLND | D7: =INDEX(tQueue[ComponentCode],MATCH($A7,tQueue[PriorityRank],0)) -> ROTOR-ASSY | E7: =INDEX(tQueue[PositionNo],MATCH($A7,tQueue[PriorityRank],0)) -> 1 | F7: =INDEX(tQueue[Criticality],MATCH($A7,tQueue[PriorityRank],0)) -> FlightCritical | G7: =INDEX(tQueue[PctOfHourInterval],MATCH($A7,tQueue[PriorityRank],0)) -> 88.68 | H7: =INDEX(tQueue[PctOfStressInterval],MATCH($A7,tQueue[PriorityRank],0)) -> 201.88 | I7: =INDEX(tQueue[ProjectedFlightHoursToStressLimit],MATCH($A7,tQueue[PriorityRank],0)) -> -67.01 | J7: =INDEX(tQueue[LeadTimeFlightHours],MATCH($A7,tQueue[PriorityRank],0)) -> 18 | K7: =INDEX(tQueue[ActionCode],MATCH($A7,tQueue[PriorityRank],0)) -> GROUND_AND_REPLACE | L7: =INDEX(tQueue[JobHours],MATCH($A7,tQueue[PriorityRank],0)) -> 4.5 | M7: =INDEX(Calc!$C$5:$C$198,MATCH($A7,Calc!$A$5:$A$198,0)) -> 13.5 | N7: =IF(M7<=HangarHoursPerWeek,"yes","-") -> yes
A8: 4 | B8: =INDEX(tQueue[TailNumber],MATCH($A8,tQueue[PriorityRank],0)) -> MU-030 | C8: =INDEX(tQueue[BaseCode],MATCH($A8,tQueue[PriorityRank],0)) -> PORT | D8: =INDEX(tQueue[ComponentCode],MATCH($A8,tQueue[PriorityRank],0)) -> ROTOR-ASSY | E8: =INDEX(tQueue[PositionNo],MATCH($A8,tQueue[PriorityRank],0)) -> 4 | F8: =INDEX(tQueue[Criticality],MATCH($A8,tQueue[PriorityRank],0)) -> FlightCritical | G8: =INDEX(tQueue[PctOfHourInterval],MATCH($A8,tQueue[PriorityRank],0)) -> 98.02 | H8: =INDEX(tQueue[PctOfStressInterval],MATCH($A8,tQueue[PriorityRank],0)) -> 199.89 | I8: =INDEX(tQueue[ProjectedFlightHoursToStressLimit],MATCH($A8,tQueue[PriorityRank],0)) -> -76.34 | J8: =INDEX(tQueue[LeadTimeFlightHours],MATCH($A8,tQueue[PriorityRank],0)) -> 18 | K8: =INDEX(tQueue[ActionCode],MATCH($A8,tQueue[PriorityRank],0)) -> GROUND_AND_REPLACE | L8: =INDEX(tQueue[JobHours],MATCH($A8,tQueue[PriorityRank],0)) -> 4.5 | M8: =INDEX(Calc!$C$5:$C$198,MATCH($A8,Calc!$A$5:$A$198,0)) -> 18 | N8: =IF(M8<=HangarHoursPerWeek,"yes","-") -> yes
A9: 5 | B9: =INDEX(tQueue[TailNumber],MATCH($A9,tQueue[PriorityRank],0)) -> MU-015 | C9: =INDEX(tQueue[BaseCode],MATCH($A9,tQueue[PriorityRank],0)) -> PORT | D9: =INDEX(tQueue[ComponentCode],MATCH($A9,tQueue[PriorityRank],0)) -> MOTOR-ESC | E9: =INDEX(tQueue[PositionNo],MATCH($A9,tQueue[PriorityRank],0)) -> 2 | F9: =INDEX(tQueue[Criticality],MATCH($A9,tQueue[PriorityRank],0)) -> FlightCritical | G9: =INDEX(tQueue[PctOfHourInterval],MATCH($A9,tQueue[PriorityRank],0)) -> 88.79 | H9: =INDEX(tQueue[PctOfStressInterval],MATCH($A9,tQueue[PriorityRank],0)) -> 174.18 | I9: =INDEX(tQueue[ProjectedFlightHoursToStressLimit],MATCH($A9,tQueue[PriorityRank],0)) -> -77.21 | J9: =INDEX(tQueue[LeadTimeFlightHours],MATCH($A9,tQueue[PriorityRank],0)) -> 12 | K9: =INDEX(tQueue[ActionCode],MATCH($A9,tQueue[PriorityRank],0)) -> GROUND_AND_REPLACE | L9: =INDEX(tQueue[JobHours],MATCH($A9,tQueue[PriorityRank],0)) -> 4.5 | M9: =INDEX(Calc!$C$5:$C$198,MATCH($A9,Calc!$A$5:$A$198,0)) -> 22.5 | N9: =IF(M9<=HangarHoursPerWeek,"yes","-") -> yes
A10: 6 | B10: =INDEX(tQueue[TailNumber],MATCH($A10,tQueue[PriorityRank],0)) -> MU-001 | C10: =INDEX(tQueue[BaseCode],MATCH($A10,tQueue[PriorityRank],0)) -> PORT | D10: =INDEX(tQueue[ComponentCode],MATCH($A10,tQueue[PriorityRank],0)) -> MOTOR-ESC | E10: =INDEX(tQueue[PositionNo],MATCH($A10,tQueue[PriorityRank],0)) -> 1 | F10: =INDEX(tQueue[Criticality],MATCH($A10,tQueue[PriorityRank],0)) -> FlightCritical | G10: =INDEX(tQueue[PctOfHourInterval],MATCH($A10,tQueue[PriorityRank],0)) -> 85.51 | H10: =INDEX(tQueue[PctOfStressInterval],MATCH($A10,tQueue[PriorityRank],0)) -> 171.52 | I10: =INDEX(tQueue[ProjectedFlightHoursToStressLimit],MATCH($A10,tQueue[PriorityRank],0)) -> -69.31 | J10: =INDEX(tQueue[LeadTimeFlightHours],MATCH($A10,tQueue[PriorityRank],0)) -> 12 | K10: =INDEX(tQueue[ActionCode],MATCH($A10,tQueue[PriorityRank],0)) -> GROUND_AND_REPLACE | L10: =INDEX(tQueue[JobHours],MATCH($A10,tQueue[PriorityRank],0)) -> 4.5 | M10: =INDEX(Calc!$C$5:$C$198,MATCH($A10,Calc!$A$5:$A$198,0)) -> 27 | N10: =IF(M10<=HangarHoursPerWeek,"yes","-") -> yes
A11: 7 | B11: =INDEX(tQueue[TailNumber],MATCH($A11,tQueue[PriorityRank],0)) -> MU-001 | C11: =INDEX(tQueue[BaseCode],MATCH($A11,tQueue[PriorityRank],0)) -> PORT | D11: =INDEX(tQueue[ComponentCode],MATCH($A11,tQueue[PriorityRank],0)) -> MOTOR-ESC | E11: =INDEX(tQueue[PositionNo],MATCH($A11,tQueue[PriorityRank],0)) -> 2 | F11: =INDEX(tQueue[Criticality],MATCH($A11,tQueue[PriorityRank],0)) -> FlightCritical | G11: =INDEX(tQueue[PctOfHourInterval],MATCH($A11,tQueue[PriorityRank],0)) -> 85.51 | H11: =INDEX(tQueue[PctOfStressInterval],MATCH($A11,tQueue[PriorityRank],0)) -> 171.52 | I11: =INDEX(tQueue[ProjectedFlightHoursToStressLimit],MATCH($A11,tQueue[PriorityRank],0)) -> -69.31 | J11: =INDEX(tQueue[LeadTimeFlightHours],MATCH($A11,tQueue[PriorityRank],0)) -> 12 | K11: =INDEX(tQueue[ActionCode],MATCH($A11,tQueue[PriorityRank],0)) -> GROUND_AND_REPLACE | L11: =INDEX(tQueue[JobHours],MATCH($A11,tQueue[PriorityRank],0)) -> 4.5 | M11: =INDEX(Calc!$C$5:$C$198,MATCH($A11,Calc!$A$5:$A$198,0)) -> 31.5 | N11: =IF(M11<=HangarHoursPerWeek,"yes","-") -> yes
A12: 8 | B12: =INDEX(tQueue[TailNumber],MATCH($A12,tQueue[PriorityRank],0)) -> MU-002 | C12: =INDEX(tQueue[BaseCode],MATCH($A12,tQueue[PriorityRank],0)) -> HIGHLND | D12: =INDEX(tQueue[ComponentCode],MATCH($A12,tQueue[PriorityRank],0)) -> MOTOR-ESC | E12: =INDEX(tQueue[PositionNo],MATCH($A12,tQueue[PriorityRank],0)) -> 2 | F12: =INDEX(tQueue[Criticality],MATCH($A12,tQueue[PriorityRank],0)) -> FlightCritical | G12: =INDEX(tQueue[PctOfHourInterval],MATCH($A12,tQueue[PriorityRank],0)) -> 75.1 | H12: =INDEX(tQueue[PctOfStressInterval],MATCH($A12,tQueue[PriorityRank],0)) -> 170.9 | I12: =INDEX(tQueue[ProjectedFlightHoursToStressLimit],MATCH($A12,tQueue[PriorityRank],0)) -> -62.18 | J12: =INDEX(tQueue[LeadTimeFlightHours],MATCH($A12,tQueue[PriorityRank],0)) -> 12 | K12: =INDEX(tQueue[ActionCode],MATCH($A12,tQueue[PriorityRank],0)) -> GROUND_AND_REPLACE | L12: =INDEX(tQueue[JobHours],MATCH($A12,tQueue[PriorityRank],0)) -> 4.5 | M12: =INDEX(Calc!$C$5:$C$198,MATCH($A12,Calc!$A$5:$A$198,0)) -> 36 | N12: =IF(M12<=HangarHoursPerWeek,"yes","-") -> yes
A13: 9 | B13: =INDEX(tQueue[TailNumber],MATCH($A13,tQueue[PriorityRank],0)) -> MU-021 | C13: =INDEX(tQueue[BaseCode],MATCH($A13,tQueue[PriorityRank],0)) -> ACADEMY | D13: =INDEX(tQueue[ComponentCode],MATCH($A13,tQueue[PriorityRank],0)) -> MOTOR-ESC | E13: =INDEX(tQueue[PositionNo],MATCH($A13,tQueue[PriorityRank],0)) -> 1 | F13: =INDEX(tQueue[Criticality],MATCH($A13,tQueue[PriorityRank],0)) -> FlightCritical | G13: =INDEX(tQueue[PctOfHourInterval],MATCH($A13,tQueue[PriorityRank],0)) -> 89.85 | H13: =INDEX(tQueue[PctOfStressInterval],MATCH($A13,tQueue[PriorityRank],0)) -> 168.36 | I13: =INDEX(tQueue[ProjectedFlightHoursToStressLimit],MATCH($A13,tQueue[PriorityRank],0)) -> -71.4 | J13: =INDEX(tQueue[LeadTimeFlightHours],MATCH($A13,tQueue[PriorityRank],0)) -> 12 | K13: =INDEX(tQueue[ActionCode],MATCH($A13,tQueue[PriorityRank],0)) -> GROUND_AND_REPLACE | L13: =INDEX(tQueue[JobHours],MATCH($A13,tQueue[PriorityRank],0)) -> 4.5 | M13: =INDEX(Calc!$C$5:$C$198,MATCH($A13,Calc!$A$5:$A$198,0)) -> 40.5 | N13: =IF(M13<=HangarHoursPerWeek,"yes","-") -> yes
A14: 10 | B14: =INDEX(tQueue[TailNumber],MATCH($A14,tQueue[PriorityRank],0)) -> MU-021 | C14: =INDEX(tQueue[BaseCode],MATCH($A14,tQueue[PriorityRank],0)) -> ACADEMY | D14: =INDEX(tQueue[ComponentCode],MATCH($A14,tQueue[PriorityRank],0)) -> MOTOR-ESC | E14: =INDEX(tQueue[PositionNo],MATCH($A14,tQueue[PriorityRank],0)) -> 2 | F14: =INDEX(tQueue[Criticality],MATCH($A14,tQueue[PriorityRank],0)) -> FlightCritical | G14: =INDEX(tQueue[PctOfHourInterval],MATCH($A14,tQueue[PriorityRank],0)) -> 89.85 | H14: =INDEX(tQueue[PctOfStressInterval],MATCH($A14,tQueue[PriorityRank],0)) -> 168.36 | I14: =INDEX(tQueue[ProjectedFlightHoursToStressLimit],MATCH($A14,tQueue[PriorityRank],0)) -> -71.4 | J14: =INDEX(tQueue[LeadTimeFlightHours],MATCH($A14,tQueue[PriorityRank],0)) -> 12 | K14: =INDEX(tQueue[ActionCode],MATCH($A14,tQueue[PriorityRank],0)) -> GROUND_AND_REPLACE | L14: =INDEX(tQueue[JobHours],MATCH($A14,tQueue[PriorityRank],0)) -> 4.5 | M14: =INDEX(Calc!$C$5:$C$198,MATCH($A14,Calc!$A$5:$A$198,0)) -> 45 | N14: =IF(M14<=HangarHoursPerWeek,"yes","-") -> yes
A15: 11 | B15: =INDEX(tQueue[TailNumber],MATCH($A15,tQueue[PriorityRank],0)) -> MU-021 | C15: =INDEX(tQueue[BaseCode],MATCH($A15,tQueue[PriorityRank],0)) -> ACADEMY | D15: =INDEX(tQueue[ComponentCode],MATCH($A15,tQueue[PriorityRank],0)) -> MOTOR-ESC | E15: =INDEX(tQueue[PositionNo],MATCH($A15,tQueue[PriorityRank],0)) -> 3 | F15: =INDEX(tQueue[Criticality],MATCH($A15,tQueue[PriorityRank],0)) -> FlightCritical | G15: =INDEX(tQueue[PctOfHourInterval],MATCH($A15,tQueue[PriorityRank],0)) -> 89.85 | H15: =INDEX(tQueue[PctOfStressInterval],MATCH($A15,tQueue[PriorityRank],0)) -> 168.36 | I15: =INDEX(tQueue[ProjectedFlightHoursToStressLimit],MATCH($A15,tQueue[PriorityRank],0)) -> -71.4 | J15: =INDEX(tQueue[LeadTimeFlightHours],MATCH($A15,tQueue[PriorityRank],0)) -> 12 | K15: =INDEX(tQueue[ActionCode],MATCH($A15,tQueue[PriorityRank],0)) -> GROUND_AND_REPLACE | L15: =INDEX(tQueue[JobHours],MATCH($A15,tQueue[PriorityRank],0)) -> 4.5 | M15: =INDEX(Calc!$C$5:$C$198,MATCH($A15,Calc!$A$5:$A$198,0)) -> 49.5 | N15: =IF(M15<=HangarHoursPerWeek,"yes","-") -> yes
A16: 12 | B16: =INDEX(tQueue[TailNumber],MATCH($A16,tQueue[PriorityRank],0)) -> MU-020 | C16: =INDEX(tQueue[BaseCode],MATCH($A16,tQueue[PriorityRank],0)) -> HIGHLND | D16: =INDEX(tQueue[ComponentCode],MATCH($A16,tQueue[PriorityRank],0)) -> MOTOR-ESC | E16: =INDEX(tQueue[PositionNo],MATCH($A16,tQueue[PriorityRank],0)) -> 2 | F16: =INDEX(tQueue[Criticality],MATCH($A16,tQueue[PriorityRank],0)) -> FlightCritical | G16: =INDEX(tQueue[PctOfHourInterval],MATCH($A16,tQueue[PriorityRank],0)) -> 79.17 | H16: =INDEX(tQueue[PctOfStressInterval],MATCH($A16,tQueue[PriorityRank],0)) -> 168.35 | I16: =INDEX(tQueue[ProjectedFlightHoursToStressLimit],MATCH($A16,tQueue[PriorityRank],0)) -> -60.54 | J16: =INDEX(tQueue[LeadTimeFlightHours],MATCH($A16,tQueue[PriorityRank],0)) -> 12 | K16: =INDEX(tQueue[ActionCode],MATCH($A16,tQueue[PriorityRank],0)) -> GROUND_AND_REPLACE | L16: =INDEX(tQueue[JobHours],MATCH($A16,tQueue[PriorityRank],0)) -> 4.5 | M16: =INDEX(Calc!$C$5:$C$198,MATCH($A16,Calc!$A$5:$A$198,0)) -> 54 | N16: =IF(M16<=HangarHoursPerWeek,"yes","-") -> yes
... A124: 120 | B124: =INDEX(tQueue[TailNumber],MATCH($A124,tQueue[PriorityRank],0)) -> MU-004 | C124: =INDEX(tQueue[BaseCode],MATCH($A124,tQueue[PriorityRank],0)) -> COASTAL | D124: =INDEX(tQueue[ComponentCode],MATCH($A124,tQueue[PriorityRank],0)) -> ROTOR-ASSY | E124: =INDEX(tQueue[PositionNo],MATCH($A124,tQueue[PriorityRank],0)) -> 2 | F124: =INDEX(tQueue[Criticality],MATCH($A124,tQueue[PriorityRank],0)) -> FlightCritical | G124: =INDEX(tQueue[PctOfHourInterval],MATCH($A124,tQueue[PriorityRank],0)) -> 74.86 | H124: =INDEX(tQueue[PctOfStressInterval],MATCH($A124,tQueue[PriorityRank],0)) -> 85.5 | I124: =INDEX(tQueue[ProjectedFlightHoursToStressLimit],MATCH($A124,tQueue[PriorityRank],0)) -> 19.77 | J124: =INDEX(tQueue[LeadTimeFlightHours],MATCH($A124,tQueue[PriorityRank],0)) -> 18 | K124: =INDEX(tQueue[ActionCode],MATCH($A124,tQueue[PriorityRank],0)) -> SCHEDULE_THIS_MONTH | L124: =INDEX(tQueue[JobHours],MATCH($A124,tQueue[PriorityRank],0)) -> 4.5 | M124: =INDEX(Calc!$C$5:$C$198,MATCH($A124,Calc!$A$5:$A$198,0)) -> 436.5 | N124: =IF(M124<=HangarHoursPerWeek,"yes","-") -> -
A126: ="Showing the top 120 of " & COUNTA(tQueue[PriorityRank]) & " outstanding jobs. The full queue is on Data_Queue -- it is kept complete for audit, and cut here only for reading." -> Showing the top 120 of 194 outstanding jobs. The full queue is on Data_Queue -- it is kept complete for audit, and cut here only for reading.

Sheet Prediction
A1: THE ALARM IS ACCURATE. THAT IS NOT THE SAME AS USEFUL.
A2: Change the Alert threshold on Control and every figure below re-states. Precision rises with it; lead time falls with it. There is no setting where both clear their target for both components.
A4: Component | B4: Part lead time (h) | C4: Threshold | D4: Alerts | E4: Caught | F4: Precision % | G4: Recall % | H4: Median warning (h) | I4: Actionable % | J4: Warning covers supply?
A5: ROTOR-ASSY | B5: =SUMIFS(tSweep[LeadTimeFlightHours],tSweep[ComponentCode],$A5,tSweep[VibThreshold],AlertThreshold) -> 18 | C5: =AlertThreshold -> 3.4 | D5: =SUMIFS(tSweep[AlertsRaised],tSweep[ComponentCode],$A5,tSweep[VibThreshold],AlertThreshold) -> 241 | E5: =SUMIFS(tSweep[TP],tSweep[ComponentCode],$A5,tSweep[VibThreshold],AlertThreshold) -> 180 | F5: =SUMIFS(tSweep[PrecisionPct],tSweep[ComponentCode],$A5,tSweep[VibThreshold],AlertThreshold) -> 74.69 | G5: =SUMIFS(tSweep[RecallPct],tSweep[ComponentCode],$A5,tSweep[VibThreshold],AlertThreshold) -> 97.83 | H5: =SUMIFS(tSweep[MedianLeadTimeFlightHours],tSweep[ComponentCode],$A5,tSweep[VibThreshold],AlertThreshold) -> 18.93 | I5: =SUMIFS(tSweep[ActionableLeadTimePct],tSweep[ComponentCode],$A5,tSweep[VibThreshold],AlertThreshold) -> 54.44 | J5: =IF(H5>=B5,"yes","NO -- the median warning is shorter than the time to get the part") -> yes
A6: MOTOR-ESC | B6: =SUMIFS(tSweep[LeadTimeFlightHours],tSweep[ComponentCode],$A6,tSweep[VibThreshold],AlertThreshold) -> 12 | C6: =AlertThreshold -> 3.4 | D6: =SUMIFS(tSweep[AlertsRaised],tSweep[ComponentCode],$A6,tSweep[VibThreshold],AlertThreshold) -> 106 | E6: =SUMIFS(tSweep[TP],tSweep[ComponentCode],$A6,tSweep[VibThreshold],AlertThreshold) -> 103 | F6: =SUMIFS(tSweep[PrecisionPct],tSweep[ComponentCode],$A6,tSweep[VibThreshold],AlertThreshold) -> 97.17 | G6: =SUMIFS(tSweep[RecallPct],tSweep[ComponentCode],$A6,tSweep[VibThreshold],AlertThreshold) -> 99.04 | H6: =SUMIFS(tSweep[MedianLeadTimeFlightHours],tSweep[ComponentCode],$A6,tSweep[VibThreshold],AlertThreshold) -> 6.75 | I6: =SUMIFS(tSweep[ActionableLeadTimePct],tSweep[ComponentCode],$A6,tSweep[VibThreshold],AlertThreshold) -> 8.74 | J6: =IF(H6>=B6,"yes","NO -- the median warning is shorter than the time to get the part") -> NO -- the median warning is shorter than the time to get the part
A8: FLEET (counts summed, not percentages averaged) | D8: =SUM(D5:D6) -> 347 | E8: =SUM(E5:E6) -> 283 | F8: =E8/D8*100 -> 81.556196 | I8: =SUMPRODUCT(SUMIFS(tSweep[ActionableTP],tSweep[ComponentCode],A5:A6,tSweep[VibThreshold],AlertThreshold))/E8*100 -> 37.809187
A11: A prediction is worth its LEAD TIME, not its accuracy. A rotor assembly takes 18 flight hours to obtain and fit, so an alert with 6 hours of warning is a correct prediction and a grounded aircraft. Precision and recall cannot tell those two alerts apart -- both are true positives. Set the threshold to 2.05 and watch the motor controller: precision falls, and the share of its failures caught in time to act rises from single figures to over 90%.

Sheet Validation
A1: VALIDATION -- Excel against SQL
A2: Each row recomputes a figure in Excel from the raw extract and compares it to what SQL published. A workbook that agrees with itself proves nothing.
A3: This proves the two AGREE. It does not prove either is right -- Project 1 shipped a workbook and a view that agreed exactly and were both wrong, because both came from the same flawed written definition.
A5: # | B5: CHECK | C5: EXCEL | D5: SQL | E5: RESULT
A6: 1 | B6: Stress compliance % | C6: =COUNTIFS(tWear[IsOverdueByStress],0)/COUNTA(tWear[InstallKey])*100 -> 68.406593 | D6: =INDEX(tKPI[MetricValue],MATCH("StressCompliancePct",tKPI[MetricName],0)) -> 68.41 | E6: =IF(ABS(C6-D6)<0.011,"OK","MISMATCH") -> OK
A7: 2 | B7: Hour compliance % | C7: =COUNTIFS(tWear[IsOverdueByHours],0)/COUNTA(tWear[InstallKey])*100 -> 99.725275 | D7: =INDEX(tKPI[MetricValue],MATCH("HourCompliancePct",tKPI[MetricName],0)) -> 99.73 | E7: =IF(ABS(C7-D7)<0.011,"OK","MISMATCH") -> OK
A8: 3 | B8: Overdue flight-critical | C8: =COUNTIFS(tWear[IsOverdueByStress],1,tWear[Criticality],"FlightCritical") -> 90 | D8: =INDEX(tKPI[MetricValue],MATCH("OverdueFlightCritical",tKPI[MetricName],0)) -> 90 | E8: =IF(ABS(C8-D8)<0.011,"OK","MISMATCH") -> OK
A9: 4 | B9: Components fitted | C9: =COUNTA(tWear[InstallKey]) -> 364 | D9: =INDEX(tKPI[Denominator],MATCH("StressCompliancePct",tKPI[MetricName],0)) -> 364 | E9: =IF(ABS(C9-D9)<0.011,"OK","MISMATCH") -> OK
A10: 5 | B10: Hidden overdue | C10: =COUNTIFS(tWear[IsHiddenOverdue],1) -> 114 | D10: =SUM(tBase[HiddenOverdue]) -> 114 | E10: =IF(ABS(C10-D10)<0.011,"OK","MISMATCH") -> OK
A11: 6 | B11: Hidden overdue, flt-crit | C11: =COUNTIFS(tWear[IsHiddenOverdue],1,tWear[Criticality],"FlightCritical") -> 89 | D11: =SUM(tBase[HiddenOverdueFlightCritical]) -> 89 | E11: =IF(ABS(C11-D11)<0.011,"OK","MISMATCH") -> OK
A12: 7 | B12: Base fitted components sum | C12: =SUM(tBase[FittedComponents]) -> 364 | D12: =COUNTA(tWear[InstallKey]) -> 364 | E12: =IF(ABS(C12-D12)<0.011,"OK","MISMATCH") -> OK
A13: 8 | B13: Queue rows | C13: =COUNTA(tQueue[PriorityRank]) -> 194 | D13: =MAX(tQueue[PriorityRank]) -> 194 | E13: =IF(ABS(C13-D13)<0.011,"OK","MISMATCH") -> OK
A14: 9 | B14: Queue hangar hours | C14: =SUM(tQueue[JobHours]) -> 682.5 | D14: =MAX(tQueue[CumulativeJobHours]) -> 682.5 | E14: =IF(ABS(C14-D14)<0.011,"OK","MISMATCH") -> OK
A15: 10 | B15: Ground-and-replace jobs | C15: =COUNTIFS(tQueue[ActionCode],"GROUND_AND_REPLACE") -> 90 | D15: =COUNTIFS(tWear[IsOverdueByStress],1,tWear[Criticality],"FlightCritical") -> 90 | E15: =IF(ABS(C15-D15)<0.011,"OK","MISMATCH") -> OK
A16: 11 | B16: Rotor precision at threshold | C16: =SUMIFS(tSweep[PrecisionPct],tSweep[ComponentCode],"ROTOR-ASSY",tSweep[VibThreshold],AlertThreshold) -> 74.69 | D16: =SUMIFS(tSweep[TP],tSweep[ComponentCode],"ROTOR-ASSY",tSweep[VibThreshold],AlertThreshold)/SUMIFS(tSweep[AlertsRaised],tSweep[ComponentCode],"ROTOR-ASSY",tSweep[VibThreshold],AlertThreshold)*100 -> 74.688797 | E16: =IF(ABS(C16-D16)<0.011,"OK","MISMATCH") -> OK
A17: 12 | B17: Motor precision at threshold | C17: =SUMIFS(tSweep[PrecisionPct],tSweep[ComponentCode],"MOTOR-ESC",tSweep[VibThreshold],AlertThreshold) -> 97.17 | D17: =SUMIFS(tSweep[TP],tSweep[ComponentCode],"MOTOR-ESC",tSweep[VibThreshold],AlertThreshold)/SUMIFS(tSweep[AlertsRaised],tSweep[ComponentCode],"MOTOR-ESC",tSweep[VibThreshold],AlertThreshold)*100 -> 97.169811 | E17: =IF(ABS(C17-D17)<0.011,"OK","MISMATCH") -> OK
A18: 13 | B18: Actionable + late = caught | C18: =SUMIFS(tSweep[ActionableTP],tSweep[VibThreshold],AlertThreshold)+SUMIFS(tSweep[LateTP],tSweep[VibThreshold],AlertThreshold) -> 283 | D18: =SUMIFS(tSweep[TP],tSweep[VibThreshold],AlertThreshold) -> 283 | E18: =IF(ABS(C18-D18)<0.011,"OK","MISMATCH") -> OK
A19: 14 | B19: Confusion matrix partitions | C19: =SUMIFS(tSweep[TP],tSweep[VibThreshold],AlertThreshold)+SUMIFS(tSweep[FP],tSweep[VibThreshold],AlertThreshold)+SUMIFS(tSweep[FN],tSweep[VibThreshold],AlertThreshold)+SUMIFS(tSweep[TN],tSweep[VibThreshold],AlertThreshold) -> 734 | D19: =SUMIFS(tSweep[Population],tSweep[VibThreshold],AlertThreshold) -> 734 | E19: =IF(ABS(C19-D19)<0.011,"OK","MISMATCH") -> OK
A20: 15 | B20: Week cut within capacity | C20: =SUMPRODUCT(CalcInWeek) -> 26 | D20: =COUNTIFS(tQueue[IsThisWeek],1) -> 26 | E20: =IF(ABS(C20-D20)<0.011,"OK","MISMATCH") -> OK
A21: 16 | B21: DQ findings total | C21: =COUNTA(tDQ[CheckCode]) -> 73 | D21: =COUNTA(tDQ[Detail]) -> 73 | E21: =IF(ABS(C21-D21)<0.011,"OK","MISMATCH") -> OK
B23: CHECKS PASSING | C23: =COUNTIF(E6:E21,"OK") & " of " & COUNTA(E6:E21) -> 16 of 16

Sheet Control
A1: MERIDIAN UAV SERVICES -- FLEET MAINTENANCE CONTROL
A2: Control panel. Every sheet reads its parameters from the cells below.
A4: PARAMETER | B4: VALUE | C4: WHAT IT CONTROLS
A5: Source folder | B5: C:\Users\inouf\OneDrive\Documents\Portfolio Projects\project-5-meridian-uav\data_exports | C5: Where the CSV extracts live. Power Query reads this cell, so the workbook moves with its data.
A6: Reporting date | B6: 46295 | C6: Pinned, not derived from the data. A figure anchored on "the latest row" stops matching the report that quoted it the moment anything is loaded.
A7: Hangar hours / week | B7: 120 | C7: Maintenance capacity for the whole fleet. Change it and the week plan re-cuts itself -- this is how "what does another bay buy us" gets answered.
A8: Alert threshold | B8: 3.4 | C8: Vibration multiple of a component's own baseline at which the alarm fires. Change it and the prediction figures re-state from the sweep.
A11: DATA DISCLOSURE
A12: Meridian UAV Services is a fictional UAV operator. All data in this workbook is synthetic and generated by the scripts in the sql\ folder. Degradation behaviour is modelled on publicly described characteristics of rotating machinery. No confidential data is used and no claim is made about any real aircraft, operator or manufacturer.

Sheet Data_Wear
A1: InstallKey | B1: ComponentSerial | C1: ComponentCode | D1: ComponentName | E1: Criticality | F1: LeadTimeFlightHours | G1: TailNumber | H1: ModelCode | I1: BaseCode | J1: BaseName | K1: PositionNo | L1: InstalledDate | M1: Sorties | N1: Landings | O1: FlightHours | P1: StressHours | Q1: IntervalFlightHours | R1: IntervalStressHours | S1: PctOfHourInterval | T1: PctOfStressInterval | U1: IsOverdueByHours | V1: IsOverdueByStress | W1: IsHiddenOverdue | X1: StressPerFlightHour | Y1: RemainingStressHours | Z1: RemainingFlightHours | AA1: ProjectedFlightHoursToStressLimit | AB1: LastSortieDate
A2: 392 | B2: ROTOR-ASSY-00139 | C2: ROTOR-ASSY | D2: Rotor assembly and bearing | E2: FlightCritical | F2: 18 | G2: MU-008 | H2: MRD-12H | I2: HIGHLND | J2: Highland Operations | K2: 2 | M2: 85 | N2: 167 | O2: 139.7328 | P2: 308.1946 | Q2: 150 | R2: 150 | S2: 93.16 | T2: 205.46 | U2: 0 | V2: 1 | W2: 1 | X2: 2.3105 | Y2: -158.1946 | Z2: 10.2672 | AA2: -68.47
A3: 209 | B3: BATT-PACK-00049 | C3: BATT-PACK | D3: Main battery pack | E3: FlightCritical | F3: 8 | G3: MU-005 | H3: MRD-8X | I3: PORT | J3: Port Logistics Hub | K3: 1 | M3: 71 | N3: 153 | O3: 121.5 | P3: 246.2652 | Q3: 120 | R3: 120 | S3: 101.25 | T3: 205.22 | U3: 1 | V3: 1 | W3: 0 | X3: 1.9127 | Y3: -126.2652 | Z3: -1.5 | AA3: -66.01
A4: 981 | B4: BATT-PACK-00213 | C4: BATT-PACK | D4: Main battery pack | E4: FlightCritical | F4: 8 | G4: MU-020 | H4: MRD-8X | I4: HIGHLND | J4: Highland Operations | K4: 1 | M4: 67 | N4: 131 | O4: 111.8997 | P4: 244.573 | Q4: 120 | R4: 120 | S4: 93.25 | T4: 203.81 | U4: 0 | V4: 1 | W4: 1 | X4: 2.2582 | Y4: -124.573 | Z4: 8.1003 | AA4: -55.16
A5: 99 | B5: ROTOR-ASSY-00026 | C5: ROTOR-ASSY | D5: Rotor assembly and bearing | E5: FlightCritical | F5: 18 | G5: MU-002 | H5: MRD-8X | I5: HIGHLND | J5: Highland Operations | K5: 1 | M5: 81 | N5: 139 | O5: 133.0167 | P5: 302.8206 | Q5: 150 | R5: 150 | S5: 88.68 | T5: 201.88 | U5: 0 | V5: 1 | W5: 1 | X5: 2.2807 | Y5: -152.8206 | Z5: 16.9833 | AA5: -67.01
A6: 372 | B6: MOTOR-ESC-00100 | C6: MOTOR-ESC | D6: Motor and speed controller | E6: FlightCritical | F6: 12 | G6: MU-008 | H6: MRD-12H | I6: HIGHLND | J6: Highland Operations | K6: 2 | M6: 111 | N6: 221 | O6: 186.2996 | P6: 402.1619 | Q6: 200 | R6: 200 | S6: 93.15 | T6: 201.08 | U6: 0 | V6: 1 | W6: 1 | X6: 2.3105 | Y6: -202.1619 | Z6: 13.7004 | AA6: -87.5
A7: 1503 | B7: ROTOR-ASSY-00545 | C7: ROTOR-ASSY | D7: Rotor assembly and bearing | E7: FlightCritical | F7: 18 | G7: MU-030 | H7: MRD-8X | I7: PORT | J7: Port Logistics Hub | K7: 4 | M7: 85 | N7: 262 | O7: 147.0335 | P7: 299.8295 | Q7: 150 | R7: 150 | S7: 98.02 | T7: 199.89 | U7: 0 | V7: 1 | W7: 1 | X7: 1.9627 | Y7: -149.8295 | Z7: 2.9665 | AA7: -76.34
A8: 1336 | B8: GIMBAL-00068 | C8: GIMBAL | D8: Payload gimbal | E8: MissionCritical | F8: 24 | G8: MU-027 | H8: MRD-8X | I8: HIGHLND | J8: Highland Operations | K8: 1 | M8: 162 | N8: 287 | O8: 282.05 | P8: 588.2364 | Q8: 300 | R8: 300 | S8: 94.02 | T8: 196.08 | U8: 0 | V8: 1 | W8: 1 | X8: 1.908 | Y8: -288.2364 | Z8: 17.95 | AA8: -151.07
A9: 215 | B9: BATT-PACK-00055 | C9: BATT-PACK | D9: Main battery pack | E9: FlightCritical | F9: 8 | G9: MU-005 | H9: MRD-8X | I9: PORT | J9: Port Logistics Hub | K9: 2 | M9: 69 | N9: 150 | O9: 116.6166 | P9: 235.2122 | Q9: 120 | R9: 120 | S9: 97.18 | T9: 196.01 | U9: 0 | V9: 1 | W9: 1 | X9: 1.9127 | Y9: -115.2122 | Z9: 3.3834 | AA9: -60.24
A10: 352 | B10: BATT-PACK-00077 | C10: BATT-PACK | D10: Main battery pack | E10: FlightCritical | F10: 8 | G10: MU-008 | H10: MRD-12H | I10: HIGHLND | J10: Highland Operations | K10: 1 | M10: 63 | N10: 121 | O10: 104.833 | P10: 233.0981 | Q10: 120 | R10: 120 | S10: 87.36 | T10: 194.25 | U10: 0 | V10: 1 | W10: 1 | X10: 2.3105 | Y10: -113.0981 | Z10: 15.167 | AA10: -48.95
A11: 262 | B11: ROTOR-ASSY-00099 | C11: ROTOR-ASSY | D11: Rotor assembly and bearing | E11: FlightCritical | F11: 18 | G11: MU-005 | H11: MRD-8X | I11: PORT | J11: Port Logistics Hub | K11: 4 | M11: 82 | N11: 177 | O11: 140.7332 | P11: 284.2317 | Q11: 150 | R11: 150 | S11: 93.82 | T11: 189.49 | U11: 0 | V11: 1 | W11: 1 | X11: 1.9127 | Y11: -134.2317 | Z11: 9.2668 | AA11: -70.18
A12: 903 | B12: ROTOR-ASSY-00325 | C12: ROTOR-ASSY | D12: Rotor assembly and bearing | E12: FlightCritical | F12: 18 | G12: MU-018 | H12: MRD-12H | I12: HIGHLND | J12: Highland Operations | K12: 3 | M12: 79 | N12: 146 | O12: 131.1003 | P12: 281.8172 | Q12: 150 | R12: 150 | S12: 87.4 | T12: 187.88 | U12: 0 | V12: 1 | W12: 1 | X12: 2.1969 | Y12: -131.8172 | Z12: 18.8997 | AA12: -60
A13: 1227 | B13: BATT-PACK-00266 | C13: BATT-PACK | D13: Main battery pack | E13: FlightCritical | F13: 8 | G13: MU-025 | H13: MRD-8X | I13: HIGHLND | J13: Highland Operations | K13: 1 | M13: 60 | N13: 114 | O13: 102.7169 | P13: 223.4371 | Q13: 120 | R13: 120 | S13: 85.6 | T13: 186.2 | U13: 0 | V13: 1 | W13: 1 | X13: 2.1718 | Y13: -103.4371 | Z13: 17.2831 | AA13: -47.63
... A365: 1329 | B365: BATT-PACK-00286 | C365: BATT-PACK | D365: Main battery pack | E365: FlightCritical | F365: 8 | G365: MU-027 | H365: MRD-8X | I365: HIGHLND | J365: Highland Operations | K365: 1 | M365: 0 | N365: 0 | O365: 0 | P365: 0 | Q365: 120 | R365: 120 | S365: 0 | T365: 0 | U365: 0 | V365: 0 | W365: 0 | X365: 1.908 | Y365: 120 | Z365: 120 | AA365: 62.89

Sheet Data_Queue
A1: PriorityRank | B1: InstallKey | C1: ComponentSerial | D1: ComponentCode | E1: ComponentName | F1: Criticality | G1: TailNumber | H1: BaseCode | I1: BaseName | J1: PositionNo | K1: InstalledDate | L1: FlightHours | M1: StressHours | N1: IntervalFlightHours | O1: IntervalStressHours | P1: PctOfHourInterval | Q1: PctOfStressInterval | R1: IsOverdueByHours | S1: IsOverdueByStress | T1: IsHiddenOverdue | U1: StressPerFlightHour | V1: RemainingStressHours | W1: ProjectedFlightHoursToStressLimit | X1: LeadTimeFlightHours | Y1: ActionCode | Z1: JobHours | AA1: CumulativeJobHours | AB1: IsThisWeek | AC1: RecommendedAction
A2: 1 | B2: 372 | C2: MOTOR-ESC-00100 | D2: MOTOR-ESC | E2: Motor and speed controller | F2: FlightCritical | G2: MU-008 | H2: HIGHLND | I2: Highland Operations | J2: 2 | L2: 186.2996 | M2: 402.1619 | N2: 200 | O2: 200 | P2: 93.15 | Q2: 201.08 | R2: 0 | S2: 1 | T2: 1 | U2: 2.3105 | V2: -202.1619 | W2: -87.5 | X2: 12 | Y2: GROUND_AND_REPLACE | Z2: 4.5 | AA2: 4.5 | AB2: 1 | AC2: Ground MU-008. Motor and speed controller at position 2 is at 201.08% of its stress interval while reading 93.15% on the hour meter.
A3: 2 | B3: 392 | C3: ROTOR-ASSY-00139 | D3: ROTOR-ASSY | E3: Rotor assembly and bearing | F3: FlightCritical | G3: MU-008 | H3: HIGHLND | I3: Highland Operations | J3: 2 | L3: 139.7328 | M3: 308.1946 | N3: 150 | O3: 150 | P3: 93.16 | Q3: 205.46 | R3: 0 | S3: 1 | T3: 1 | U3: 2.3105 | V3: -158.1946 | W3: -68.47 | X3: 18 | Y3: GROUND_AND_REPLACE | Z3: 4.5 | AA3: 9 | AB3: 1 | AC3: Ground MU-008. Rotor assembly and bearing at position 2 is at 205.46% of its stress interval while reading 93.16% on the hour meter.
A4: 3 | B4: 99 | C4: ROTOR-ASSY-00026 | D4: ROTOR-ASSY | E4: Rotor assembly and bearing | F4: FlightCritical | G4: MU-002 | H4: HIGHLND | I4: Highland Operations | J4: 1 | L4: 133.0167 | M4: 302.8206 | N4: 150 | O4: 150 | P4: 88.68 | Q4: 201.88 | R4: 0 | S4: 1 | T4: 1 | U4: 2.2807 | V4: -152.8206 | W4: -67.01 | X4: 18 | Y4: GROUND_AND_REPLACE | Z4: 4.5 | AA4: 13.5 | AB4: 1 | AC4: Ground MU-002. Rotor assembly and bearing at position 1 is at 201.88% of its stress interval while reading 88.68% on the hour meter.
A5: 4 | B5: 1503 | C5: ROTOR-ASSY-00545 | D5: ROTOR-ASSY | E5: Rotor assembly and bearing | F5: FlightCritical | G5: MU-030 | H5: PORT | I5: Port Logistics Hub | J5: 4 | L5: 147.0335 | M5: 299.8295 | N5: 150 | O5: 150 | P5: 98.02 | Q5: 199.89 | R5: 0 | S5: 1 | T5: 1 | U5: 1.9627 | V5: -149.8295 | W5: -76.34 | X5: 18 | Y5: GROUND_AND_REPLACE | Z5: 4.5 | AA5: 18 | AB5: 1 | AC5: Ground MU-030. Rotor assembly and bearing at position 4 is at 199.89% of its stress interval while reading 98.02% on the hour meter.
A6: 5 | B6: 722 | C6: MOTOR-ESC-00198 | D6: MOTOR-ESC | E6: Motor and speed controller | F6: FlightCritical | G6: MU-015 | H6: PORT | I6: Port Logistics Hub | J6: 2 | L6: 177.5832 | M6: 348.3593 | N6: 200 | O6: 200 | P6: 88.79 | Q6: 174.18 | R6: 0 | S6: 1 | T6: 1 | U6: 1.9216 | V6: -148.3593 | W6: -77.21 | X6: 12 | Y6: GROUND_AND_REPLACE | Z6: 4.5 | AA6: 22.5 | AB6: 1 | AC6: Ground MU-015. Motor and speed controller at position 2 is at 174.18% of its stress interval while reading 88.79% on the hour meter.
A7: 6 | B7: 23 | C7: MOTOR-ESC-00003 | D7: MOTOR-ESC | E7: Motor and speed controller | F7: FlightCritical | G7: MU-001 | H7: PORT | I7: Port Logistics Hub | J7: 1 | L7: 171.0173 | M7: 343.0481 | N7: 200 | O7: 200 | P7: 85.51 | Q7: 171.52 | R7: 0 | S7: 1 | T7: 1 | U7: 2.0638 | V7: -143.0481 | W7: -69.31 | X7: 12 | Y7: GROUND_AND_REPLACE | Z7: 4.5 | AA7: 27 | AB7: 1 | AC7: Ground MU-001. Motor and speed controller at position 1 is at 171.52% of its stress interval while reading 85.51% on the hour meter.
A8: 7 | B8: 26 | C8: MOTOR-ESC-00006 | D8: MOTOR-ESC | E8: Motor and speed controller | F8: FlightCritical | G8: MU-001 | H8: PORT | I8: Port Logistics Hub | J8: 2 | L8: 171.0173 | M8: 343.0481 | N8: 200 | O8: 200 | P8: 85.51 | Q8: 171.52 | R8: 0 | S8: 1 | T8: 1 | U8: 2.0638 | V8: -143.0481 | W8: -69.31 | X8: 12 | Y8: GROUND_AND_REPLACE | Z8: 4.5 | AA8: 31.5 | AB8: 1 | AC8: Ground MU-001. Motor and speed controller at position 2 is at 171.52% of its stress interval while reading 85.51% on the hour meter.
A9: 8 | B9: 85 | C9: MOTOR-ESC-00022 | D9: MOTOR-ESC | E9: Motor and speed controller | F9: FlightCritical | G9: MU-002 | H9: HIGHLND | I9: Highland Operations | J9: 2 | L9: 150.2001 | M9: 341.8081 | N9: 200 | O9: 200 | P9: 75.1 | Q9: 170.9 | R9: 0 | S9: 1 | T9: 1 | U9: 2.2807 | V9: -141.8081 | W9: -62.18 | X9: 12 | Y9: GROUND_AND_REPLACE | Z9: 4.5 | AA9: 36 | AB9: 1 | AC9: Ground MU-002. Motor and speed controller at position 2 is at 170.90% of its stress interval while reading 75.10% on the hour meter.
A10: 9 | B10: 1044 | C10: MOTOR-ESC-00284 | D10: MOTOR-ESC | E10: Motor and speed controller | F10: FlightCritical | G10: MU-021 | H10: ACADEMY | I10: Training Academy | J10: 1 | L10: 179.7 | M10: 336.7168 | N10: 200 | O10: 200 | P10: 89.85 | Q10: 168.36 | R10: 0 | S10: 1 | T10: 1 | U10: 1.9149 | V10: -136.7168 | W10: -71.4 | X10: 12 | Y10: GROUND_AND_REPLACE | Z10: 4.5 | AA10: 40.5 | AB10: 1 | AC10: Ground MU-021. Motor and speed controller at position 1 is at 168.36% of its stress interval while reading 89.85% on the hour meter.
A11: 10 | B11: 1046 | C11: MOTOR-ESC-00286 | D11: MOTOR-ESC | E11: Motor and speed controller | F11: FlightCritical | G11: MU-021 | H11: ACADEMY | I11: Training Academy | J11: 2 | L11: 179.7 | M11: 336.7168 | N11: 200 | O11: 200 | P11: 89.85 | Q11: 168.36 | R11: 0 | S11: 1 | T11: 1 | U11: 1.9149 | V11: -136.7168 | W11: -71.4 | X11: 12 | Y11: GROUND_AND_REPLACE | Z11: 4.5 | AA11: 45 | AB11: 1 | AC11: Ground MU-021. Motor and speed controller at position 2 is at 168.36% of its stress interval while reading 89.85% on the hour meter.
A12: 11 | B12: 1048 | C12: MOTOR-ESC-00288 | D12: MOTOR-ESC | E12: Motor and speed controller | F12: FlightCritical | G12: MU-021 | H12: ACADEMY | I12: Training Academy | J12: 3 | L12: 179.7 | M12: 336.7168 | N12: 200 | O12: 200 | P12: 89.85 | Q12: 168.36 | R12: 0 | S12: 1 | T12: 1 | U12: 1.9149 | V12: -136.7168 | W12: -71.4 | X12: 12 | Y12: GROUND_AND_REPLACE | Z12: 4.5 | AA12: 49.5 | AB12: 1 | AC12: Ground MU-021. Motor and speed controller at position 3 is at 168.36% of its stress interval while reading 89.85% on the hour meter.
A13: 12 | B13: 1001 | C13: MOTOR-ESC-00274 | D13: MOTOR-ESC | E13: Motor and speed controller | F13: FlightCritical | G13: MU-020 | H13: HIGHLND | I13: Highland Operations | J13: 2 | L13: 158.3329 | M13: 336.7002 | N13: 200 | O13: 200 | P13: 79.17 | Q13: 168.35 | R13: 0 | S13: 1 | T13: 1 | U13: 2.2582 | V13: -136.7002 | W13: -60.54 | X13: 12 | Y13: GROUND_AND_REPLACE | Z13: 4.5 | AA13: 54 | AB13: 1 | AC13: Ground MU-020. Motor and speed controller at position 2 is at 168.35% of its stress interval while reading 79.17% on the hour meter.
... A195: 194 | B195: 934 | C195: LANDGEAR-00059 | D195: LANDGEAR | E195: Landing gear assembly | F195: Degraded | G195: MU-019 | H195: PORT | I195: Port Logistics Hub | J195: 1 | L195: 97.4333 | M195: 183.5789 | N195: 250 | O195: 250 | P195: 38.97 | Q195: 73.43 | R195: 0 | S195: 0 | T195: 0 | U195: 1.8879 | V195: 66.4211 | W195: 35.18 | X195: 4 | Y195: SCHEDULE_THIS_MONTH | Z195: 1.5 | AA195: 682.5 | AB195: 0 | AC195: Schedule MU-019 within the month. Landing gear assembly projected to reach its stress limit in 35.18 flight hours.

Sheet Data_Base
A1: BaseCode | B1: BaseName | C1: Region | D1: HangarBays | E1: Airframes | F1: FlightHours | G1: StressHours | H1: StressRatio | I1: FittedComponents | J1: HourCompliancePct | K1: StressCompliancePct | L1: ComplianceGapPoints | M1: HiddenOverdue | N1: HiddenOverdueFlightCritical | O1: UnscheduledRatePct | P1: MaintenanceEvents | Q1: DowntimeHours
A2: PORT | B2: Port Logistics Hub | C2: East Estuary | D2: 3 | E2: 7 | F2: 4113.65 | G2: 8243.56 | H2: 2.004 | I2: 91 | J2: 98.9 | K2: 57.14 | L2: 41.76 | M2: 38 | N2: 27 | O2: 40.14 | P2: 147 | Q2: 1350.6
A3: ACADEMY | B3: Training Academy | C3: Central Plain | D3: 2 | E3: 4 | F3: 1359.57 | G3: 2527.95 | H3: 1.8594 | I3: 52 | J3: 100 | K3: 57.69 | L3: 42.31 | M3: 22 | N3: 17 | O3: 41.67 | P3: 48 | Q3: 496.6
A4: HIGHLND | B4: Highland Operations | C4: North Highlands | D4: 3 | E4: 7 | F4: 4106.12 | G4: 8841.26 | H4: 2.1532 | I4: 91 | J4: 100 | K4: 62.64 | L4: 37.36 | M4: 34 | N4: 29 | O4: 51.01 | P4: 149 | Q4: 1663.7
A5: COASTAL | B5: Coastal Survey Base | C5: West Coast | D5: 4 | E5: 10 | F5: 5572.45 | G5: 6542.66 | H5: 1.1741 | I5: 130 | J5: 100 | K5: 84.62 | L5: 15.38 | M5: 20 | N5: 16 | O5: 17.86 | P5: 168 | Q5: 1268.2

Sheet Data_KPI
A1: MetricName | B1: MetricValue | C1: Numerator | D1: Denominator | E1: TargetValue | F1: WarningValue | G1: Direction | H1: Unit | I1: RAGStatus | J1: Description
A2: ActionableLeadTimePct | B2: 37.81 | C2: 107 | D2: 283 | E2: 70 | F2: 50 | G2: HigherBetter | H2: Percent | I2: Red | J2: Share of predicted failures caught with enough remaining life to order and fit the part. The only prediction quality measure that changes a decision.
A3: AirframeAvailabilityPct | B3: 92.86 | C3: 26 | D3: 28 | E3: 85 | F3: 75 | G3: HigherBetter | H3: Percent | I3: Green | J3: Share of active airframes not grounded for maintenance at the reporting date.
A4: HourCompliancePct | B4: 99.73 | C4: 363 | D4: 364 | E4: 100 | F4: 95 | G4: HigherBetter | H4: Percent | I4: Amber | J4: Fitted components inside their interval measured in FLIGHT hours. What the maintenance system enforces today, reported because the programme reports it.
A5: OverdueFlightCritical | B5: 90 | C5: 90 | E5: 0 | F5: 2 | G5: LowerBetter | H5: Count | I5: Red | J5: Flight-critical components past their stress interval and still fitted.
A6: PredictionPrecisionPct | B6: 81.56 | C6: 283 | D6: 347 | E6: 75 | F6: 60 | G6: HigherBetter | H6: Percent | I6: Green | J6: Of components the model flags, the share that genuinely fail within the horizon. Low precision means crews stop believing the alerts.
A7: PredictionRecallPct | B7: 98.26 | C7: 283 | D7: 288 | E7: 80 | F7: 65 | G7: HigherBetter | H7: Percent | I7: Green | J7: Of components that genuinely fail, the share the model flagged. Recall alone is not enough -- see ActionableLeadTimePct.
A8: StressCompliancePct | B8: 68.41 | C8: 249 | D8: 364 | E8: 100 | F8: 95 | G8: HigherBetter | H8: Percent | I8: Red | J8: Fitted components inside their interval measured in STRESS hours. The real compliance figure; 100% is the only passing value on flight-critical parts.
A9: UnscheduledRatePct | B9: 36.13 | C9: 185 | D9: 512 | E9: 15 | F9: 25 | G9: LowerBetter | H9: Percent | I9: Red | J9: Unscheduled maintenance events as a share of all events. A fleet above this is being maintained by its failures.

Sheet Data_Sweep
A1: VibThreshold | B1: ComponentCode | C1: Population | D1: Failures | E1: AlertsRaised | F1: TP | G1: FP | H1: FN | I1: TN | J1: ActionableTP | K1: LateTP | L1: PrecisionPct | M1: RecallPct | N1: ActionableLeadTimePct | O1: PreventableFailurePct | P1: MedianLeadTimeFlightHours | Q1: LeadTimeFlightHours
A2: 1.2 | B2: MOTOR-ESC | C2: 302 | D2: 104 | E2: 254 | F2: 103 | G2: 151 | H2: 1 | I2: 47 | J2: 101 | K2: 2 | L2: 40.55 | M2: 99.04 | N2: 98.06 | O2: 97.12 | P2: 73.4 | Q2: 12
A3: 1.25 | B3: MOTOR-ESC | C3: 302 | D3: 104 | E3: 237 | F3: 103 | G3: 134 | H3: 1 | I3: 64 | J3: 101 | K3: 2 | L3: 43.46 | M3: 99.04 | N3: 98.06 | O3: 97.12 | P3: 67.9 | Q3: 12
A4: 1.3 | B4: MOTOR-ESC | C4: 302 | D4: 104 | E4: 222 | F4: 103 | G4: 119 | H4: 1 | I4: 79 | J4: 101 | K4: 2 | L4: 46.4 | M4: 99.04 | N4: 98.06 | O4: 97.12 | P4: 63.8 | Q4: 12
A5: 1.35 | B5: MOTOR-ESC | C5: 302 | D5: 104 | E5: 211 | F5: 103 | G5: 108 | H5: 1 | I5: 90 | J5: 101 | K5: 2 | L5: 48.82 | M5: 99.04 | N5: 98.06 | O5: 97.12 | P5: 61.87 | Q5: 12
A6: 1.4 | B6: MOTOR-ESC | C6: 302 | D6: 104 | E6: 201 | F6: 103 | G6: 98 | H6: 1 | I6: 100 | J6: 101 | K6: 2 | L6: 51.24 | M6: 99.04 | N6: 98.06 | O6: 97.12 | P6: 57.73 | Q6: 12
A7: 1.45 | B7: MOTOR-ESC | C7: 302 | D7: 104 | E7: 193 | F7: 103 | G7: 90 | H7: 1 | I7: 108 | J7: 101 | K7: 2 | L7: 53.37 | M7: 99.04 | N7: 98.06 | O7: 97.12 | P7: 56.2 | Q7: 12
A8: 1.5 | B8: MOTOR-ESC | C8: 302 | D8: 104 | E8: 187 | F8: 103 | G8: 84 | H8: 1 | I8: 114 | J8: 101 | K8: 2 | L8: 55.08 | M8: 99.04 | N8: 98.06 | O8: 97.12 | P8: 52.13 | Q8: 12
A9: 1.55 | B9: MOTOR-ESC | C9: 302 | D9: 104 | E9: 184 | F9: 103 | G9: 81 | H9: 1 | I9: 117 | J9: 99 | K9: 4 | L9: 55.98 | M9: 99.04 | N9: 96.12 | O9: 95.19 | P9: 50.07 | Q9: 12
A10: 1.6 | B10: MOTOR-ESC | C10: 302 | D10: 104 | E10: 182 | F10: 103 | G10: 79 | H10: 1 | I10: 119 | J10: 99 | K10: 4 | L10: 56.59 | M10: 99.04 | N10: 96.12 | O10: 95.19 | P10: 48.47 | Q10: 12
A11: 1.65 | B11: MOTOR-ESC | C11: 302 | D11: 104 | E11: 173 | F11: 103 | G11: 70 | H11: 1 | I11: 128 | J11: 99 | K11: 4 | L11: 59.54 | M11: 99.04 | N11: 96.12 | O11: 95.19 | P11: 45.38 | Q11: 12
A12: 1.7 | B12: MOTOR-ESC | C12: 302 | D12: 104 | E12: 169 | F12: 103 | G12: 66 | H12: 1 | I12: 132 | J12: 98 | K12: 5 | L12: 60.95 | M12: 99.04 | N12: 95.15 | O12: 94.23 | P12: 44.18 | Q12: 12
A13: 1.75 | B13: MOTOR-ESC | C13: 302 | D13: 104 | E13: 163 | F13: 103 | G13: 60 | H13: 1 | I13: 138 | J13: 97 | K13: 6 | L13: 63.19 | M13: 99.04 | N13: 94.17 | O13: 93.27 | P13: 42.87 | Q13: 12
... A115: 4 | B115: ROTOR-ASSY | C115: 432 | D115: 184 | E115: 209 | F115: 177 | G115: 32 | H115: 7 | I115: 216 | J115: 7 | K115: 170 | L115: 84.69 | M115: 96.2 | N115: 3.95 | O115: 3.8 | P115: 9.23 | Q115: 18

Sheet Data_Targets
A1: MetricName | B1: TargetValue | C1: WarningValue | D1: Direction | E1: Unit | F1: Description
A2: ActionableLeadTimePct | B2: 70 | C2: 50 | D2: HigherBetter | E2: Percent | F2: Share of predicted failures caught with enough remaining life to order and fit the part. The only prediction quality measure that changes a decision.
A3: AirframeAvailabilityPct | B3: 85 | C3: 75 | D3: HigherBetter | E3: Percent | F3: Share of active airframes not grounded for maintenance at the reporting date.
A4: HourCompliancePct | B4: 100 | C4: 95 | D4: HigherBetter | E4: Percent | F4: Fitted components inside their interval measured in FLIGHT hours. What the maintenance system enforces today, reported because the programme reports it.
A5: OverdueFlightCritical | B5: 0 | C5: 2 | D5: LowerBetter | E5: Count | F5: Flight-critical components past their stress interval and still fitted.
A6: PredictionPrecisionPct | B6: 75 | C6: 60 | D6: HigherBetter | E6: Percent | F6: Of components the model flags, the share that genuinely fail within the horizon. Low precision means crews stop believing the alerts.
A7: PredictionRecallPct | B7: 80 | C7: 65 | D7: HigherBetter | E7: Percent | F7: Of components that genuinely fail, the share the model flagged. Recall alone is not enough -- see ActionableLeadTimePct.
A8: StressCompliancePct | B8: 100 | C8: 95 | D8: HigherBetter | E8: Percent | F8: Fitted components inside their interval measured in STRESS hours. The real compliance figure; 100% is the only passing value on flight-critical parts.
A9: UnscheduledRatePct | B9: 15 | C9: 25 | D9: LowerBetter | E9: Percent | F9: Unscheduled maintenance events as a share of all events. A fleet above this is being maintained by its failures.

Sheet Data_Stress
A1: ProfileCode | B1: StressMultiplier | C1: CyclePenaltyHours | D1: PayloadPenaltyPerKg | E1: SourceNote
A2: MOUNTAIN | B2: 2.4 | C2: 0.06 | D2: 0.0085 | E2: Sustained high power at density altitude, with thermal turbulence. The largest hourly multiplier in the fleet and the reason the finding exists.
A3: CARGO | B3: 2.05 | C3: 0.04 | D3: 0.011 | E3: Continuous high rotor loading at maximum payload. Lower turbulence than mountain work but the highest payload penalty.
A4: SAR | B4: 1.85 | C4: 0.07 | D4: 0.006 | E4: Hover-heavy with an unpredictable profile, frequently flown in degraded conditions. Wide variance around this figure.
A5: URBAN | B5: 1.35 | C5: 0.055 | D5: 0.004 | E5: Turbulence loading from building wake plus a high landing count. The cycle penalty dominates the hourly multiplier on short sorties.
A6: TRAINING | B6: 1.15 | C6: 0.095 | D6: 0.001 | E6: Light payload reduces hourly loading, but circuit work produces far more landings per hour than any other profile. Training flies below the 12kg nominal, so the payload term goes NEGATIVE for this profile and removes stress -- which is the intent. A negative coefficient here would have added stress to a lighter aircraft.
A7: COASTAL | B7: 1 | C7: 0.02 | D7: 0 | E7: Baseline. Nominal payload, stable air, minimal thermal cycling. All other profiles are expressed relative to this.

Sheet Data_Interval
A1: ComponentCode | B1: IntervalFlightHours | C1: IntervalStressHours | D1: WeibullShape | E1: IntervalNote
A2: AIRDATA | B2: 400 | C2: 400 | D2: 1.05 | E2: Effectively random failure. Shape 1.05 means scheduled replacement buys almost nothing -- replacing it early replaces a good part with an equally failure-prone new one.
A3: BATT-PACK | B3: 120 | C3: 120 | D3: 1.8 | E3: Capacity fade. Deep discharge on high-payload profiles accelerates it well beyond what the hour meter suggests.
A4: GIMBAL | B4: 300 | C4: 300 | D4: 1.4 | E4: Servo and slip-ring wear. Nearly flat hazard: close to random failure, so condition monitoring earns less here than elsewhere.
A5: LANDGEAR | B5: 250 | C5: 250 | D5: 3.1 | E5: Fatigue driven almost entirely by landing count rather than airborne time. The clearest case in the fleet for measuring cycles instead of hours.
A6: MOTOR-ESC | B6: 200 | C6: 200 | D6: 2.1 | E6: Winding insulation and bearing degradation. Thermal cycling matters as much as running hours; the stress model has no temperature term, so cycling enters only through the per-landing cycle penalty and this interval is correspondingly approximate.
A7: ROTOR-ASSY | B7: 150 | C7: 150 | D7: 2.6 | E7: Bearing wear-out. Shape 2.6 means the failure rate rises steeply with accumulated stress -- the mean is a poor guide and the interval must be set on the distribution, not the average.

Sheet Data_Trend
A1: MonthEndDate | B1: MetricName | C1: MetricValue
B2: HourCompliancePct | C2: 99.5
B3: OverdueFlightCritical | C3: 109
B4: StressCompliancePct | C4: 69.92
B5: UnscheduledRatePct | C5: 57.14
B6: HourCompliancePct | C6: 100
B7: OverdueFlightCritical | C7: 94
B8: StressCompliancePct | C8: 71.93
B9: UnscheduledRatePct | C9: 48.54
B10: HourCompliancePct | C10: 100
B11: OverdueFlightCritical | C11: 106
B12: StressCompliancePct | C12: 68.09
B13: UnscheduledRatePct | C13: 48.33
... B97: UnscheduledRatePct | C97: 36.13

Sheet Data_DQ
A1: CheckCode | B1: CheckName | C1: Severity | D1: EntityType | E1: EntityRef | F1: Detail | G1: AffectsCurrentWear
A2: DQ-01 | B2: Duplicate sortie record | C2: High | D2: Sortie | E2: S-00008219 | F2: Airframe MU-024 on 2026-07-27: 2 identical sorties (94 min, 1 landings, same profile). Flight and stress hours are double counted. | G2: 1
A3: DQ-01 | B3: Duplicate sortie record | C3: High | D3: Sortie | E3: D-00008219 | F3: Airframe MU-024 on 2026-07-27: 2 identical sorties (94 min, 1 landings, same profile). Flight and stress hours are double counted. | G3: 1
A4: DQ-01 | B4: Duplicate sortie record | C4: High | D4: Sortie | E4: S-00003225 | F4: Airframe MU-010 on 2024-11-02: 2 identical sorties (102 min, 2 landings, same profile). Flight and stress hours are double counted. | G4: 0
A5: DQ-01 | B5: Duplicate sortie record | C5: High | D5: Sortie | E5: D-00003225 | F5: Airframe MU-010 on 2024-11-02: 2 identical sorties (102 min, 2 landings, same profile). Flight and stress hours are double counted. | G5: 0
A6: DQ-01 | B6: Duplicate sortie record | C6: High | D6: Sortie | E6: S-00006412 | F6: Airframe MU-020 on 2024-08-17: 2 identical sorties (169 min, 1 landings, same profile). Flight and stress hours are double counted. | G6: 0
A7: DQ-01 | B7: Duplicate sortie record | C7: High | D7: Sortie | E7: D-00006412 | F7: Airframe MU-020 on 2024-08-17: 2 identical sorties (169 min, 1 landings, same profile). Flight and stress hours are double counted. | G7: 0
A8: DQ-01 | B8: Duplicate sortie record | C8: High | D8: Sortie | E8: S-00009931 | F8: Airframe MU-030 on 2024-12-16: 2 identical sorties (172 min, 2 landings, same profile). Flight and stress hours are double counted. | G8: 0
A9: DQ-01 | B9: Duplicate sortie record | C9: High | D9: Sortie | E9: D-00009931 | F9: Airframe MU-030 on 2024-12-16: 2 identical sorties (172 min, 2 landings, same profile). Flight and stress hours are double counted. | G9: 0
A10: DQ-01 | B10: Duplicate sortie record | C10: High | D10: Sortie | E10: S-00006621 | F10: Airframe MU-020 on 2026-04-02: 2 identical sorties (137 min, 2 landings, same profile). Flight and stress hours are double counted. | G10: 1
A11: DQ-01 | B11: Duplicate sortie record | C11: High | D11: Sortie | E11: D-00006621 | F11: Airframe MU-020 on 2026-04-02: 2 identical sorties (137 min, 2 landings, same profile). Flight and stress hours are double counted. | G11: 1
A12: DQ-01 | B12: Duplicate sortie record | C12: High | D12: Sortie | E12: S-00001148 | F12: Airframe MU-004 on 2025-08-13: 2 identical sorties (95 min, 1 landings, same profile). Flight and stress hours are double counted. | G12: 0
