Workbook
Name AsOfDate: Control!$B$5
Name MaterialThreshold: Control!$B$9
Name NegotiationsPerBuyer: Control!$B$7
Name QueueRowsShown: Control!$B$8
Name SourceFolder: Control!$B$6
Name WinFrom: Calc!$C$4
Name WinTo: Calc!$C$5
Name xlTop5: Calc!$C$46
Name xlWindowAll: Calc!$C$47

Sheet README
A1: LUMEN OPTICS MANUFACTURING -- PHOTONICS SPEND SCORECARD
A3: Lumen Optics Manufacturing is a fictional photonics manufacturer. Every figure in this workbook is synthetic, generated by the SQL scripts in the sql\ folder of this project. No confidential data is used and no claim is made about any production system.
A5: THE QUESTION THIS ANSWERS
A6: Our purchase prices are flat or falling and every variance report is green -- so why is material cost per ACCEPTED unit rising, and which supplier-part combinations should sourcing renegotiate first?
A8: WHY PRICE VARIANCE CANNOT ANSWER IT
A9: Photonic components follow learning curves: unit prices decline as volumes rise and processes mature. Purchase price variance compares what was paid against what was AGREED, so a supplier who renews flat every year scores zero variance forever while quietly keeping everything the curve was supposed to hand back. Erosion capture measures that gap; price variance is structurally blind to it.
A11: SHEETS
A12: Dashboard The scorecard, the erosion position and the category cut. Every number is a formula over the extract.
A13: Renegotiation Queue Which supplier-part pair to open first, with the action and the annual value. Filters re-rank the list.
A14: Vendor Scorecard Cost index against the best available on the same parts, plus quality, delivery and compliance.
A15: Validation Each headline figure computed twice -- once in SQL, once in Excel -- and reconciled.
A16: Control Every parameter the workbook obeys.
... A27: Erosion is measured from the FIRST OBSERVED PRICE, so it detects a failure to erode, not whether the opening price was fair. A part bought badly in 2023 and eroded perfectly since will look healthy here. Answering that needs a should-cost build-up from materials and process, which is a different exercise with different inputs.

Sheet Dashboard
A1: LUMEN OPTICS MANUFACTURING -- PHOTONICS SPEND SCORECARD
A2: ="Twelve months to "&TEXT(AsOfDate,"d mmmm yyyy")&" | Fictional company, synthetic data, no production system." -> Twelve months to 31 December 2025 | Fictional company, synthetic data, no production system.
A4: THE QUESTION
A5: Our purchase prices are flat or falling and every variance report is green -- so why is material cost per ACCEPTED unit rising, and which supplier-part combinations should sourcing renegotiate first?
A7: SPEND -- recomputed in Excel from the purchase-order extract | E7: PRICE EROSION -- what the learning curve should have handed back
A8: Extended price (12 months) | C8: =SUMIFS(tPO[ExtendedPrice],tPO[OrderDate],">"&WinFrom,tPO[OrderDate],"<="&WinTo) -> 48586387 | E8: Vendor-part pairs assessed | G8: =COUNTA(tErosion[PartNumber]) -> 185
A9: Landed cost (12 months) | C9: =SUMIFS(tPO[LandedCost],tPO[OrderDate],">"&WinFrom,tPO[OrderDate],"<="&WinTo) -> 49474786 | E9: Spend-weighted erosion capture % | G9: =SUMPRODUCT(tErosion[ErosionCapturePct],tErosion[TTMSpend])/SUM(tErosion[TTMSpend]) -> 29.499101
A10: Freight | C10: =SUMIFS(tPO[FreightAmount],tPO[OrderDate],">"&WinFrom,tPO[OrderDate],"<="&WinTo) -> 779056.82 | E10: Annual opportunity (gross) | G10: =SUMIF(tErosion[AnnualOpportunity],">0") -> 4047608.7 | H10: Gross, not netted: a supplier already beating the curve is not a savings source and cannot fund another supplier's shortfall.
A11: Expedite fees | C11: =SUMIFS(tPO[ExpediteFee],tPO[OrderDate],">"&WinFrom,tPO[OrderDate],"<="&WinTo) -> 109342.24 | E11: Pairs already ahead of the curve | G11: =COUNTIF(tErosion[AnnualOpportunity],"<0") -> 19
A12: Off-contract spend | C12: =SUMIFS(tPO[ExtendedPrice],tPO[OrderDate],">"&WinFrom,tPO[OrderDate],"<="&WinTo,tPO[IsOnContract],0) -> 13161620 | E12: Value where already ahead | G12: =SUMIF(tErosion[AnnualOpportunity],"<0") -> -249428.64
A13: Single-source spend | C13: =SUMIFS(tPO[ExtendedPrice],tPO[OrderDate],">"&WinFrom,tPO[OrderDate],"<="&WinTo,tPO[IsSingleSource],1) -> 13201040 | E13: Pairs capturing under 20% | G13: =COUNTIFS(tErosion[ErosionCapturePct],"<20") -> 61
A14: Units received | C14: =SUMIFS(tPO[QtyReceived],tPO[OrderDate],">"&WinFrom,tPO[OrderDate],"<="&WinTo) -> 560046 | E14: Spend on those pairs | G14: =SUMIFS(tErosion[TTMSpend],tErosion[ErosionCapturePct],"<20") -> 17495221
A15: Units accepted | C15: =SUMIFS(tPO[QtyAccepted],tPO[OrderDate],">"&WinFrom,tPO[OrderDate],"<="&WinTo) -> 555083
A16: Value of rejected material | C16: =SUMIFS(tPO[RejectedValue],tPO[OrderDate],">"&WinFrom,tPO[OrderDate],"<="&WinTo) -> 498840.71
A18: SCORECARD -- status computed against the target table, not typed in
A19: Metric | B19: Value | C19: Target | D19: Warning | E19: Status | F19: Variance | G19: What it means
A20: Erosion capture % | B20: =$G$9 -> 29.499101 | C20: =INDEX(tTargets[TargetValue],MATCH("ErosionCapturePct",tTargets[MetricName],0)) -> 80 | D20: =INDEX(tTargets[WarningValue],MATCH("ErosionCapturePct",tTargets[MetricName],0)) -> 60 | E20: =IF(B20>=C20,"Green",IF(B20>=D20,"Amber","Red")) -> Red | F20: =C20-B20 -> 50.500899 | G20: Share of the expected category erosion actually realised. No price-variance report can see this gap.
A21: Maverick spend % | B21: =100*$C$12/$C$8 -> 27.08911 | C21: =INDEX(tTargets[TargetValue],MATCH("MaverickSpendPct",tTargets[MetricName],0)) -> 5 | D21: =INDEX(tTargets[WarningValue],MATCH("MaverickSpendPct",tTargets[MetricName],0)) -> 12 | E21: =IF(B21<=C21,"Green",IF(B21<=D21,"Amber","Red")) -> Red | F21: =B21-C21 -> 22.08911 | G21: Spend with no agreement in force. There is nothing to negotiate against until it is on contract.
A22: Purchase price variance % | B22: =100*SUMIFS(tPO[PPVAmount],tPO[OrderDate],">"&WinFrom,tPO[OrderDate],"<="&WinTo)/SUMIFS(tPO[ContractedExtended],tPO[OrderDate],">"&WinFrom,tPO[OrderDate],"<="&WinTo) -> -0.18902298 | C22: =INDEX(tTargets[TargetValue],MATCH("PPVPct",tTargets[MetricName],0)) -> 0 | D22: =INDEX(tTargets[WarningValue],MATCH("PPVPct",tTargets[MetricName],0)) -> 2 | E22: =IF(B22<=C22,"Green",IF(B22<=D22,"Amber","Red")) -> Green | F22: =B22-C22 -> -0.18902298 | G22: A supplier who renews flat scores zero here forever. Read it beside erosion capture, never alone.
A23: Acceptance rate % | B23: =100*$C$15/$C$14 -> 99.113823 | C23: =INDEX(tTargets[TargetValue],MATCH("AcceptanceRatePct",tTargets[MetricName],0)) -> 98 | D23: =INDEX(tTargets[WarningValue],MATCH("AcceptanceRatePct",tTargets[MetricName],0)) -> 95 | E23: =IF(B23>=C23,"Green",IF(B23>=D23,"Amber","Red")) -> Green | F23: =C23-B23 -> -1.1138228 | G23: Portfolio figure. Check the vendor-category cut before concluding anything.
A24: On-time delivery % | B24: =100*COUNTIFS(tPO[IsOnTime],1,tPO[OrderDate],">"&WinFrom,tPO[OrderDate],"<="&WinTo)/COUNTIFS(tPO[IsOnTime],">=0",tPO[OrderDate],">"&WinFrom,tPO[OrderDate],"<="&WinTo) -> 80.622837 | C24: =INDEX(tTargets[TargetValue],MATCH("OnTimeDeliveryPct",tTargets[MetricName],0)) -> 95 | D24: =INDEX(tTargets[WarningValue],MATCH("OnTimeDeliveryPct",tTargets[MetricName],0)) -> 90 | E24: =IF(B24>=C24,"Green",IF(B24>=D24,"Amber","Red")) -> Red | F24: =C24-B24 -> 14.377163 | G24: Receipts on or before the promised date.
A25: Expedite spend % | B25: =100*$C$11/$C$8 -> 0.22504707 | C25: =INDEX(tTargets[TargetValue],MATCH("ExpediteSpendPct",tTargets[MetricName],0)) -> 1 | D25: =INDEX(tTargets[WarningValue],MATCH("ExpediteSpendPct",tTargets[MetricName],0)) -> 3 | E25: =IF(B25<=C25,"Green",IF(B25<=D25,"Amber","Red")) -> Green | F25: =B25-C25 -> -0.77495293 | G25: Caused by planning, not by the supplier. Negotiable only by fixing the plan.
A26: Single-source spend % | B26: =100*$C$13/$C$8 -> 27.170244 | C26: =INDEX(tTargets[TargetValue],MATCH("SingleSourceSpendPct",tTargets[MetricName],0)) -> 20 | D26: =INDEX(tTargets[WarningValue],MATCH("SingleSourceSpendPct",tTargets[MetricName],0)) -> 35 | E26: =IF(B26<=C26,"Green",IF(B26<=D26,"Amber","Red")) -> Amber | F26: =B26-C26 -> 7.1702436 | G26: Where the largest erosion gaps sit and the least leverage exists.
A27: Top-5 vendor share % | B27: =100*xlTop5/xlWindowAll -> 27.198155 | C27: =INDEX(tTargets[TargetValue],MATCH("Top5VendorSharePct",tTargets[MetricName],0)) -> 50 | D27: =INDEX(tTargets[WarningValue],MATCH("Top5VendorSharePct",tTargets[MetricName],0)) -> 70 | E27: =IF(B27<=C27,"Green",IF(B27<=D27,"Amber","Red")) -> Green | F27: =B27-C27 -> -22.801845 | G27: Concentration of spend in the five largest suppliers.
A29: BY CATEGORY -- spend, benchmark and what was actually captured
A30: Category | B30: Spend (12m) | C30: Share % | D30: Benchmark erosion % | E30: Captured % | F30: Opportunity | G30: Maverick %
A31: =IFERROR(INDEX(tBenchmark[Category],1),"") -> Fibre Connector | B31: =IF($A31="","",SUMIFS(tPO[ExtendedPrice],tPO[OrderDate],">"&WinFrom,tPO[OrderDate],"<="&WinTo,tPO[Category],$A31)) -> 2929738.1 | C31: =IF($A31="","",100*B31/$C$8) -> 6.0299566 | D31: =IFERROR(INDEX(tBenchmark[AnnualErosionPct],1),"") -> 7 | E31: =IF($A31="","",IFERROR(SUMPRODUCT((tErosion[Category]=$A31)*tErosion[ErosionCapturePct]*tErosion[TTMSpend])/SUMPRODUCT((tErosion[Category]=$A31)*tErosion[TTMSpend]),"")) -> 28.839434 | F31: =IF($A31="","",SUMIFS(tErosion[AnnualOpportunity],tErosion[Category],$A31,tErosion[AnnualOpportunity],">0")) -> 359521.71 | G31: =IF($A31="","",IFERROR(100*SUMIFS(tPO[ExtendedPrice],tPO[OrderDate],">"&WinFrom,tPO[OrderDate],"<="&WinTo,tPO[Category],$A31,tPO[IsOnContract],0)/SUMIFS(tPO[ExtendedPrice],tPO[OrderDate],">"&WinFrom,tPO[OrderDate],"<="&WinTo,tPO[Category],$A31),"")) -> 10.011915
A32: =IFERROR(INDEX(tBenchmark[Category],2),"") -> Laser Diode | B32: =IF($A32="","",SUMIFS(tPO[ExtendedPrice],tPO[OrderDate],">"&WinFrom,tPO[OrderDate],"<="&WinTo,tPO[Category],$A32)) -> 10615765 | C32: =IF($A32="","",100*B32/$C$8) -> 21.849257 | D32: =IFERROR(INDEX(tBenchmark[AnnualErosionPct],2),"") -> 8 | E32: =IF($A32="","",IFERROR(SUMPRODUCT((tErosion[Category]=$A32)*tErosion[ErosionCapturePct]*tErosion[TTMSpend])/SUMPRODUCT((tErosion[Category]=$A32)*tErosion[TTMSpend]),"")) -> 42.984473 | F32: =IF($A32="","",SUMIFS(tErosion[AnnualOpportunity],tErosion[Category],$A32,tErosion[AnnualOpportunity],">0")) -> 1189602.5 | G32: =IF($A32="","",IFERROR(100*SUMIFS(tPO[ExtendedPrice],tPO[OrderDate],">"&WinFrom,tPO[OrderDate],"<="&WinTo,tPO[Category],$A32,tPO[IsOnContract],0)/SUMIFS(tPO[ExtendedPrice],tPO[OrderDate],">"&WinFrom,tPO[OrderDate],"<="&WinTo,tPO[Category],$A32),"")) -> 28.031512
A33: =IFERROR(INDEX(tBenchmark[Category],3),"") -> Lens Assembly | B33: =IF($A33="","",SUMIFS(tPO[ExtendedPrice],tPO[OrderDate],">"&WinFrom,tPO[OrderDate],"<="&WinTo,tPO[Category],$A33)) -> 5521842.9 | C33: =IF($A33="","",100*B33/$C$8) -> 11.365 | D33: =IFERROR(INDEX(tBenchmark[AnnualErosionPct],3),"") -> 3 | E33: =IF($A33="","",IFERROR(SUMPRODUCT((tErosion[Category]=$A33)*tErosion[ErosionCapturePct]*tErosion[TTMSpend])/SUMPRODUCT((tErosion[Category]=$A33)*tErosion[TTMSpend]),"")) -> -14.074411 | F33: =IF($A33="","",SUMIFS(tErosion[AnnualOpportunity],tErosion[Category],$A33,tErosion[AnnualOpportunity],">0")) -> 429596.73 | G33: =IF($A33="","",IFERROR(100*SUMIFS(tPO[ExtendedPrice],tPO[OrderDate],">"&WinFrom,tPO[OrderDate],"<="&WinTo,tPO[Category],$A33,tPO[IsOnContract],0)/SUMIFS(tPO[ExtendedPrice],tPO[OrderDate],">"&WinFrom,tPO[OrderDate],"<="&WinTo,tPO[Category],$A33),"")) -> 40.204204
A34: =IFERROR(INDEX(tBenchmark[Category],4),"") -> Optical Coating | B34: =IF($A34="","",SUMIFS(tPO[ExtendedPrice],tPO[OrderDate],">"&WinFrom,tPO[OrderDate],"<="&WinTo,tPO[Category],$A34)) -> 4144023.4 | C34: =IF($A34="","",100*B34/$C$8) -> 8.5291862 | D34: =IFERROR(INDEX(tBenchmark[AnnualErosionPct],4),"") -> 5 | E34: =IF($A34="","",IFERROR(SUMPRODUCT((tErosion[Category]=$A34)*tErosion[ErosionCapturePct]*tErosion[TTMSpend])/SUMPRODUCT((tErosion[Category]=$A34)*tErosion[TTMSpend]),"")) -> 43.097375 | F34: =IF($A34="","",SUMIFS(tErosion[AnnualOpportunity],tErosion[Category],$A34,tErosion[AnnualOpportunity],">0")) -> 259236 | G34: =IF($A34="","",IFERROR(100*SUMIFS(tPO[ExtendedPrice],tPO[OrderDate],">"&WinFrom,tPO[OrderDate],"<="&WinTo,tPO[Category],$A34,tPO[IsOnContract],0)/SUMIFS(tPO[ExtendedPrice],tPO[OrderDate],">"&WinFrom,tPO[OrderDate],"<="&WinTo,tPO[Category],$A34),"")) -> 22.588663
A35: =IFERROR(INDEX(tBenchmark[Category],5),"") -> Optical Fibre | B35: =IF($A35="","",SUMIFS(tPO[ExtendedPrice],tPO[OrderDate],">"&WinFrom,tPO[OrderDate],"<="&WinTo,tPO[Category],$A35)) -> 11843666 | C35: =IF($A35="","",100*B35/$C$8) -> 24.376511 | D35: =IFERROR(INDEX(tBenchmark[AnnualErosionPct],5),"") -> 4 | E35: =IF($A35="","",IFERROR(SUMPRODUCT((tErosion[Category]=$A35)*tErosion[ErosionCapturePct]*tErosion[TTMSpend])/SUMPRODUCT((tErosion[Category]=$A35)*tErosion[TTMSpend]),"")) -> 43.885711 | F35: =IF($A35="","",SUMIFS(tErosion[AnnualOpportunity],tErosion[Category],$A35,tErosion[AnnualOpportunity],">0")) -> 715059.09 | G35: =IF($A35="","",IFERROR(100*SUMIFS(tPO[ExtendedPrice],tPO[OrderDate],">"&WinFrom,tPO[OrderDate],"<="&WinTo,tPO[Category],$A35,tPO[IsOnContract],0)/SUMIFS(tPO[ExtendedPrice],tPO[OrderDate],">"&WinFrom,tPO[OrderDate],"<="&WinTo,tPO[Category],$A35),"")) -> 18.361652
A36: =IFERROR(INDEX(tBenchmark[Category],6),"") -> Photodetector | B36: =IF($A36="","",SUMIFS(tPO[ExtendedPrice],tPO[OrderDate],">"&WinFrom,tPO[OrderDate],"<="&WinTo,tPO[Category],$A36)) -> 6260935.7 | C36: =IF($A36="","",100*B36/$C$8) -> 12.886193 | D36: =IFERROR(INDEX(tBenchmark[AnnualErosionPct],6),"") -> 6.5 | E36: =IF($A36="","",IFERROR(SUMPRODUCT((tErosion[Category]=$A36)*tErosion[ErosionCapturePct]*tErosion[TTMSpend])/SUMPRODUCT((tErosion[Category]=$A36)*tErosion[TTMSpend]),"")) -> 30.426866 | F36: =IF($A36="","",SUMIFS(tErosion[AnnualOpportunity],tErosion[Category],$A36,tErosion[AnnualOpportunity],">0")) -> 619420.28 | G36: =IF($A36="","",IFERROR(100*SUMIFS(tPO[ExtendedPrice],tPO[OrderDate],">"&WinFrom,tPO[OrderDate],"<="&WinTo,tPO[Category],$A36,tPO[IsOnContract],0)/SUMIFS(tPO[ExtendedPrice],tPO[OrderDate],">"&WinFrom,tPO[OrderDate],"<="&WinTo,tPO[Category],$A36),"")) -> 40.060673
A37: =IFERROR(INDEX(tBenchmark[Category],7),"") -> Precision Mount | B37: =IF($A37="","",SUMIFS(tPO[ExtendedPrice],tPO[OrderDate],">"&WinFrom,tPO[OrderDate],"<="&WinTo,tPO[Category],$A37)) -> 3429103.1 | C37: =IF($A37="","",100*B37/$C$8) -> 7.0577447 | D37: =IFERROR(INDEX(tBenchmark[AnnualErosionPct],7),"") -> 2 | E37: =IF($A37="","",IFERROR(SUMPRODUCT((tErosion[Category]=$A37)*tErosion[ErosionCapturePct]*tErosion[TTMSpend])/SUMPRODUCT((tErosion[Category]=$A37)*tErosion[TTMSpend]),"")) -> -20.831331 | F37: =IF($A37="","",SUMIFS(tErosion[AnnualOpportunity],tErosion[Category],$A37,tErosion[AnnualOpportunity],">0")) -> 189051.85 | G37: =IF($A37="","",IFERROR(100*SUMIFS(tPO[ExtendedPrice],tPO[OrderDate],">"&WinFrom,tPO[OrderDate],"<="&WinTo,tPO[Category],$A37,tPO[IsOnContract],0)/SUMIFS(tPO[ExtendedPrice],tPO[OrderDate],">"&WinFrom,tPO[OrderDate],"<="&WinTo,tPO[Category],$A37),"")) -> 26.112233
A38: =IFERROR(INDEX(tBenchmark[Category],8),"") -> Thermal Control | B38: =IF($A38="","",SUMIFS(tPO[ExtendedPrice],tPO[OrderDate],">"&WinFrom,tPO[OrderDate],"<="&WinTo,tPO[Category],$A38)) -> 3841313 | C38: =IF($A38="","",100*B38/$C$8) -> 7.9061508 | D38: =IFERROR(INDEX(tBenchmark[AnnualErosionPct],8),"") -> 5.5 | E38: =IF($A38="","",IFERROR(SUMPRODUCT((tErosion[Category]=$A38)*tErosion[ErosionCapturePct]*tErosion[TTMSpend])/SUMPRODUCT((tErosion[Category]=$A38)*tErosion[TTMSpend]),"")) -> 38.547711 | F38: =IF($A38="","",SUMIFS(tErosion[AnnualOpportunity],tErosion[Category],$A38,tErosion[AnnualOpportunity],">0")) -> 286120.51 | G38: =IF($A38="","",IFERROR(100*SUMIFS(tPO[ExtendedPrice],tPO[OrderDate],">"&WinFrom,tPO[OrderDate],"<="&WinTo,tPO[Category],$A38,tPO[IsOnContract],0)/SUMIFS(tPO[ExtendedPrice],tPO[OrderDate],">"&WinFrom,tPO[OrderDate],"<="&WinTo,tPO[Category],$A38),"")) -> 30.150219
A39: TOTAL | B39: =SUM(B31:B38) -> 48586387 | C39: =SUM(C31:C38) -> 100 | F39: =SUM(F31:F38) -> 4047608.7

Sheet Renegotiation Queue
A1: RENEGOTIATION QUEUE
A2: Which supplier-part combination to renegotiate first. Ranked by annual opportunity; the ACTION is decided by leverage, because the biggest gaps sit where there is least of it.
B4: Category manager | C4: (All) | F4: Pairs matching | H4: =SUM(Calc!$B$52:$B$236) -> 43
B5: Action | C5: (All) | F5: Annual opportunity in scope | H5: =SUMPRODUCT(Calc!$B$52:$B$236,tQueue[AnnualOpportunity]) -> 2673946.2
B6: Category | C6: (All) | F6: Spend in scope (12m) | H6: =SUMPRODUCT(Calc!$B$52:$B$236,tQueue[TTMSpend]) -> 18583467
B7: This quarter only | C7: Yes | F7: ="Showing top "&MIN(QueueRowsShown,H4)&" of "&H4 -> Showing top 25 of 43
A9: # | B9: Part | C9: Category | D9: Vendor | E9: Manager | F9: Sources | G9: Bench % | H9: Actual % | I9: Capture % | J9: Gap / unit | K9: TTM spend | L9: Opportunity | M9: Leverage | N9: Action | O9: What to do
A10: =IF(1>MIN(QueueRowsShown,$H$4),"",1) -> 1 | B10: =IFERROR(INDEX(tQueue[PartNumber],MATCH(1,Calc!$C$52:$C$236,0)),"") -> LOM-0104 | C10: =IFERROR(INDEX(tQueue[Category],MATCH(1,Calc!$C$52:$C$236,0)),"") -> Laser Diode | D10: =IFERROR(INDEX(tQueue[VendorID],MATCH(1,Calc!$C$52:$C$236,0)),"") -> VEN-003 | E10: =IFERROR(INDEX(tQueue[BuyerName],MATCH(1,Calc!$C$52:$C$236,0)),"") -> Adaeze Okonkwo | F10: =IFERROR(INDEX(tQueue[QualifiedSupplierCount],MATCH(1,Calc!$C$52:$C$236,0)),"") -> 2 | G10: =IFERROR(INDEX(tQueue[BenchmarkErosionPct],MATCH(1,Calc!$C$52:$C$236,0)),"") -> 8 | H10: =IFERROR(INDEX(tQueue[ActualErosionPct],MATCH(1,Calc!$C$52:$C$236,0)),"") -> -4.474 | I10: =IFERROR(INDEX(tQueue[ErosionCapturePct],MATCH(1,Calc!$C$52:$C$236,0)),"") -> -55.93 | J10: =IFERROR(INDEX(tQueue[ErosionGapPerUnit],MATCH(1,Calc!$C$52:$C$236,0)),"") -> 180.3505 | K10: =IFERROR(INDEX(tQueue[TTMSpend],MATCH(1,Calc!$C$52:$C$236,0)),"") -> 714564.24 | L10: =IFERROR(INDEX(tQueue[AnnualOpportunity],MATCH(1,Calc!$C$52:$C$236,0)),"") -> 199828.4 | M10: =IFERROR(INDEX(tQueue[LeverageScore],MATCH(1,Calc!$C$52:$C$236,0)),"") -> 59 | N10: =IFERROR(INDEX(tQueue[ActionCode],MATCH(1,Calc!$C$52:$C$236,0)),"") -> PUT_ON_CONTRACT | O10: =IFERROR(INDEX(tQueue[RecommendedAction],MATCH(1,Calc!$C$52:$C$236,0)),"") -> Most of this spend has no agreement in force. Put it under contract before attempting to negotiate a price against nothing.
A11: =IF(2>MIN(QueueRowsShown,$H$4),"",2) -> 2 | B11: =IFERROR(INDEX(tQueue[PartNumber],MATCH(2,Calc!$C$52:$C$236,0)),"") -> LOM-0128 | C11: =IFERROR(INDEX(tQueue[Category],MATCH(2,Calc!$C$52:$C$236,0)),"") -> Laser Diode | D11: =IFERROR(INDEX(tQueue[VendorID],MATCH(2,Calc!$C$52:$C$236,0)),"") -> VEN-015 | E11: =IFERROR(INDEX(tQueue[BuyerName],MATCH(2,Calc!$C$52:$C$236,0)),"") -> Adaeze Okonkwo | F11: =IFERROR(INDEX(tQueue[QualifiedSupplierCount],MATCH(2,Calc!$C$52:$C$236,0)),"") -> 2 | G11: =IFERROR(INDEX(tQueue[BenchmarkErosionPct],MATCH(2,Calc!$C$52:$C$236,0)),"") -> 8 | H11: =IFERROR(INDEX(tQueue[ActualErosionPct],MATCH(2,Calc!$C$52:$C$236,0)),"") -> 0.738 | I11: =IFERROR(INDEX(tQueue[ErosionCapturePct],MATCH(2,Calc!$C$52:$C$236,0)),"") -> 9.23 | J11: =IFERROR(INDEX(tQueue[ErosionGapPerUnit],MATCH(2,Calc!$C$52:$C$236,0)),"") -> 150.6214 | K11: =IFERROR(INDEX(tQueue[TTMSpend],MATCH(2,Calc!$C$52:$C$236,0)),"") -> 997643.82 | L11: =IFERROR(INDEX(tQueue[AnnualOpportunity],MATCH(2,Calc!$C$52:$C$236,0)),"") -> 179088.8 | M11: =IFERROR(INDEX(tQueue[LeverageScore],MATCH(2,Calc!$C$52:$C$236,0)),"") -> 35 | N11: =IFERROR(INDEX(tQueue[ActionCode],MATCH(2,Calc!$C$52:$C$236,0)),"") -> RENEGOTIATE | O11: =IFERROR(INDEX(tQueue[RecommendedAction],MATCH(2,Calc!$C$52:$C$236,0)),"") -> Renegotiate. A qualified alternative exists, though Lumen is under 8% of this supplier's revenue: leverage is weak, but the gap is large enough to justify the meeting. Open with the category erosion benchmark.
A12: =IF(3>MIN(QueueRowsShown,$H$4),"",3) -> 3 | B12: =IFERROR(INDEX(tQueue[PartNumber],MATCH(3,Calc!$C$52:$C$236,0)),"") -> LOM-0096 | C12: =IFERROR(INDEX(tQueue[Category],MATCH(3,Calc!$C$52:$C$236,0)),"") -> Laser Diode | D12: =IFERROR(INDEX(tQueue[VendorID],MATCH(3,Calc!$C$52:$C$236,0)),"") -> VEN-011 | E12: =IFERROR(INDEX(tQueue[BuyerName],MATCH(3,Calc!$C$52:$C$236,0)),"") -> Adaeze Okonkwo | F12: =IFERROR(INDEX(tQueue[QualifiedSupplierCount],MATCH(3,Calc!$C$52:$C$236,0)),"") -> 1 | G12: =IFERROR(INDEX(tQueue[BenchmarkErosionPct],MATCH(3,Calc!$C$52:$C$236,0)),"") -> 8 | H12: =IFERROR(INDEX(tQueue[ActualErosionPct],MATCH(3,Calc!$C$52:$C$236,0)),"") -> -2.262 | I12: =IFERROR(INDEX(tQueue[ErosionCapturePct],MATCH(3,Calc!$C$52:$C$236,0)),"") -> -28.28 | J12: =IFERROR(INDEX(tQueue[ErosionGapPerUnit],MATCH(3,Calc!$C$52:$C$236,0)),"") -> 116.1129 | K12: =IFERROR(INDEX(tQueue[TTMSpend],MATCH(3,Calc!$C$52:$C$236,0)),"") -> 686912.99 | L12: =IFERROR(INDEX(tQueue[AnnualOpportunity],MATCH(3,Calc!$C$52:$C$236,0)),"") -> 176607.69 | M12: =IFERROR(INDEX(tQueue[LeverageScore],MATCH(3,Calc!$C$52:$C$236,0)),"") -> 37 | N12: =IFERROR(INDEX(tQueue[ActionCode],MATCH(3,Calc!$C$52:$C$236,0)),"") -> PUT_ON_CONTRACT | O12: =IFERROR(INDEX(tQueue[RecommendedAction],MATCH(3,Calc!$C$52:$C$236,0)),"") -> Most of this spend has no agreement in force. Put it under contract before attempting to negotiate a price against nothing.
A13: =IF(4>MIN(QueueRowsShown,$H$4),"",4) -> 4 | B13: =IFERROR(INDEX(tQueue[PartNumber],MATCH(4,Calc!$C$52:$C$236,0)),"") -> LOM-0048 | C13: =IFERROR(INDEX(tQueue[Category],MATCH(4,Calc!$C$52:$C$236,0)),"") -> Laser Diode | D13: =IFERROR(INDEX(tQueue[VendorID],MATCH(4,Calc!$C$52:$C$236,0)),"") -> VEN-008 | E13: =IFERROR(INDEX(tQueue[BuyerName],MATCH(4,Calc!$C$52:$C$236,0)),"") -> Adaeze Okonkwo | F13: =IFERROR(INDEX(tQueue[QualifiedSupplierCount],MATCH(4,Calc!$C$52:$C$236,0)),"") -> 3 | G13: =IFERROR(INDEX(tQueue[BenchmarkErosionPct],MATCH(4,Calc!$C$52:$C$236,0)),"") -> 8 | H13: =IFERROR(INDEX(tQueue[ActualErosionPct],MATCH(4,Calc!$C$52:$C$236,0)),"") -> 2.202 | I13: =IFERROR(INDEX(tQueue[ErosionCapturePct],MATCH(4,Calc!$C$52:$C$236,0)),"") -> 27.53 | J13: =IFERROR(INDEX(tQueue[ErosionGapPerUnit],MATCH(4,Calc!$C$52:$C$236,0)),"") -> 113.5144 | K13: =IFERROR(INDEX(tQueue[TTMSpend],MATCH(4,Calc!$C$52:$C$236,0)),"") -> 988567.39 | L13: =IFERROR(INDEX(tQueue[AnnualOpportunity],MATCH(4,Calc!$C$52:$C$236,0)),"") -> 154039.04 | M13: =IFERROR(INDEX(tQueue[LeverageScore],MATCH(4,Calc!$C$52:$C$236,0)),"") -> 70 | N13: =IFERROR(INDEX(tQueue[ActionCode],MATCH(4,Calc!$C$52:$C$236,0)),"") -> RENEGOTIATE | O13: =IFERROR(INDEX(tQueue[RecommendedAction],MATCH(4,Calc!$C$52:$C$236,0)),"") -> Renegotiate. A qualified alternative exists, though Lumen is under 8% of this supplier's revenue. Open with the category erosion benchmark.
A14: =IF(5>MIN(QueueRowsShown,$H$4),"",5) -> 5 | B14: =IFERROR(INDEX(tQueue[PartNumber],MATCH(5,Calc!$C$52:$C$236,0)),"") -> LOM-0057 | C14: =IFERROR(INDEX(tQueue[Category],MATCH(5,Calc!$C$52:$C$236,0)),"") -> Photodetector | D14: =IFERROR(INDEX(tQueue[VendorID],MATCH(5,Calc!$C$52:$C$236,0)),"") -> VEN-005 | E14: =IFERROR(INDEX(tQueue[BuyerName],MATCH(5,Calc!$C$52:$C$236,0)),"") -> Rafael Duarte | F14: =IFERROR(INDEX(tQueue[QualifiedSupplierCount],MATCH(5,Calc!$C$52:$C$236,0)),"") -> 1 | G14: =IFERROR(INDEX(tQueue[BenchmarkErosionPct],MATCH(5,Calc!$C$52:$C$236,0)),"") -> 6.5 | H14: =IFERROR(INDEX(tQueue[ActualErosionPct],MATCH(5,Calc!$C$52:$C$236,0)),"") -> -3.504 | I14: =IFERROR(INDEX(tQueue[ErosionCapturePct],MATCH(5,Calc!$C$52:$C$236,0)),"") -> -53.91 | J14: =IFERROR(INDEX(tQueue[ErosionGapPerUnit],MATCH(5,Calc!$C$52:$C$236,0)),"") -> 120.4996 | K14: =IFERROR(INDEX(tQueue[TTMSpend],MATCH(5,Calc!$C$52:$C$236,0)),"") -> 436614.97 | L14: =IFERROR(INDEX(tQueue[AnnualOpportunity],MATCH(5,Calc!$C$52:$C$236,0)),"") -> 105437.11 | M14: =IFERROR(INDEX(tQueue[LeverageScore],MATCH(5,Calc!$C$52:$C$236,0)),"") -> 37 | N14: =IFERROR(INDEX(tQueue[ActionCode],MATCH(5,Calc!$C$52:$C$236,0)),"") -> PUT_ON_CONTRACT | O14: =IFERROR(INDEX(tQueue[RecommendedAction],MATCH(5,Calc!$C$52:$C$236,0)),"") -> Most of this spend has no agreement in force. Put it under contract before attempting to negotiate a price against nothing.
A15: =IF(6>MIN(QueueRowsShown,$H$4),"",6) -> 6 | B15: =IFERROR(INDEX(tQueue[PartNumber],MATCH(6,Calc!$C$52:$C$236,0)),"") -> LOM-0082 | C15: =IFERROR(INDEX(tQueue[Category],MATCH(6,Calc!$C$52:$C$236,0)),"") -> Optical Fibre | D15: =IFERROR(INDEX(tQueue[VendorID],MATCH(6,Calc!$C$52:$C$236,0)),"") -> VEN-032 | E15: =IFERROR(INDEX(tQueue[BuyerName],MATCH(6,Calc!$C$52:$C$236,0)),"") -> Mei-Ling Chow | F15: =IFERROR(INDEX(tQueue[QualifiedSupplierCount],MATCH(6,Calc!$C$52:$C$236,0)),"") -> 1 | G15: =IFERROR(INDEX(tQueue[BenchmarkErosionPct],MATCH(6,Calc!$C$52:$C$236,0)),"") -> 4 | H15: =IFERROR(INDEX(tQueue[ActualErosionPct],MATCH(6,Calc!$C$52:$C$236,0)),"") -> 0.016 | I15: =IFERROR(INDEX(tQueue[ErosionCapturePct],MATCH(6,Calc!$C$52:$C$236,0)),"") -> 0.4 | J15: =IFERROR(INDEX(tQueue[ErosionGapPerUnit],MATCH(6,Calc!$C$52:$C$236,0)),"") -> 4.4279 | K15: =IFERROR(INDEX(tQueue[TTMSpend],MATCH(6,Calc!$C$52:$C$236,0)),"") -> 1026650.2 | L15: =IFERROR(INDEX(tQueue[AnnualOpportunity],MATCH(6,Calc!$C$52:$C$236,0)),"") -> 104353.4 | M15: =IFERROR(INDEX(tQueue[LeverageScore],MATCH(6,Calc!$C$52:$C$236,0)),"") -> 60 | N15: =IFERROR(INDEX(tQueue[ActionCode],MATCH(6,Calc!$C$52:$C$236,0)),"") -> RENEGOTIATE | O15: =IFERROR(INDEX(tQueue[RecommendedAction],MATCH(6,Calc!$C$52:$C$236,0)),"") -> Renegotiate. No second supplier is qualified, but Lumen is at least 8% of this supplier's revenue. Open with the category erosion benchmark.
A16: =IF(7>MIN(QueueRowsShown,$H$4),"",7) -> 7 | B16: =IFERROR(INDEX(tQueue[PartNumber],MATCH(7,Calc!$C$52:$C$236,0)),"") -> LOM-0024 | C16: =IFERROR(INDEX(tQueue[Category],MATCH(7,Calc!$C$52:$C$236,0)),"") -> Laser Diode | D16: =IFERROR(INDEX(tQueue[VendorID],MATCH(7,Calc!$C$52:$C$236,0)),"") -> VEN-019 | E16: =IFERROR(INDEX(tQueue[BuyerName],MATCH(7,Calc!$C$52:$C$236,0)),"") -> Rafael Duarte | F16: =IFERROR(INDEX(tQueue[QualifiedSupplierCount],MATCH(7,Calc!$C$52:$C$236,0)),"") -> 1 | G16: =IFERROR(INDEX(tQueue[BenchmarkErosionPct],MATCH(7,Calc!$C$52:$C$236,0)),"") -> 8 | H16: =IFERROR(INDEX(tQueue[ActualErosionPct],MATCH(7,Calc!$C$52:$C$236,0)),"") -> -0.976 | I16: =IFERROR(INDEX(tQueue[ErosionCapturePct],MATCH(7,Calc!$C$52:$C$236,0)),"") -> -12.2 | J16: =IFERROR(INDEX(tQueue[ErosionGapPerUnit],MATCH(7,Calc!$C$52:$C$236,0)),"") -> 98.9079 | K16: =IFERROR(INDEX(tQueue[TTMSpend],MATCH(7,Calc!$C$52:$C$236,0)),"") -> 454797.44 | L16: =IFERROR(INDEX(tQueue[AnnualOpportunity],MATCH(7,Calc!$C$52:$C$236,0)),"") -> 101479.51 | M16: =IFERROR(INDEX(tQueue[LeverageScore],MATCH(7,Calc!$C$52:$C$236,0)),"") -> 60 | N16: =IFERROR(INDEX(tQueue[ActionCode],MATCH(7,Calc!$C$52:$C$236,0)),"") -> RENEGOTIATE | O16: =IFERROR(INDEX(tQueue[RecommendedAction],MATCH(7,Calc!$C$52:$C$236,0)),"") -> Renegotiate. No second supplier is qualified, but Lumen is at least 8% of this supplier's revenue. Open with the category erosion benchmark.
A17: =IF(8>MIN(QueueRowsShown,$H$4),"",8) -> 8 | B17: =IFERROR(INDEX(tQueue[PartNumber],MATCH(8,Calc!$C$52:$C$236,0)),"") -> LOM-0130 | C17: =IFERROR(INDEX(tQueue[Category],MATCH(8,Calc!$C$52:$C$236,0)),"") -> Optical Fibre | D17: =IFERROR(INDEX(tQueue[VendorID],MATCH(8,Calc!$C$52:$C$236,0)),"") -> VEN-008 | E17: =IFERROR(INDEX(tQueue[BuyerName],MATCH(8,Calc!$C$52:$C$236,0)),"") -> Mei-Ling Chow | F17: =IFERROR(INDEX(tQueue[QualifiedSupplierCount],MATCH(8,Calc!$C$52:$C$236,0)),"") -> 1 | G17: =IFERROR(INDEX(tQueue[BenchmarkErosionPct],MATCH(8,Calc!$C$52:$C$236,0)),"") -> 4 | H17: =IFERROR(INDEX(tQueue[ActualErosionPct],MATCH(8,Calc!$C$52:$C$236,0)),"") -> -1.56 | I17: =IFERROR(INDEX(tQueue[ErosionCapturePct],MATCH(8,Calc!$C$52:$C$236,0)),"") -> -39 | J17: =IFERROR(INDEX(tQueue[ErosionGapPerUnit],MATCH(8,Calc!$C$52:$C$236,0)),"") -> 5.7597 | K17: =IFERROR(INDEX(tQueue[TTMSpend],MATCH(8,Calc!$C$52:$C$236,0)),"") -> 694927.1 | L17: =IFERROR(INDEX(tQueue[AnnualOpportunity],MATCH(8,Calc!$C$52:$C$236,0)),"") -> 96439.91 | M17: =IFERROR(INDEX(tQueue[LeverageScore],MATCH(8,Calc!$C$52:$C$236,0)),"") -> 27 | N17: =IFERROR(INDEX(tQueue[ActionCode],MATCH(8,Calc!$C$52:$C$236,0)),"") -> DUAL_SOURCE | O17: =IFERROR(INDEX(tQueue[RecommendedAction],MATCH(8,Calc!$C$52:$C$236,0)),"") -> Sole source with real money at stake and a reachable requalification. Qualify a second supplier, then reopen the price.
A18: =IF(9>MIN(QueueRowsShown,$H$4),"",9) -> 9 | B18: =IFERROR(INDEX(tQueue[PartNumber],MATCH(9,Calc!$C$52:$C$236,0)),"") -> LOM-0009 | C18: =IFERROR(INDEX(tQueue[Category],MATCH(9,Calc!$C$52:$C$236,0)),"") -> Photodetector | D18: =IFERROR(INDEX(tQueue[VendorID],MATCH(9,Calc!$C$52:$C$236,0)),"") -> VEN-020 | E18: =IFERROR(INDEX(tQueue[BuyerName],MATCH(9,Calc!$C$52:$C$236,0)),"") -> Adaeze Okonkwo | F18: =IFERROR(INDEX(tQueue[QualifiedSupplierCount],MATCH(9,Calc!$C$52:$C$236,0)),"") -> 3 | G18: =IFERROR(INDEX(tQueue[BenchmarkErosionPct],MATCH(9,Calc!$C$52:$C$236,0)),"") -> 6.5 | H18: =IFERROR(INDEX(tQueue[ActualErosionPct],MATCH(9,Calc!$C$52:$C$236,0)),"") -> 0.026 | I18: =IFERROR(INDEX(tQueue[ErosionCapturePct],MATCH(9,Calc!$C$52:$C$236,0)),"") -> 0.4 | J18: =IFERROR(INDEX(tQueue[ErosionGapPerUnit],MATCH(9,Calc!$C$52:$C$236,0)),"") -> 72.682 | K18: =IFERROR(INDEX(tQueue[TTMSpend],MATCH(9,Calc!$C$52:$C$236,0)),"") -> 557683.88 | L18: =IFERROR(INDEX(tQueue[AnnualOpportunity],MATCH(9,Calc!$C$52:$C$236,0)),"") -> 93977.83 | M18: =IFERROR(INDEX(tQueue[LeverageScore],MATCH(9,Calc!$C$52:$C$236,0)),"") -> 79 | N18: =IFERROR(INDEX(tQueue[ActionCode],MATCH(9,Calc!$C$52:$C$236,0)),"") -> RENEGOTIATE | O18: =IFERROR(INDEX(tQueue[RecommendedAction],MATCH(9,Calc!$C$52:$C$236,0)),"") -> Renegotiate. A qualified alternative exists, and Lumen is at least 8% of this supplier's revenue. Open with the category erosion benchmark.
A19: =IF(10>MIN(QueueRowsShown,$H$4),"",10) -> 10 | B19: =IFERROR(INDEX(tQueue[PartNumber],MATCH(10,Calc!$C$52:$C$236,0)),"") -> LOM-0106 | C19: =IFERROR(INDEX(tQueue[Category],MATCH(10,Calc!$C$52:$C$236,0)),"") -> Optical Fibre | D19: =IFERROR(INDEX(tQueue[VendorID],MATCH(10,Calc!$C$52:$C$236,0)),"") -> VEN-010 | E19: =IFERROR(INDEX(tQueue[BuyerName],MATCH(10,Calc!$C$52:$C$236,0)),"") -> Johan Lindberg | F19: =IFERROR(INDEX(tQueue[QualifiedSupplierCount],MATCH(10,Calc!$C$52:$C$236,0)),"") -> 1 | G19: =IFERROR(INDEX(tQueue[BenchmarkErosionPct],MATCH(10,Calc!$C$52:$C$236,0)),"") -> 4 | H19: =IFERROR(INDEX(tQueue[ActualErosionPct],MATCH(10,Calc!$C$52:$C$236,0)),"") -> 0.732 | I19: =IFERROR(INDEX(tQueue[ErosionCapturePct],MATCH(10,Calc!$C$52:$C$236,0)),"") -> 18.3 | J19: =IFERROR(INDEX(tQueue[ErosionGapPerUnit],MATCH(10,Calc!$C$52:$C$236,0)),"") -> 4.3014 | K19: =IFERROR(INDEX(tQueue[TTMSpend],MATCH(10,Calc!$C$52:$C$236,0)),"") -> 1096526.6 | L19: =IFERROR(INDEX(tQueue[AnnualOpportunity],MATCH(10,Calc!$C$52:$C$236,0)),"") -> 90892.88 | M19: =IFERROR(INDEX(tQueue[LeverageScore],MATCH(10,Calc!$C$52:$C$236,0)),"") -> 27 | N19: =IFERROR(INDEX(tQueue[ActionCode],MATCH(10,Calc!$C$52:$C$236,0)),"") -> DUAL_SOURCE | O19: =IFERROR(INDEX(tQueue[RecommendedAction],MATCH(10,Calc!$C$52:$C$236,0)),"") -> Sole source with real money at stake and a reachable requalification. Qualify a second supplier, then reopen the price.
A20: =IF(11>MIN(QueueRowsShown,$H$4),"",11) -> 11 | B20: =IFERROR(INDEX(tQueue[PartNumber],MATCH(11,Calc!$C$52:$C$236,0)),"") -> LOM-0120 | C20: =IFERROR(INDEX(tQueue[Category],MATCH(11,Calc!$C$52:$C$236,0)),"") -> Laser Diode | D20: =IFERROR(INDEX(tQueue[VendorID],MATCH(11,Calc!$C$52:$C$236,0)),"") -> VEN-016 | E20: =IFERROR(INDEX(tQueue[BuyerName],MATCH(11,Calc!$C$52:$C$236,0)),"") -> Adaeze Okonkwo | F20: =IFERROR(INDEX(tQueue[QualifiedSupplierCount],MATCH(11,Calc!$C$52:$C$236,0)),"") -> 3 | G20: =IFERROR(INDEX(tQueue[BenchmarkErosionPct],MATCH(11,Calc!$C$52:$C$236,0)),"") -> 8 | H20: =IFERROR(INDEX(tQueue[ActualErosionPct],MATCH(11,Calc!$C$52:$C$236,0)),"") -> 2.505 | I20: =IFERROR(INDEX(tQueue[ErosionCapturePct],MATCH(11,Calc!$C$52:$C$236,0)),"") -> 31.31 | J20: =IFERROR(INDEX(tQueue[ErosionGapPerUnit],MATCH(11,Calc!$C$52:$C$236,0)),"") -> 126.6776 | K20: =IFERROR(INDEX(tQueue[TTMSpend],MATCH(11,Calc!$C$52:$C$236,0)),"") -> 646871.89 | L20: =IFERROR(INDEX(tQueue[AnnualOpportunity],MATCH(11,Calc!$C$52:$C$236,0)),"") -> 85507.38 | M20: =IFERROR(INDEX(tQueue[LeverageScore],MATCH(11,Calc!$C$52:$C$236,0)),"") -> 77 | N20: =IFERROR(INDEX(tQueue[ActionCode],MATCH(11,Calc!$C$52:$C$236,0)),"") -> RENEGOTIATE | O20: =IFERROR(INDEX(tQueue[RecommendedAction],MATCH(11,Calc!$C$52:$C$236,0)),"") -> Renegotiate. A qualified alternative exists, though Lumen is under 8% of this supplier's revenue. Open with the category erosion benchmark.
A21: =IF(12>MIN(QueueRowsShown,$H$4),"",12) -> 12 | B21: =IFERROR(INDEX(tQueue[PartNumber],MATCH(12,Calc!$C$52:$C$236,0)),"") -> LOM-0123 | C21: =IFERROR(INDEX(tQueue[Category],MATCH(12,Calc!$C$52:$C$236,0)),"") -> Lens Assembly | D21: =IFERROR(INDEX(tQueue[VendorID],MATCH(12,Calc!$C$52:$C$236,0)),"") -> VEN-008 | E21: =IFERROR(INDEX(tQueue[BuyerName],MATCH(12,Calc!$C$52:$C$236,0)),"") -> Mei-Ling Chow | F21: =IFERROR(INDEX(tQueue[QualifiedSupplierCount],MATCH(12,Calc!$C$52:$C$236,0)),"") -> 3 | G21: =IFERROR(INDEX(tQueue[BenchmarkErosionPct],MATCH(12,Calc!$C$52:$C$236,0)),"") -> 3 | H21: =IFERROR(INDEX(tQueue[ActualErosionPct],MATCH(12,Calc!$C$52:$C$236,0)),"") -> -5.388 | I21: =IFERROR(INDEX(tQueue[ErosionCapturePct],MATCH(12,Calc!$C$52:$C$236,0)),"") -> -179.6 | J21: =IFERROR(INDEX(tQueue[ErosionGapPerUnit],MATCH(12,Calc!$C$52:$C$236,0)),"") -> 50.417 | K21: =IFERROR(INDEX(tQueue[TTMSpend],MATCH(12,Calc!$C$52:$C$236,0)),"") -> 410583.38 | L21: =IFERROR(INDEX(tQueue[AnnualOpportunity],MATCH(12,Calc!$C$52:$C$236,0)),"") -> 78045.54 | M21: =IFERROR(INDEX(tQueue[LeverageScore],MATCH(12,Calc!$C$52:$C$236,0)),"") -> 61 | N21: =IFERROR(INDEX(tQueue[ActionCode],MATCH(12,Calc!$C$52:$C$236,0)),"") -> PUT_ON_CONTRACT | O21: =IFERROR(INDEX(tQueue[RecommendedAction],MATCH(12,Calc!$C$52:$C$236,0)),"") -> Most of this spend has no agreement in force. Put it under contract before attempting to negotiate a price against nothing.
A22: =IF(13>MIN(QueueRowsShown,$H$4),"",13) -> 13 | B22: =IFERROR(INDEX(tQueue[PartNumber],MATCH(13,Calc!$C$52:$C$236,0)),"") -> LOM-0134 | C22: =IFERROR(INDEX(tQueue[Category],MATCH(13,Calc!$C$52:$C$236,0)),"") -> Fibre Connector | D22: =IFERROR(INDEX(tQueue[VendorID],MATCH(13,Calc!$C$52:$C$236,0)),"") -> VEN-010 | E22: =IFERROR(INDEX(tQueue[BuyerName],MATCH(13,Calc!$C$52:$C$236,0)),"") -> Johan Lindberg | F22: =IFERROR(INDEX(tQueue[QualifiedSupplierCount],MATCH(13,Calc!$C$52:$C$236,0)),"") -> 1 | G22: =IFERROR(INDEX(tQueue[BenchmarkErosionPct],MATCH(13,Calc!$C$52:$C$236,0)),"") -> 7 | H22: =IFERROR(INDEX(tQueue[ActualErosionPct],MATCH(13,Calc!$C$52:$C$236,0)),"") -> -0.256 | I22: =IFERROR(INDEX(tQueue[ErosionCapturePct],MATCH(13,Calc!$C$52:$C$236,0)),"") -> -3.66 | J22: =IFERROR(INDEX(tQueue[ErosionGapPerUnit],MATCH(13,Calc!$C$52:$C$236,0)),"") -> 7.5997 | K22: =IFERROR(INDEX(tQueue[TTMSpend],MATCH(13,Calc!$C$52:$C$236,0)),"") -> 375755.12 | L22: =IFERROR(INDEX(tQueue[AnnualOpportunity],MATCH(13,Calc!$C$52:$C$236,0)),"") -> 72706.7 | M22: =IFERROR(INDEX(tQueue[LeverageScore],MATCH(13,Calc!$C$52:$C$236,0)),"") -> 27 | N22: =IFERROR(INDEX(tQueue[ActionCode],MATCH(13,Calc!$C$52:$C$236,0)),"") -> DUAL_SOURCE | O22: =IFERROR(INDEX(tQueue[RecommendedAction],MATCH(13,Calc!$C$52:$C$236,0)),"") -> Sole source with real money at stake and a reachable requalification. Qualify a second supplier, then reopen the price.
A23: =IF(14>MIN(QueueRowsShown,$H$4),"",14) -> 14 | B23: =IFERROR(INDEX(tQueue[PartNumber],MATCH(14,Calc!$C$52:$C$236,0)),"") -> LOM-0098 | C23: =IFERROR(INDEX(tQueue[Category],MATCH(14,Calc!$C$52:$C$236,0)),"") -> Optical Fibre | D23: =IFERROR(INDEX(tQueue[VendorID],MATCH(14,Calc!$C$52:$C$236,0)),"") -> VEN-028 | E23: =IFERROR(INDEX(tQueue[BuyerName],MATCH(14,Calc!$C$52:$C$236,0)),"") -> Mei-Ling Chow | F23: =IFERROR(INDEX(tQueue[QualifiedSupplierCount],MATCH(14,Calc!$C$52:$C$236,0)),"") -> 3 | G23: =IFERROR(INDEX(tQueue[BenchmarkErosionPct],MATCH(14,Calc!$C$52:$C$236,0)),"") -> 4 | H23: =IFERROR(INDEX(tQueue[ActualErosionPct],MATCH(14,Calc!$C$52:$C$236,0)),"") -> 0.466 | I23: =IFERROR(INDEX(tQueue[ErosionCapturePct],MATCH(14,Calc!$C$52:$C$236,0)),"") -> 11.65 | J23: =IFERROR(INDEX(tQueue[ErosionGapPerUnit],MATCH(14,Calc!$C$52:$C$236,0)),"") -> 3.7052 | K23: =IFERROR(INDEX(tQueue[TTMSpend],MATCH(14,Calc!$C$52:$C$236,0)),"") -> 739415.54 | L23: =IFERROR(INDEX(tQueue[AnnualOpportunity],MATCH(14,Calc!$C$52:$C$236,0)),"") -> 66048.73 | M23: =IFERROR(INDEX(tQueue[LeverageScore],MATCH(14,Calc!$C$52:$C$236,0)),"") -> 90 | N23: =IFERROR(INDEX(tQueue[ActionCode],MATCH(14,Calc!$C$52:$C$236,0)),"") -> PUT_ON_CONTRACT | O23: =IFERROR(INDEX(tQueue[RecommendedAction],MATCH(14,Calc!$C$52:$C$236,0)),"") -> Most of this spend has no agreement in force. Put it under contract before attempting to negotiate a price against nothing.
A24: =IF(15>MIN(QueueRowsShown,$H$4),"",15) -> 15 | B24: =IFERROR(INDEX(tQueue[PartNumber],MATCH(15,Calc!$C$52:$C$236,0)),"") -> LOM-0074 | C24: =IFERROR(INDEX(tQueue[Category],MATCH(15,Calc!$C$52:$C$236,0)),"") -> Optical Fibre | D24: =IFERROR(INDEX(tQueue[VendorID],MATCH(15,Calc!$C$52:$C$236,0)),"") -> VEN-027 | E24: =IFERROR(INDEX(tQueue[BuyerName],MATCH(15,Calc!$C$52:$C$236,0)),"") -> Johan Lindberg | F24: =IFERROR(INDEX(tQueue[QualifiedSupplierCount],MATCH(15,Calc!$C$52:$C$236,0)),"") -> 1 | G24: =IFERROR(INDEX(tQueue[BenchmarkErosionPct],MATCH(15,Calc!$C$52:$C$236,0)),"") -> 4 | H24: =IFERROR(INDEX(tQueue[ActualErosionPct],MATCH(15,Calc!$C$52:$C$236,0)),"") -> 0.166 | I24: =IFERROR(INDEX(tQueue[ErosionCapturePct],MATCH(15,Calc!$C$52:$C$236,0)),"") -> 4.15 | J24: =IFERROR(INDEX(tQueue[ErosionGapPerUnit],MATCH(15,Calc!$C$52:$C$236,0)),"") -> 3.2367 | K24: =IFERROR(INDEX(tQueue[TTMSpend],MATCH(15,Calc!$C$52:$C$236,0)),"") -> 667640.96 | L24: =IFERROR(INDEX(tQueue[AnnualOpportunity],MATCH(15,Calc!$C$52:$C$236,0)),"") -> 64044.58 | M24: =IFERROR(INDEX(tQueue[LeverageScore],MATCH(15,Calc!$C$52:$C$236,0)),"") -> 36 | N24: =IFERROR(INDEX(tQueue[ActionCode],MATCH(15,Calc!$C$52:$C$236,0)),"") -> DUAL_SOURCE | O24: =IFERROR(INDEX(tQueue[RecommendedAction],MATCH(15,Calc!$C$52:$C$236,0)),"") -> Sole source with real money at stake and a reachable requalification. Qualify a second supplier, then reopen the price.
A25: =IF(16>MIN(QueueRowsShown,$H$4),"",16) -> 16 | B25: =IFERROR(INDEX(tQueue[PartNumber],MATCH(16,Calc!$C$52:$C$236,0)),"") -> LOM-0016 | C25: =IFERROR(INDEX(tQueue[Category],MATCH(16,Calc!$C$52:$C$236,0)),"") -> Laser Diode | D25: =IFERROR(INDEX(tQueue[VendorID],MATCH(16,Calc!$C$52:$C$236,0)),"") -> VEN-017 | E25: =IFERROR(INDEX(tQueue[BuyerName],MATCH(16,Calc!$C$52:$C$236,0)),"") -> Adaeze Okonkwo | F25: =IFERROR(INDEX(tQueue[QualifiedSupplierCount],MATCH(16,Calc!$C$52:$C$236,0)),"") -> 1 | G25: =IFERROR(INDEX(tQueue[BenchmarkErosionPct],MATCH(16,Calc!$C$52:$C$236,0)),"") -> 8 | H25: =IFERROR(INDEX(tQueue[ActualErosionPct],MATCH(16,Calc!$C$52:$C$236,0)),"") -> 0.142 | I25: =IFERROR(INDEX(tQueue[ErosionCapturePct],MATCH(16,Calc!$C$52:$C$236,0)),"") -> 1.78 | J25: =IFERROR(INDEX(tQueue[ErosionGapPerUnit],MATCH(16,Calc!$C$52:$C$236,0)),"") -> 51.8803 | K25: =IFERROR(INDEX(tQueue[TTMSpend],MATCH(16,Calc!$C$52:$C$236,0)),"") -> 341330.3 | L25: =IFERROR(INDEX(tQueue[AnnualOpportunity],MATCH(16,Calc!$C$52:$C$236,0)),"") -> 63760.89 | M25: =IFERROR(INDEX(tQueue[LeverageScore],MATCH(16,Calc!$C$52:$C$236,0)),"") -> 36 | N25: =IFERROR(INDEX(tQueue[ActionCode],MATCH(16,Calc!$C$52:$C$236,0)),"") -> DUAL_SOURCE | O25: =IFERROR(INDEX(tQueue[RecommendedAction],MATCH(16,Calc!$C$52:$C$236,0)),"") -> Sole source with real money at stake and a reachable requalification. Qualify a second supplier, then reopen the price.
A26: =IF(17>MIN(QueueRowsShown,$H$4),"",17) -> 17 | B26: =IFERROR(INDEX(tQueue[PartNumber],MATCH(17,Calc!$C$52:$C$236,0)),"") -> LOM-0097 | C26: =IFERROR(INDEX(tQueue[Category],MATCH(17,Calc!$C$52:$C$236,0)),"") -> Photodetector | D26: =IFERROR(INDEX(tQueue[VendorID],MATCH(17,Calc!$C$52:$C$236,0)),"") -> VEN-014 | E26: =IFERROR(INDEX(tQueue[BuyerName],MATCH(17,Calc!$C$52:$C$236,0)),"") -> Adaeze Okonkwo | F26: =IFERROR(INDEX(tQueue[QualifiedSupplierCount],MATCH(17,Calc!$C$52:$C$236,0)),"") -> 3 | G26: =IFERROR(INDEX(tQueue[BenchmarkErosionPct],MATCH(17,Calc!$C$52:$C$236,0)),"") -> 6.5 | H26: =IFERROR(INDEX(tQueue[ActualErosionPct],MATCH(17,Calc!$C$52:$C$236,0)),"") -> 2.137 | I26: =IFERROR(INDEX(tQueue[ErosionCapturePct],MATCH(17,Calc!$C$52:$C$236,0)),"") -> 32.88 | J26: =IFERROR(INDEX(tQueue[ErosionGapPerUnit],MATCH(17,Calc!$C$52:$C$236,0)),"") -> 52.6555 | K26: =IFERROR(INDEX(tQueue[TTMSpend],MATCH(17,Calc!$C$52:$C$236,0)),"") -> 548805.62 | L26: =IFERROR(INDEX(tQueue[AnnualOpportunity],MATCH(17,Calc!$C$52:$C$236,0)),"") -> 61764.9 | M26: =IFERROR(INDEX(tQueue[LeverageScore],MATCH(17,Calc!$C$52:$C$236,0)),"") -> 70 | N26: =IFERROR(INDEX(tQueue[ActionCode],MATCH(17,Calc!$C$52:$C$236,0)),"") -> RENEGOTIATE | O26: =IFERROR(INDEX(tQueue[RecommendedAction],MATCH(17,Calc!$C$52:$C$236,0)),"") -> Renegotiate. A qualified alternative exists, though Lumen is under 8% of this supplier's revenue. Open with the category erosion benchmark.
A27: =IF(18>MIN(QueueRowsShown,$H$4),"",18) -> 18 | B27: =IFERROR(INDEX(tQueue[PartNumber],MATCH(18,Calc!$C$52:$C$236,0)),"") -> LOM-0043 | C27: =IFERROR(INDEX(tQueue[Category],MATCH(18,Calc!$C$52:$C$236,0)),"") -> Lens Assembly | D27: =IFERROR(INDEX(tQueue[VendorID],MATCH(18,Calc!$C$52:$C$236,0)),"") -> VEN-029 | E27: =IFERROR(INDEX(tQueue[BuyerName],MATCH(18,Calc!$C$52:$C$236,0)),"") -> Johan Lindberg | F27: =IFERROR(INDEX(tQueue[QualifiedSupplierCount],MATCH(18,Calc!$C$52:$C$236,0)),"") -> 1 | G27: =IFERROR(INDEX(tQueue[BenchmarkErosionPct],MATCH(18,Calc!$C$52:$C$236,0)),"") -> 3 | H27: =IFERROR(INDEX(tQueue[ActualErosionPct],MATCH(18,Calc!$C$52:$C$236,0)),"") -> -3.536 | I27: =IFERROR(INDEX(tQueue[ErosionCapturePct],MATCH(18,Calc!$C$52:$C$236,0)),"") -> -117.87 | J27: =IFERROR(INDEX(tQueue[ErosionGapPerUnit],MATCH(18,Calc!$C$52:$C$236,0)),"") -> 51.3169 | K27: =IFERROR(INDEX(tQueue[TTMSpend],MATCH(18,Calc!$C$52:$C$236,0)),"") -> 378324.53 | L27: =IFERROR(INDEX(tQueue[AnnualOpportunity],MATCH(18,Calc!$C$52:$C$236,0)),"") -> 61734.18 | M27: =IFERROR(INDEX(tQueue[LeverageScore],MATCH(18,Calc!$C$52:$C$236,0)),"") -> 64 | N27: =IFERROR(INDEX(tQueue[ActionCode],MATCH(18,Calc!$C$52:$C$236,0)),"") -> PUT_ON_CONTRACT | O27: =IFERROR(INDEX(tQueue[RecommendedAction],MATCH(18,Calc!$C$52:$C$236,0)),"") -> Most of this spend has no agreement in force. Put it under contract before attempting to negotiate a price against nothing.
A28: =IF(19>MIN(QueueRowsShown,$H$4),"",19) -> 19 | B28: =IFERROR(INDEX(tQueue[PartNumber],MATCH(19,Calc!$C$52:$C$236,0)),"") -> LOM-0001 | C28: =IFERROR(INDEX(tQueue[Category],MATCH(19,Calc!$C$52:$C$236,0)),"") -> Photodetector | D28: =IFERROR(INDEX(tQueue[VendorID],MATCH(19,Calc!$C$52:$C$236,0)),"") -> VEN-015 | E28: =IFERROR(INDEX(tQueue[BuyerName],MATCH(19,Calc!$C$52:$C$236,0)),"") -> Rafael Duarte | F28: =IFERROR(INDEX(tQueue[QualifiedSupplierCount],MATCH(19,Calc!$C$52:$C$236,0)),"") -> 1 | G28: =IFERROR(INDEX(tQueue[BenchmarkErosionPct],MATCH(19,Calc!$C$52:$C$236,0)),"") -> 6.5 | H28: =IFERROR(INDEX(tQueue[ActualErosionPct],MATCH(19,Calc!$C$52:$C$236,0)),"") -> 0.538 | I28: =IFERROR(INDEX(tQueue[ErosionCapturePct],MATCH(19,Calc!$C$52:$C$236,0)),"") -> 8.28 | J28: =IFERROR(INDEX(tQueue[ErosionGapPerUnit],MATCH(19,Calc!$C$52:$C$236,0)),"") -> 54.52 | K28: =IFERROR(INDEX(tQueue[TTMSpend],MATCH(19,Calc!$C$52:$C$236,0)),"") -> 403455.27 | L28: =IFERROR(INDEX(tQueue[AnnualOpportunity],MATCH(19,Calc!$C$52:$C$236,0)),"") -> 60462.65 | M28: =IFERROR(INDEX(tQueue[LeverageScore],MATCH(19,Calc!$C$52:$C$236,0)),"") -> 23 | N28: =IFERROR(INDEX(tQueue[ActionCode],MATCH(19,Calc!$C$52:$C$236,0)),"") -> PUT_ON_CONTRACT | O28: =IFERROR(INDEX(tQueue[RecommendedAction],MATCH(19,Calc!$C$52:$C$236,0)),"") -> Most of this spend has no agreement in force. Put it under contract before attempting to negotiate a price against nothing.
A29: =IF(20>MIN(QueueRowsShown,$H$4),"",20) -> 20 | B29: =IFERROR(INDEX(tQueue[PartNumber],MATCH(20,Calc!$C$52:$C$236,0)),"") -> LOM-0034 | C29: =IFERROR(INDEX(tQueue[Category],MATCH(20,Calc!$C$52:$C$236,0)),"") -> Optical Fibre | D29: =IFERROR(INDEX(tQueue[VendorID],MATCH(20,Calc!$C$52:$C$236,0)),"") -> VEN-016 | E29: =IFERROR(INDEX(tQueue[BuyerName],MATCH(20,Calc!$C$52:$C$236,0)),"") -> Mei-Ling Chow | F29: =IFERROR(INDEX(tQueue[QualifiedSupplierCount],MATCH(20,Calc!$C$52:$C$236,0)),"") -> 2 | G29: =IFERROR(INDEX(tQueue[BenchmarkErosionPct],MATCH(20,Calc!$C$52:$C$236,0)),"") -> 4 | H29: =IFERROR(INDEX(tQueue[ActualErosionPct],MATCH(20,Calc!$C$52:$C$236,0)),"") -> 1.024 | I29: =IFERROR(INDEX(tQueue[ErosionCapturePct],MATCH(20,Calc!$C$52:$C$236,0)),"") -> 25.6 | J29: =IFERROR(INDEX(tQueue[ErosionGapPerUnit],MATCH(20,Calc!$C$52:$C$236,0)),"") -> 3.5834 | K29: =IFERROR(INDEX(tQueue[TTMSpend],MATCH(20,Calc!$C$52:$C$236,0)),"") -> 742352.47 | L29: =IFERROR(INDEX(tQueue[AnnualOpportunity],MATCH(20,Calc!$C$52:$C$236,0)),"") -> 54657.48 | M29: =IFERROR(INDEX(tQueue[LeverageScore],MATCH(20,Calc!$C$52:$C$236,0)),"") -> 47 | N29: =IFERROR(INDEX(tQueue[ActionCode],MATCH(20,Calc!$C$52:$C$236,0)),"") -> PUT_ON_CONTRACT | O29: =IFERROR(INDEX(tQueue[RecommendedAction],MATCH(20,Calc!$C$52:$C$236,0)),"") -> Most of this spend has no agreement in force. Put it under contract before attempting to negotiate a price against nothing.
A30: =IF(21>MIN(QueueRowsShown,$H$4),"",21) -> 21 | B30: =IFERROR(INDEX(tQueue[PartNumber],MATCH(21,Calc!$C$52:$C$236,0)),"") -> LOM-0048 | C30: =IFERROR(INDEX(tQueue[Category],MATCH(21,Calc!$C$52:$C$236,0)),"") -> Laser Diode | D30: =IFERROR(INDEX(tQueue[VendorID],MATCH(21,Calc!$C$52:$C$236,0)),"") -> VEN-014 | E30: =IFERROR(INDEX(tQueue[BuyerName],MATCH(21,Calc!$C$52:$C$236,0)),"") -> Rafael Duarte | F30: =IFERROR(INDEX(tQueue[QualifiedSupplierCount],MATCH(21,Calc!$C$52:$C$236,0)),"") -> 3 | G30: =IFERROR(INDEX(tQueue[BenchmarkErosionPct],MATCH(21,Calc!$C$52:$C$236,0)),"") -> 8 | H30: =IFERROR(INDEX(tQueue[ActualErosionPct],MATCH(21,Calc!$C$52:$C$236,0)),"") -> -0.085 | I30: =IFERROR(INDEX(tQueue[ErosionCapturePct],MATCH(21,Calc!$C$52:$C$236,0)),"") -> -1.06 | J30: =IFERROR(INDEX(tQueue[ErosionGapPerUnit],MATCH(21,Calc!$C$52:$C$236,0)),"") -> 160.3057 | K30: =IFERROR(INDEX(tQueue[TTMSpend],MATCH(21,Calc!$C$52:$C$236,0)),"") -> 241053.34 | L30: =IFERROR(INDEX(tQueue[AnnualOpportunity],MATCH(21,Calc!$C$52:$C$236,0)),"") -> 49855.09 | M30: =IFERROR(INDEX(tQueue[LeverageScore],MATCH(21,Calc!$C$52:$C$236,0)),"") -> 74 | N30: =IFERROR(INDEX(tQueue[ActionCode],MATCH(21,Calc!$C$52:$C$236,0)),"") -> PUT_ON_CONTRACT | O30: =IFERROR(INDEX(tQueue[RecommendedAction],MATCH(21,Calc!$C$52:$C$236,0)),"") -> Most of this spend has no agreement in force. Put it under contract before attempting to negotiate a price against nothing.
A31: =IF(22>MIN(QueueRowsShown,$H$4),"",22) -> 22 | B31: =IFERROR(INDEX(tQueue[PartNumber],MATCH(22,Calc!$C$52:$C$236,0)),"") -> LOM-0125 | C31: =IFERROR(INDEX(tQueue[Category],MATCH(22,Calc!$C$52:$C$236,0)),"") -> Precision Mount | D31: =IFERROR(INDEX(tQueue[VendorID],MATCH(22,Calc!$C$52:$C$236,0)),"") -> VEN-009 | E31: =IFERROR(INDEX(tQueue[BuyerName],MATCH(22,Calc!$C$52:$C$236,0)),"") -> Priya Raghunathan | F31: =IFERROR(INDEX(tQueue[QualifiedSupplierCount],MATCH(22,Calc!$C$52:$C$236,0)),"") -> 2 | G31: =IFERROR(INDEX(tQueue[BenchmarkErosionPct],MATCH(22,Calc!$C$52:$C$236,0)),"") -> 2 | H31: =IFERROR(INDEX(tQueue[ActualErosionPct],MATCH(22,Calc!$C$52:$C$236,0)),"") -> -6.799 | I31: =IFERROR(INDEX(tQueue[ErosionCapturePct],MATCH(22,Calc!$C$52:$C$236,0)),"") -> -339.95 | J31: =IFERROR(INDEX(tQueue[ErosionGapPerUnit],MATCH(22,Calc!$C$52:$C$236,0)),"") -> 46.8777 | K31: =IFERROR(INDEX(tQueue[TTMSpend],MATCH(22,Calc!$C$52:$C$236,0)),"") -> 235463.37 | L31: =IFERROR(INDEX(tQueue[AnnualOpportunity],MATCH(22,Calc!$C$52:$C$236,0)),"") -> 48846.59 | M31: =IFERROR(INDEX(tQueue[LeverageScore],MATCH(22,Calc!$C$52:$C$236,0)),"") -> 76 | N31: =IFERROR(INDEX(tQueue[ActionCode],MATCH(22,Calc!$C$52:$C$236,0)),"") -> PUT_ON_CONTRACT | O31: =IFERROR(INDEX(tQueue[RecommendedAction],MATCH(22,Calc!$C$52:$C$236,0)),"") -> Most of this spend has no agreement in force. Put it under contract before attempting to negotiate a price against nothing.
A32: =IF(23>MIN(QueueRowsShown,$H$4),"",23) -> 23 | B32: =IFERROR(INDEX(tQueue[PartNumber],MATCH(23,Calc!$C$52:$C$236,0)),"") -> LOM-0083 | C32: =IFERROR(INDEX(tQueue[Category],MATCH(23,Calc!$C$52:$C$236,0)),"") -> Lens Assembly | D32: =IFERROR(INDEX(tQueue[VendorID],MATCH(23,Calc!$C$52:$C$236,0)),"") -> VEN-003 | E32: =IFERROR(INDEX(tQueue[BuyerName],MATCH(23,Calc!$C$52:$C$236,0)),"") -> Johan Lindberg | F32: =IFERROR(INDEX(tQueue[QualifiedSupplierCount],MATCH(23,Calc!$C$52:$C$236,0)),"") -> 1 | G32: =IFERROR(INDEX(tQueue[BenchmarkErosionPct],MATCH(23,Calc!$C$52:$C$236,0)),"") -> 3 | H32: =IFERROR(INDEX(tQueue[ActualErosionPct],MATCH(23,Calc!$C$52:$C$236,0)),"") -> -0.147 | I32: =IFERROR(INDEX(tQueue[ErosionCapturePct],MATCH(23,Calc!$C$52:$C$236,0)),"") -> -4.9 | J32: =IFERROR(INDEX(tQueue[ErosionGapPerUnit],MATCH(23,Calc!$C$52:$C$236,0)),"") -> 28.7023 | K32: =IFERROR(INDEX(tQueue[TTMSpend],MATCH(23,Calc!$C$52:$C$236,0)),"") -> 550211.7 | L32: =IFERROR(INDEX(tQueue[AnnualOpportunity],MATCH(23,Calc!$C$52:$C$236,0)),"") -> 43570.09 | M32: =IFERROR(INDEX(tQueue[LeverageScore],MATCH(23,Calc!$C$52:$C$236,0)),"") -> 19 | N32: =IFERROR(INDEX(tQueue[ActionCode],MATCH(23,Calc!$C$52:$C$236,0)),"") -> DUAL_SOURCE | O32: =IFERROR(INDEX(tQueue[RecommendedAction],MATCH(23,Calc!$C$52:$C$236,0)),"") -> Sole source with real money at stake and a reachable requalification. Qualify a second supplier, then reopen the price.
A33: =IF(24>MIN(QueueRowsShown,$H$4),"",24) -> 24 | B33: =IFERROR(INDEX(tQueue[PartNumber],MATCH(24,Calc!$C$52:$C$236,0)),"") -> LOM-0042 | C33: =IFERROR(INDEX(tQueue[Category],MATCH(24,Calc!$C$52:$C$236,0)),"") -> Optical Fibre | D33: =IFERROR(INDEX(tQueue[VendorID],MATCH(24,Calc!$C$52:$C$236,0)),"") -> VEN-032 | E33: =IFERROR(INDEX(tQueue[BuyerName],MATCH(24,Calc!$C$52:$C$236,0)),"") -> Mei-Ling Chow | F33: =IFERROR(INDEX(tQueue[QualifiedSupplierCount],MATCH(24,Calc!$C$52:$C$236,0)),"") -> 1 | G33: =IFERROR(INDEX(tQueue[BenchmarkErosionPct],MATCH(24,Calc!$C$52:$C$236,0)),"") -> 4 | H33: =IFERROR(INDEX(tQueue[ActualErosionPct],MATCH(24,Calc!$C$52:$C$236,0)),"") -> 1.633 | I33: =IFERROR(INDEX(tQueue[ErosionCapturePct],MATCH(24,Calc!$C$52:$C$236,0)),"") -> 40.83 | J33: =IFERROR(INDEX(tQueue[ErosionGapPerUnit],MATCH(24,Calc!$C$52:$C$236,0)),"") -> 3.6684 | K33: =IFERROR(INDEX(tQueue[TTMSpend],MATCH(24,Calc!$C$52:$C$236,0)),"") -> 660641.39 | L33: =IFERROR(INDEX(tQueue[AnnualOpportunity],MATCH(24,Calc!$C$52:$C$236,0)),"") -> 42377.36 | M33: =IFERROR(INDEX(tQueue[LeverageScore],MATCH(24,Calc!$C$52:$C$236,0)),"") -> 46 | N33: =IFERROR(INDEX(tQueue[ActionCode],MATCH(24,Calc!$C$52:$C$236,0)),"") -> DUAL_SOURCE | O33: =IFERROR(INDEX(tQueue[RecommendedAction],MATCH(24,Calc!$C$52:$C$236,0)),"") -> Sole source with real money at stake and a reachable requalification. Qualify a second supplier, then reopen the price.
A34: =IF(25>MIN(QueueRowsShown,$H$4),"",25) -> 25 | B34: =IFERROR(INDEX(tQueue[PartNumber],MATCH(25,Calc!$C$52:$C$236,0)),"") -> LOM-0086 | C34: =IFERROR(INDEX(tQueue[Category],MATCH(25,Calc!$C$52:$C$236,0)),"") -> Fibre Connector | D34: =IFERROR(INDEX(tQueue[VendorID],MATCH(25,Calc!$C$52:$C$236,0)),"") -> VEN-004 | E34: =IFERROR(INDEX(tQueue[BuyerName],MATCH(25,Calc!$C$52:$C$236,0)),"") -> Mei-Ling Chow | F34: =IFERROR(INDEX(tQueue[QualifiedSupplierCount],MATCH(25,Calc!$C$52:$C$236,0)),"") -> 1 | G34: =IFERROR(INDEX(tQueue[BenchmarkErosionPct],MATCH(25,Calc!$C$52:$C$236,0)),"") -> 7 | H34: =IFERROR(INDEX(tQueue[ActualErosionPct],MATCH(25,Calc!$C$52:$C$236,0)),"") -> 0.603 | I34: =IFERROR(INDEX(tQueue[ErosionCapturePct],MATCH(25,Calc!$C$52:$C$236,0)),"") -> 8.61 | J34: =IFERROR(INDEX(tQueue[ErosionGapPerUnit],MATCH(25,Calc!$C$52:$C$236,0)),"") -> 4.9134 | K34: =IFERROR(INDEX(tQueue[TTMSpend],MATCH(25,Calc!$C$52:$C$236,0)),"") -> 264990.97 | L34: =IFERROR(INDEX(tQueue[AnnualOpportunity],MATCH(25,Calc!$C$52:$C$236,0)),"") -> 41537.77 | M34: =IFERROR(INDEX(tQueue[LeverageScore],MATCH(25,Calc!$C$52:$C$236,0)),"") -> 19 | N34: =IFERROR(INDEX(tQueue[ActionCode],MATCH(25,Calc!$C$52:$C$236,0)),"") -> DUAL_SOURCE | O34: =IFERROR(INDEX(tQueue[RecommendedAction],MATCH(25,Calc!$C$52:$C$236,0)),"") -> Sole source with real money at stake and a reachable requalification. Qualify a second supplier, then reopen the price.

Sheet Vendor Scorecard
A1: VENDOR SCORECARD
A2: Cost index compares each vendor with the cheapest cost per ACCEPTED unit on the same parts, so 100 is the best available and 108 is eight per cent dearer per usable part. Unit price alone cannot show this.
A4: Vendor | B4: Name | C4: Tier | D4: Spend (12m) | E4: Our share of their revenue % | F4: On contract % | G4: Acceptance % | H4: Rejected value | I4: On-time % | J4: Cost index vs best | K4: Shared parts | L4: Read
A5: =IFERROR(INDEX(tVendor[VendorID],1),"") -> VEN-008 | B5: =IFERROR(INDEX(tVendor[VendorName],1),"") -> Meridian Photonics GmbH | C5: =IFERROR(INDEX(tVendor[VendorTier],1),"") -> Preferred | D5: =IFERROR(INDEX(tVendor[TotalSpend],1),"") -> 8518594 | E5: =IFERROR(INDEX(tVendor[LumenRevenueSharePct],1),"") -> 5.01 | F5: =IFERROR(INDEX(tVendor[OnContractPct],1),"") -> 87.9 | G5: =IFERROR(INDEX(tVendor[AcceptanceRatePct],1),"") -> 99.13 | H5: =IFERROR(INDEX(tVendor[RejectedValue],1),"") -> 81655.48 | I5: =IFERROR(INDEX(tVendor[OnTimePct],1),"") -> 81.11 | J5: =IFERROR(INDEX(tVendor[CostIndexVsBest],1),"") -> 104.42 | K5: =IFERROR(INDEX(tVendor[SharedParts],1),"") -> 14 | L5: =IF(J5="","",IF(J5>105,"Dearer per usable part than the best alternative",IF(G5<97,"Quality is the problem, not price","Competitive"))) -> Competitive
A6: =IFERROR(INDEX(tVendor[VendorID],2),"") -> VEN-010 | B6: =IFERROR(INDEX(tVendor[VendorName],2),"") -> Vectra GmbH | C6: =IFERROR(INDEX(tVendor[VendorTier],2),"") -> Preferred | D6: =IFERROR(INDEX(tVendor[TotalSpend],2),"") -> 8098186.8 | E6: =IFERROR(INDEX(tVendor[LumenRevenueSharePct],2),"") -> 5.43 | F6: =IFERROR(INDEX(tVendor[OnContractPct],2),"") -> 89.75 | G6: =IFERROR(INDEX(tVendor[AcceptanceRatePct],2),"") -> 99.2 | H6: =IFERROR(INDEX(tVendor[RejectedValue],2),"") -> 62897.76 | I6: =IFERROR(INDEX(tVendor[OnTimePct],2),"") -> 81.84 | J6: =IFERROR(INDEX(tVendor[CostIndexVsBest],2),"") -> 101.77 | K6: =IFERROR(INDEX(tVendor[SharedParts],2),"") -> 10 | L6: =IF(J6="","",IF(J6>105,"Dearer per usable part than the best alternative",IF(G6<97,"Quality is the problem, not price","Competitive"))) -> Competitive
A7: =IFERROR(INDEX(tVendor[VendorID],3),"") -> VEN-016 | B7: =IFERROR(INDEX(tVendor[VendorName],3),"") -> Spectra Industries | C7: =IFERROR(INDEX(tVendor[VendorTier],3),"") -> Preferred | D7: =IFERROR(INDEX(tVendor[TotalSpend],3),"") -> 7562968.4 | E7: =IFERROR(INDEX(tVendor[LumenRevenueSharePct],3),"") -> 7.82 | F7: =IFERROR(INDEX(tVendor[OnContractPct],3),"") -> 79.49 | G7: =IFERROR(INDEX(tVendor[AcceptanceRatePct],3),"") -> 99.13 | H7: =IFERROR(INDEX(tVendor[RejectedValue],3),"") -> 77381.04 | I7: =IFERROR(INDEX(tVendor[OnTimePct],3),"") -> 77.95 | J7: =IFERROR(INDEX(tVendor[CostIndexVsBest],3),"") -> 100.8 | K7: =IFERROR(INDEX(tVendor[SharedParts],3),"") -> 11 | L7: =IF(J7="","",IF(J7>105,"Dearer per usable part than the best alternative",IF(G7<97,"Quality is the problem, not price","Competitive"))) -> Competitive
A8: =IFERROR(INDEX(tVendor[VendorID],4),"") -> VEN-032 | B8: =IFERROR(INDEX(tVendor[VendorName],4),"") -> Meridian Photonics Technologies | C8: =IFERROR(INDEX(tVendor[VendorTier],4),"") -> Transactional | D8: =IFERROR(INDEX(tVendor[TotalSpend],4),"") -> 7188922.6 | E8: =IFERROR(INDEX(tVendor[LumenRevenueSharePct],4),"") -> 28.3 | F8: =IFERROR(INDEX(tVendor[OnContractPct],4),"") -> 93.87 | G8: =IFERROR(INDEX(tVendor[AcceptanceRatePct],4),"") -> 99.28 | H8: =IFERROR(INDEX(tVendor[RejectedValue],4),"") -> 56967.13 | I8: =IFERROR(INDEX(tVendor[OnTimePct],4),"") -> 86.19 | J8: =IFERROR(INDEX(tVendor[CostIndexVsBest],4),"") -> 101.04 | K8: =IFERROR(INDEX(tVendor[SharedParts],4),"") -> 6 | L8: =IF(J8="","",IF(J8>105,"Dearer per usable part than the best alternative",IF(G8<97,"Quality is the problem, not price","Competitive"))) -> Competitive
A9: =IFERROR(INDEX(tVendor[VendorID],5),"") -> VEN-014 | B9: =IFERROR(INDEX(tVendor[VendorName],5),"") -> Photonica Industries | C9: =IFERROR(INDEX(tVendor[VendorTier],5),"") -> Preferred | D9: =IFERROR(INDEX(tVendor[TotalSpend],5),"") -> 6776342.2 | E9: =IFERROR(INDEX(tVendor[LumenRevenueSharePct],5),"") -> 4.81 | F9: =IFERROR(INDEX(tVendor[OnContractPct],5),"") -> 83.68 | G9: =IFERROR(INDEX(tVendor[AcceptanceRatePct],5),"") -> 99.15 | H9: =IFERROR(INDEX(tVendor[RejectedValue],5),"") -> 54049.22 | I9: =IFERROR(INDEX(tVendor[OnTimePct],5),"") -> 84.48 | J9: =IFERROR(INDEX(tVendor[CostIndexVsBest],5),"") -> 104.15 | K9: =IFERROR(INDEX(tVendor[SharedParts],5),"") -> 13 | L9: =IF(J9="","",IF(J9>105,"Dearer per usable part than the best alternative",IF(G9<97,"Quality is the problem, not price","Competitive"))) -> Competitive
A10: =IFERROR(INDEX(tVendor[VendorID],6),"") -> VEN-005 | B10: =IFERROR(INDEX(tVendor[VendorName],6),"") -> Helix Optics GmbH | C10: =IFERROR(INDEX(tVendor[VendorTier],6),"") -> Strategic | D10: =IFERROR(INDEX(tVendor[TotalSpend],6),"") -> 6535276.6 | E10: =IFERROR(INDEX(tVendor[LumenRevenueSharePct],6),"") -> 1.75 | F10: =IFERROR(INDEX(tVendor[OnContractPct],6),"") -> 80.07 | G10: =IFERROR(INDEX(tVendor[AcceptanceRatePct],6),"") -> 99.15 | H10: =IFERROR(INDEX(tVendor[RejectedValue],6),"") -> 60207.61 | I10: =IFERROR(INDEX(tVendor[OnTimePct],6),"") -> 84.25 | J10: =IFERROR(INDEX(tVendor[CostIndexVsBest],6),"") -> 101.57 | K10: =IFERROR(INDEX(tVendor[SharedParts],6),"") -> 11 | L10: =IF(J10="","",IF(J10>105,"Dearer per usable part than the best alternative",IF(G10<97,"Quality is the problem, not price","Competitive"))) -> Competitive
A11: =IFERROR(INDEX(tVendor[VendorID],7),"") -> VEN-003 | B11: =IFERROR(INDEX(tVendor[VendorName],7),"") -> Crystalline GmbH | C11: =IFERROR(INDEX(tVendor[VendorTier],7),"") -> Strategic | D11: =IFERROR(INDEX(tVendor[TotalSpend],7),"") -> 5774441.6 | E11: =IFERROR(INDEX(tVendor[LumenRevenueSharePct],7),"") -> 3.69 | F11: =IFERROR(INDEX(tVendor[OnContractPct],7),"") -> 74.79 | G11: =IFERROR(INDEX(tVendor[AcceptanceRatePct],7),"") -> 99.03 | H11: =IFERROR(INDEX(tVendor[RejectedValue],7),"") -> 60006.31 | I11: =IFERROR(INDEX(tVendor[OnTimePct],7),"") -> 82.17 | J11: =IFERROR(INDEX(tVendor[CostIndexVsBest],7),"") -> 102.13 | K11: =IFERROR(INDEX(tVendor[SharedParts],7),"") -> 6 | L11: =IF(J11="","",IF(J11>105,"Dearer per usable part than the best alternative",IF(G11<97,"Quality is the problem, not price","Competitive"))) -> Competitive
