Workbook
Name AsOfDate: Control!$B$5
Name Bucket90Threshold: Control!$B$9
Name CallsPerCollectorPerDay: Control!$B$7
Name DisputeDiscount: Control!$B$8
Name QueueRowsShown: Control!$B$10
Name SourceFolder: Control!$B$6
Name xlADD: Calc!$C$23
Name xlBPDSO: Calc!$C$22
Name xlDSOCountback: Calc!$C$20

Sheet README
A1: VANTAGE WHOLESALE SUPPLY -- RECEIVABLES CONTROL
A3: Vantage Wholesale Supply is a fictional industrial parts distributor. Every figure in this workbook is synthetic, generated by the SQL scripts in the sql\ folder of this project. No confidential data is used and no claim is made about any production system.
A5: THE QUESTION THIS ANSWERS
A6: DSO has risen. How many of those days did Vantage grant itself through the terms it sold, how many are customers taking beyond those terms, and who should collections call first?
A8: SHEETS
A9: Dashboard The scorecard, the DSO bridge and the ageing profile. Every number is a formula over the extract.
A10: Priority Queue The operational control: who to call, in what order, with the instruction and the dollar ask.
A11: Cash Application The OTHER worklist: money already banked that nobody matched. Where it covers at least half the past-due balance (APPLY_CASH) the account must not be called; elsewhere, quote the balance net of it.
A12: Ageing Matrix Open AR by bucket, cut by any dimension you pick.
A13: Validation Each headline figure computed twice -- once in SQL, once in Excel -- and reconciled.
A14: Control Every parameter the workbook obeys.
A15: Calc The working behind countback DSO and the queue ranking. Visible on purpose.
... A35: Nothing on the Dashboard is a pasted value. The balances come from SUMIFS over the open-item extract, the countback DSO from a real month-by-month loop on the Calc sheet, and the red/amber/green status from INDEX/MATCH against the target table -- so changing a target changes the status, and changing the data changes the numbers. The Validation sheet then checks the Excel implementation against the SQL one and says on its own face if they ever disagree.

Sheet Dashboard
A1: VANTAGE WHOLESALE SUPPLY -- RECEIVABLES PERFORMANCE
A2: ="Reporting date: "&TEXT(AsOfDate,"d mmmm yyyy")&" | Fictional company, synthetic data, no production system." -> Reporting date: 31 December 2025 | Fictional company, synthetic data, no production system.
A4: THE QUESTION
A5: DSO has risen. How many of those days did Vantage GRANT itself through the terms it sold, how many are customers TAKING beyond those terms -- and who should collections call first?
A7: BALANCES -- recomputed in Excel from the open-item extract | E7: DSO BRIDGE -- granted versus taken (these three add to classic DSO exactly)
A8: Total open AR | C8: =SUM(tOpenItems[OpenBalance]) -> 10847081 | E8: Component | F8: Days | G8: Cash | H8: Who owns it
A9: Not yet due (granted) | C9: =SUMIFS(tOpenItems[OpenBalance],tOpenItems[DaysPastDue],"<=0") -> 8095793.8 | E9: Granted -- not yet due | F9: =C9*$C$15/$C$14 -> 45.967923 | G9: =C9 -> 8095793.8 | H9: Sales / terms policy
A10: Past due, disputed | C10: =SUMIFS(tOpenItems[OpenBalance],tOpenItems[DaysPastDue],">0",tOpenItems[IsDisputedOpen],1) -> 154864.71 | E10: Taken -- disputed | F10: =C10*$C$15/$C$14 -> 0.87932194 | G10: =C10 -> 154864.71 | H10: Billing / sales
A11: Past due, undisputed | C11: =SUMIFS(tOpenItems[OpenBalance],tOpenItems[DaysPastDue],">0",tOpenItems[IsDisputedOpen],0) -> 2596423 | E11: Taken -- undisputed | F11: =C11*$C$15/$C$14 -> 14.742492 | G11: =C11 -> 2596423 | H11: Collections
A12: Of which 90+ days | C12: =SUMIFS(tOpenItems[OpenBalance],tOpenItems[DaysPastDue],">"&Bucket90Threshold) -> 362863.78 | E12: TOTAL -- classic DSO | F12: =C8*$C$15/$C$14 -> 61.589737 | G12: =C8 -> 10847081
A13: Open invoices | C13: =COUNTA(tOpenItems[InvoiceNo]) -> 2346 | E13: Check: parts less total | F13: =ROUND(F9+F10+F11-F12,10) -> 0 | H13: =IF(ABS(F13)<0.0000001,"Identity holds","BRIDGE DOES NOT CLOSE") -> Identity holds
A14: Credit sales, last 12 mths | C14: =SUMIFS(tSales[CreditSales],tSales[MonthEndDate],">"&EOMONTH(AsOfDate,-12),tSales[MonthEndDate],"<="&AsOfDate) -> 64283189 | E14: Weighted average terms sold | F14: =SUMPRODUCT((tSales[MonthEndDate]>EOMONTH(AsOfDate,-12))*(tSales[MonthEndDate]<=AsOfDate)*tSales[CreditSales]*tSales[WeightedAvgTermsDays])/$C$14 -> 46.675073 | H14: The floor: DSO if every customer paid exactly on the due date
A15: Days in that window | C15: =SUMIFS(tSales[DaysInMonth],tSales[MonthEndDate],">"&EOMONTH(AsOfDate,-12),tSales[MonthEndDate],"<="&AsOfDate) -> 365 | E15: DSO target | F15: =INDEX(tTargets[TargetValue],MATCH("DSO",tTargets[MetricName],0)) -> 45
A16: Credit sales per day | C16: =C14/C15 -> 176118.33 | E16: Allowance the target leaves over terms | F16: =F15-F14 -> -1.6750732 | H16: =IF(F16<0,"TARGET IS BELOW THE TERMS FLOOR -- unachievable","Achievable: "&TEXT(F16,"0.0")&" days of collection allowance") -> TARGET IS BELOW THE TERMS FLOOR -- unachievable
E17: Billing lag (despatch to invoice) | F17: =SUMPRODUCT((tLag[MonthEndDate]>EOMONTH(AsOfDate,-12))*(tLag[MonthEndDate]<=AsOfDate)*tLag[CreditSales]*tLag[BillingLagDays])/SUMPRODUCT((tLag[MonthEndDate]>EOMONTH(AsOfDate,-12))*(tLag[MonthEndDate]<=AsOfDate)*tLag[CreditSales]) -> 1.7841244 | H17: Before the DSO clock starts, so additive -- and the only days fixable without a customer conversation
E18: TRUE CASH CYCLE (despatch to cash) | F18: =F17+F12 -> 63.373862 | H18: ="Larger than the DSO anyone is reporting, by "&TEXT(F17,"0.00")&" days" -> Larger than the DSO anyone is reporting, by 1.78 days
A20: SCORECARD -- status is computed against the target table, not typed in
A21: Metric | B21: Value | C21: Target | D21: Warning | E21: Status | F21: Variance to target | G21: What it means
A22: DSO (countback) | B22: =xlDSOCountback -> 63.071066 | C22: =INDEX(tTargets[TargetValue],MATCH("DSO",tTargets[MetricName],0)) -> 45 | D22: =INDEX(tTargets[WarningValue],MATCH("DSO",tTargets[MetricName],0)) -> 55 | E22: =IF(INDEX(tTargets[Direction],MATCH("DSO",tTargets[MetricName],0))="LowerBetter",IF(B22<=C22,"Green",IF(B22<=D22,"Amber","Red")),IF(B22>=C22,"Green",IF(B22>=D22,"Amber","Red"))) -> Red | F22: =IF(INDEX(tTargets[Direction],MATCH("DSO",tTargets[MetricName],0))="LowerBetter",B22-C22,C22-B22) -> 18.071066 | G22: Days of recent sales sitting in receivables.
A23: Average days delinquent | B23: =xlADD -> 16.8 | C23: =INDEX(tTargets[TargetValue],MATCH("AvgDaysDelinquent",tTargets[MetricName],0)) -> 8 | D23: =INDEX(tTargets[WarningValue],MATCH("AvgDaysDelinquent",tTargets[MetricName],0)) -> 15 | E23: =IF(INDEX(tTargets[Direction],MATCH("AvgDaysDelinquent",tTargets[MetricName],0))="LowerBetter",IF(B23<=C23,"Green",IF(B23<=D23,"Amber","Red")),IF(B23>=C23,"Green",IF(B23>=D23,"Amber","Red"))) -> Red | F23: =IF(INDEX(tTargets[Direction],MATCH("AvgDaysDelinquent",tTargets[MetricName],0))="LowerBetter",B23-C23,C23-B23) -> 8.8 | G23: Days lost purely to late payment, terms stripped out.
A24: Past due share of AR | B24: =100*($C$10+$C$11)/$C$8 -> 25.364313 | C24: =INDEX(tTargets[TargetValue],MATCH("PctPastDue",tTargets[MetricName],0)) -> 15 | D24: =INDEX(tTargets[WarningValue],MATCH("PctPastDue",tTargets[MetricName],0)) -> 25 | E24: =IF(INDEX(tTargets[Direction],MATCH("PctPastDue",tTargets[MetricName],0))="LowerBetter",IF(B24<=C24,"Green",IF(B24<=D24,"Amber","Red")),IF(B24>=C24,"Green",IF(B24>=D24,"Amber","Red"))) -> Red | F24: =IF(INDEX(tTargets[Direction],MATCH("PctPastDue",tTargets[MetricName],0))="LowerBetter",B24-C24,C24-B24) -> 10.364313 | G24: By value. Compare with the count version before concluding anything.
A25: 90+ share of AR | B25: =100*$C$12/$C$8 -> 3.3452665 | C25: =INDEX(tTargets[TargetValue],MATCH("Pct90Plus",tTargets[MetricName],0)) -> 3 | D25: =INDEX(tTargets[WarningValue],MATCH("Pct90Plus",tTargets[MetricName],0)) -> 6 | E25: =IF(INDEX(tTargets[Direction],MATCH("Pct90Plus",tTargets[MetricName],0))="LowerBetter",IF(B25<=C25,"Green",IF(B25<=D25,"Amber","Red")),IF(B25>=C25,"Green",IF(B25>=D25,"Amber","Red"))) -> Amber | F25: =IF(INDEX(tTargets[Direction],MATCH("Pct90Plus",tTargets[MetricName],0))="LowerBetter",B25-C25,C25-B25) -> 0.34526647 | G25: Seriously delinquent balance as a share of the book.
A26: Collection effectiveness (book) | B26: =INDEX(tKPI[CEI_Book],MATCH(MAX(tKPI[AsOfDate]),tKPI[AsOfDate],0)) -> 66.91 | C26: =INDEX(tTargets[TargetValue],MATCH("CEI",tTargets[MetricName],0)) -> 85 | D26: =INDEX(tTargets[WarningValue],MATCH("CEI",tTargets[MetricName],0)) -> 75 | E26: =IF(B26>=C26,"Green",IF(B26>=D26,"Amber","Red")) -> Red | F26: =C26-B26 -> 18.09 | G26: ="Cash variant reads "&TEXT(INDEX(tKPI[CEI_Cash],MATCH(MAX(tKPI[AsOfDate]),tKPI[AsOfDate],0)),"0.00")&"%. The gap is write-offs counted as collections."&" (from SQL: needs a prior-month balance the open-item file does not carry.)" -> Cash variant reads 65.26%. The gap is write-offs counted as collections. (from SQL: needs a prior-month balance the open-item file does not carry.)
A27: Unapplied cash % of AR | B27: =100*SUM(tCashApp[UnappliedCash])/$C$8 -> 3.8664053 | C27: =INDEX(tTargets[TargetValue],MATCH("UnappliedCashPct",tTargets[MetricName],0)) -> 0.5 | D27: =INDEX(tTargets[WarningValue],MATCH("UnappliedCashPct",tTargets[MetricName],0)) -> 1.5 | E27: =IF(B27<=C27,"Green",IF(B27<=D27,"Amber","Red")) -> Red | F27: =B27-C27 -> 3.3664053 | G27: ="Cash banked against "&COUNTA(tCashApp[CustomerID])&" accounts that nobody has matched. Every dollar of it makes an invoice look unpaid when it is not." -> Cash banked against 97 accounts that nobody has matched. Every dollar of it makes an invoice look unpaid when it is not.
A28: Billing lag (days) | B28: =SUMPRODUCT((tLag[MonthEndDate]>EOMONTH(AsOfDate,-12))*(tLag[MonthEndDate]<=AsOfDate)*tLag[CreditSales]*tLag[BillingLagDays])/SUMPRODUCT((tLag[MonthEndDate]>EOMONTH(AsOfDate,-12))*(tLag[MonthEndDate]<=AsOfDate)*tLag[CreditSales]) -> 1.7841244 | C28: =INDEX(tTargets[TargetValue],MATCH("BillingLagDays",tTargets[MetricName],0)) -> 2 | D28: =INDEX(tTargets[WarningValue],MATCH("BillingLagDays",tTargets[MetricName],0)) -> 4 | E28: =IF(B28<=C28,"Green",IF(B28<=D28,"Amber","Red")) -> Green | F28: =B28-C28 -> -0.21587556 | G28: Despatch to invoice, dollar-weighted. Sits BEFORE the DSO clock starts, so it adds to the cycle rather than being part of DSO.
A29: Promise kept rate % | B29: =100*SUMIFS(tPromise[PromisedAmount],tPromise[PromiseStatus],"Kept",tPromise[PromisedPayDate],">"&EOMONTH(AsOfDate,-12))/SUMIFS(tPromise[PromisedAmount],tPromise[PromiseStatus],"<>Outstanding",tPromise[PromisedPayDate],">"&EOMONTH(AsOfDate,-12)) -> 86.599287 | C29: =INDEX(tTargets[TargetValue],MATCH("PromiseKeptRate",tTargets[MetricName],0)) -> 80 | D29: =INDEX(tTargets[WarningValue],MATCH("PromiseKeptRate",tTargets[MetricName],0)) -> 65 | E29: =IF(B29>=C29,"Green",IF(B29>=D29,"Amber","Red")) -> Green | F29: =C29-B29 -> -6.5992866 | G29: ="Portfolio figure. The High-risk tier reads "&TEXT(100*SUMIFS(tPromise[PromisedAmount],tPromise[PromiseStatus],"Kept",tPromise[RiskTier],"High")/SUMIFS(tPromise[PromisedAmount],tPromise[PromiseStatus],"<>Outstanding",tPromise[RiskTier],"High"),"0.0")&"% -- read the cohort, never the headline." -> Portfolio figure. The High-risk tier reads 54.6% -- read the cohort, never the headline.
A31: AGEING -- buckets re-derived in Excel from days past due, not taken from the extract
A32: Bucket | B32: Invoices | C32: Balance | D32: Share of AR | E32: Risk-weighted exposure
A33: =INDEX(tBuckets[BucketName],1) -> Current | B33: =COUNTIFS(tOpenItems[DaysPastDue],">="&INDEX(tBuckets[MinDaysPastDue],1),tOpenItems[DaysPastDue],"<="&INDEX(tBuckets[MaxDaysPastDue],1)) -> 1672 | C33: =SUMIFS(tOpenItems[OpenBalance],tOpenItems[DaysPastDue],">="&INDEX(tBuckets[MinDaysPastDue],1),tOpenItems[DaysPastDue],"<="&INDEX(tBuckets[MaxDaysPastDue],1)) -> 8095793.8 | D33: =C33/$C$8 -> 0.74635687 | E33: =C33*INDEX(tBuckets[RiskWeight],1) -> 0
A34: =INDEX(tBuckets[BucketName],2) -> 1-30 | B34: =COUNTIFS(tOpenItems[DaysPastDue],">="&INDEX(tBuckets[MinDaysPastDue],2),tOpenItems[DaysPastDue],"<="&INDEX(tBuckets[MaxDaysPastDue],2)) -> 414 | C34: =SUMIFS(tOpenItems[OpenBalance],tOpenItems[DaysPastDue],">="&INDEX(tBuckets[MinDaysPastDue],2),tOpenItems[DaysPastDue],"<="&INDEX(tBuckets[MaxDaysPastDue],2)) -> 1839519.4 | D34: =C34/$C$8 -> 0.16958658 | E34: =C34*INDEX(tBuckets[RiskWeight],2) -> 459879.85
A35: =INDEX(tBuckets[BucketName],3) -> 31-60 | B35: =COUNTIFS(tOpenItems[DaysPastDue],">="&INDEX(tBuckets[MinDaysPastDue],3),tOpenItems[DaysPastDue],"<="&INDEX(tBuckets[MaxDaysPastDue],3)) -> 101 | C35: =SUMIFS(tOpenItems[OpenBalance],tOpenItems[DaysPastDue],">="&INDEX(tBuckets[MinDaysPastDue],3),tOpenItems[DaysPastDue],"<="&INDEX(tBuckets[MaxDaysPastDue],3)) -> 405938.13 | D35: =C35/$C$8 -> 0.037423719 | E35: =C35*INDEX(tBuckets[RiskWeight],3) -> 202969.06
A36: =INDEX(tBuckets[BucketName],4) -> 61-90 | B36: =COUNTIFS(tOpenItems[DaysPastDue],">="&INDEX(tBuckets[MinDaysPastDue],4),tOpenItems[DaysPastDue],"<="&INDEX(tBuckets[MaxDaysPastDue],4)) -> 34 | C36: =SUMIFS(tOpenItems[OpenBalance],tOpenItems[DaysPastDue],">="&INDEX(tBuckets[MinDaysPastDue],4),tOpenItems[DaysPastDue],"<="&INDEX(tBuckets[MaxDaysPastDue],4)) -> 142966.39 | D36: =C36/$C$8 -> 0.013180171 | E36: =C36*INDEX(tBuckets[RiskWeight],4) -> 107224.79
A37: =INDEX(tBuckets[BucketName],5) -> 90+ | B37: =COUNTIFS(tOpenItems[DaysPastDue],">="&INDEX(tBuckets[MinDaysPastDue],5),tOpenItems[DaysPastDue],"<="&INDEX(tBuckets[MaxDaysPastDue],5)) -> 125 | C37: =SUMIFS(tOpenItems[OpenBalance],tOpenItems[DaysPastDue],">="&INDEX(tBuckets[MinDaysPastDue],5),tOpenItems[DaysPastDue],"<="&INDEX(tBuckets[MaxDaysPastDue],5)) -> 362863.78 | D37: =C37/$C$8 -> 0.033452665 | E37: =C37*INDEX(tBuckets[RiskWeight],5) -> 362863.78
A38: TOTAL | B38: =SUM(B33:B37) -> 2346 | C38: =SUM(C33:C37) -> 10847081 | D38: =SUM(D33:D37) -> 1 | E38: =SUM(E33:E37) -> 1132937.5

Sheet Priority Queue
A1: PRIORITY ACTION QUEUE
A2: Who collections should call first, ranked by risk-weighted money a call can actually move. Change the filters; the list re-ranks itself.
B4: Collector | C4: (All) | E4: Accounts matching | F4: =SUM(Calc!$B$28:$B$299) -> 65
B5: Action | C5: (All) | E5: Past due in scope | F5: =SUMPRODUCT(Calc!$B$28:$B$299,tQueue[PastDueBalance]) -> 1685560
B6: Today's worklist only | C6: Yes | E6: Collectable exposure in scope | F6: =SUMPRODUCT(Calc!$B$28:$B$299,tQueue[CollectableExposure]) -> 640540.01
B7: Minimum past due ($) | C7: 0 | E7: ="Showing top "&MIN(QueueRowsShown,F4)&" of "&F4 -> Showing top 25 of 65
A9: # | B9: Customer | C9: Segment | D9: Risk | E9: Collector | F9: Terms | G9: Open balance | H9: Past due | I9: 90+ | J9: Disputed | K9: Collectable exposure | L9: Oldest days | M9: Credit use % | N9: Hold | O9: Action | P9: What to do
A10: =IF(1>MIN(QueueRowsShown,$F$4),"",1) -> 1 | B10: =IFERROR(INDEX(tQueue[CustomerName],MATCH(1,Calc!$C$28:$C$299,0)),"") -> Ironbridge Components | C10: =IFERROR(INDEX(tQueue[Segment],MATCH(1,Calc!$C$28:$C$299,0)),"") -> OEM Manufacturer | D10: =IFERROR(INDEX(tQueue[RiskTier],MATCH(1,Calc!$C$28:$C$299,0)),"") -> High | E10: =IFERROR(INDEX(tQueue[CollectorName],MATCH(1,Calc!$C$28:$C$299,0)),"") -> Priya Natarajan | F10: =IFERROR(INDEX(tQueue[TermsCode],MATCH(1,Calc!$C$28:$C$299,0)),"") -> NET45 | G10: =IFERROR(INDEX(tQueue[OpenBalance],MATCH(1,Calc!$C$28:$C$299,0)),"") -> 171140.07 | H10: =IFERROR(INDEX(tQueue[PastDueBalance],MATCH(1,Calc!$C$28:$C$299,0)),"") -> 132293.14 | I10: =IFERROR(INDEX(tQueue[Balance90Plus],MATCH(1,Calc!$C$28:$C$299,0)),"") -> 0 | J10: =IFERROR(INDEX(tQueue[DisputedBalance],MATCH(1,Calc!$C$28:$C$299,0)),"") -> 15640.04 | K10: =IFERROR(INDEX(tQueue[CollectableExposure],MATCH(1,Calc!$C$28:$C$299,0)),"") -> 57024.44 | L10: =IFERROR(INDEX(tQueue[OldestDaysPastDue],MATCH(1,Calc!$C$28:$C$299,0)),"") -> 90 | M10: =IFERROR(INDEX(tQueue[CreditUtilizationPct],MATCH(1,Calc!$C$28:$C$299,0)),"") -> 38.03 | N10: =IFERROR(INDEX(tQueue[CreditHoldFlag],MATCH(1,Calc!$C$28:$C$299,0)),"") -> 0 | O10: =IFERROR(INDEX(tQueue[ActionCode],MATCH(1,Calc!$C$28:$C$299,0)),"") -> ESCALATE | P10: =IFERROR(INDEX(tQueue[RecommendedAction],MATCH(1,Calc!$C$28:$C$299,0)),"") -> Escalate: high-risk account carrying a 90+ balance. Hold further shipments and agree a payment plan or refer for recovery.
A11: =IF(2>MIN(QueueRowsShown,$F$4),"",2) -> 2 | B11: =IFERROR(INDEX(tQueue[CustomerName],MATCH(2,Calc!$C$28:$C$299,0)),"") -> Westbrook Industries - West | C11: =IFERROR(INDEX(tQueue[Segment],MATCH(2,Calc!$C$28:$C$299,0)),"") -> OEM Manufacturer | D11: =IFERROR(INDEX(tQueue[RiskTier],MATCH(2,Calc!$C$28:$C$299,0)),"") -> Medium | E11: =IFERROR(INDEX(tQueue[CollectorName],MATCH(2,Calc!$C$28:$C$299,0)),"") -> Marcus Bell | F11: =IFERROR(INDEX(tQueue[TermsCode],MATCH(2,Calc!$C$28:$C$299,0)),"") -> NET60 | G11: =IFERROR(INDEX(tQueue[OpenBalance],MATCH(2,Calc!$C$28:$C$299,0)),"") -> 122327.81 | H11: =IFERROR(INDEX(tQueue[PastDueBalance],MATCH(2,Calc!$C$28:$C$299,0)),"") -> 82857.53 | I11: =IFERROR(INDEX(tQueue[Balance90Plus],MATCH(2,Calc!$C$28:$C$299,0)),"") -> 0 | J11: =IFERROR(INDEX(tQueue[DisputedBalance],MATCH(2,Calc!$C$28:$C$299,0)),"") -> 0 | K11: =IFERROR(INDEX(tQueue[CollectableExposure],MATCH(2,Calc!$C$28:$C$299,0)),"") -> 37750.08 | L11: =IFERROR(INDEX(tQueue[OldestDaysPastDue],MATCH(2,Calc!$C$28:$C$299,0)),"") -> 68 | M11: =IFERROR(INDEX(tQueue[CreditUtilizationPct],MATCH(2,Calc!$C$28:$C$299,0)),"") -> 38.23 | N11: =IFERROR(INDEX(tQueue[CreditHoldFlag],MATCH(2,Calc!$C$28:$C$299,0)),"") -> 0 | O11: =IFERROR(INDEX(tQueue[ActionCode],MATCH(2,Calc!$C$28:$C$299,0)),"") -> COLLECTION_CALL | P11: =IFERROR(INDEX(tQueue[RecommendedAction],MATCH(2,Calc!$C$28:$C$299,0)),"") -> Collection call: oldest item is more than 30 days past due.
A12: =IF(3>MIN(QueueRowsShown,$F$4),"",3) -> 3 | B12: =IFERROR(INDEX(tQueue[CustomerName],MATCH(3,Calc!$C$28:$C$299,0)),"") -> Crestview Contracting - Northeast 3 | C12: =IFERROR(INDEX(tQueue[Segment],MATCH(3,Calc!$C$28:$C$299,0)),"") -> Contractor | D12: =IFERROR(INDEX(tQueue[RiskTier],MATCH(3,Calc!$C$28:$C$299,0)),"") -> High | E12: =IFERROR(INDEX(tQueue[CollectorName],MATCH(3,Calc!$C$28:$C$299,0)),"") -> Tomas Okafor | F12: =IFERROR(INDEX(tQueue[TermsCode],MATCH(3,Calc!$C$28:$C$299,0)),"") -> 2/10NET30 | G12: =IFERROR(INDEX(tQueue[OpenBalance],MATCH(3,Calc!$C$28:$C$299,0)),"") -> 60651.51 | H12: =IFERROR(INDEX(tQueue[PastDueBalance],MATCH(3,Calc!$C$28:$C$299,0)),"") -> 52023.36 | I12: =IFERROR(INDEX(tQueue[Balance90Plus],MATCH(3,Calc!$C$28:$C$299,0)),"") -> 19027.82 | J12: =IFERROR(INDEX(tQueue[DisputedBalance],MATCH(3,Calc!$C$28:$C$299,0)),"") -> 0 | K12: =IFERROR(INDEX(tQueue[CollectableExposure],MATCH(3,Calc!$C$28:$C$299,0)),"") -> 37672.1 | L12: =IFERROR(INDEX(tQueue[OldestDaysPastDue],MATCH(3,Calc!$C$28:$C$299,0)),"") -> 139 | M12: =IFERROR(INDEX(tQueue[CreditUtilizationPct],MATCH(3,Calc!$C$28:$C$299,0)),"") -> 48.52 | N12: =IFERROR(INDEX(tQueue[CreditHoldFlag],MATCH(3,Calc!$C$28:$C$299,0)),"") -> 0 | O12: =IFERROR(INDEX(tQueue[ActionCode],MATCH(3,Calc!$C$28:$C$299,0)),"") -> ESCALATE | P12: =IFERROR(INDEX(tQueue[RecommendedAction],MATCH(3,Calc!$C$28:$C$299,0)),"") -> Escalate: high-risk account carrying a 90+ balance. Hold further shipments and agree a payment plan or refer for recovery.
A13: =IF(4>MIN(QueueRowsShown,$F$4),"",4) -> 4 | B13: =IFERROR(INDEX(tQueue[CustomerName],MATCH(4,Calc!$C$28:$C$299,0)),"") -> Titan Builders - Southwest | C13: =IFERROR(INDEX(tQueue[Segment],MATCH(4,Calc!$C$28:$C$299,0)),"") -> Contractor | D13: =IFERROR(INDEX(tQueue[RiskTier],MATCH(4,Calc!$C$28:$C$299,0)),"") -> High | E13: =IFERROR(INDEX(tQueue[CollectorName],MATCH(4,Calc!$C$28:$C$299,0)),"") -> Tomas Okafor | F13: =IFERROR(INDEX(tQueue[TermsCode],MATCH(4,Calc!$C$28:$C$299,0)),"") -> 2/10NET30 | G13: =IFERROR(INDEX(tQueue[OpenBalance],MATCH(4,Calc!$C$28:$C$299,0)),"") -> 60280.9 | H13: =IFERROR(INDEX(tQueue[PastDueBalance],MATCH(4,Calc!$C$28:$C$299,0)),"") -> 48278 | I13: =IFERROR(INDEX(tQueue[Balance90Plus],MATCH(4,Calc!$C$28:$C$299,0)),"") -> 24426.9 | J13: =IFERROR(INDEX(tQueue[DisputedBalance],MATCH(4,Calc!$C$28:$C$299,0)),"") -> 0 | K13: =IFERROR(INDEX(tQueue[CollectableExposure],MATCH(4,Calc!$C$28:$C$299,0)),"") -> 35663.13 | L13: =IFERROR(INDEX(tQueue[OldestDaysPastDue],MATCH(4,Calc!$C$28:$C$299,0)),"") -> 147 | M13: =IFERROR(INDEX(tQueue[CreditUtilizationPct],MATCH(4,Calc!$C$28:$C$299,0)),"") -> 57.41 | N13: =IFERROR(INDEX(tQueue[CreditHoldFlag],MATCH(4,Calc!$C$28:$C$299,0)),"") -> 0 | O13: =IFERROR(INDEX(tQueue[ActionCode],MATCH(4,Calc!$C$28:$C$299,0)),"") -> ESCALATE | P13: =IFERROR(INDEX(tQueue[RecommendedAction],MATCH(4,Calc!$C$28:$C$299,0)),"") -> Escalate: high-risk account carrying a 90+ balance. Hold further shipments and agree a payment plan or refer for recovery.
A14: =IF(5>MIN(QueueRowsShown,$F$4),"",5) -> 5 | B14: =IFERROR(INDEX(tQueue[CustomerName],MATCH(5,Calc!$C$28:$C$299,0)),"") -> Bluewater Electric | C14: =IFERROR(INDEX(tQueue[Segment],MATCH(5,Calc!$C$28:$C$299,0)),"") -> Contractor | D14: =IFERROR(INDEX(tQueue[RiskTier],MATCH(5,Calc!$C$28:$C$299,0)),"") -> High | E14: =IFERROR(INDEX(tQueue[CollectorName],MATCH(5,Calc!$C$28:$C$299,0)),"") -> Elena Ruiz | F14: =IFERROR(INDEX(tQueue[TermsCode],MATCH(5,Calc!$C$28:$C$299,0)),"") -> NET60 | G14: =IFERROR(INDEX(tQueue[OpenBalance],MATCH(5,Calc!$C$28:$C$299,0)),"") -> 76941.41 | H14: =IFERROR(INDEX(tQueue[PastDueBalance],MATCH(5,Calc!$C$28:$C$299,0)),"") -> 46413.57 | I14: =IFERROR(INDEX(tQueue[Balance90Plus],MATCH(5,Calc!$C$28:$C$299,0)),"") -> 10287.08 | J14: =IFERROR(INDEX(tQueue[DisputedBalance],MATCH(5,Calc!$C$28:$C$299,0)),"") -> 0 | K14: =IFERROR(INDEX(tQueue[CollectableExposure],MATCH(5,Calc!$C$28:$C$299,0)),"") -> 32793.73 | L14: =IFERROR(INDEX(tQueue[OldestDaysPastDue],MATCH(5,Calc!$C$28:$C$299,0)),"") -> 120 | M14: =IFERROR(INDEX(tQueue[CreditUtilizationPct],MATCH(5,Calc!$C$28:$C$299,0)),"") -> 76.94 | N14: =IFERROR(INDEX(tQueue[CreditHoldFlag],MATCH(5,Calc!$C$28:$C$299,0)),"") -> 0 | O14: =IFERROR(INDEX(tQueue[ActionCode],MATCH(5,Calc!$C$28:$C$299,0)),"") -> ESCALATE | P14: =IFERROR(INDEX(tQueue[RecommendedAction],MATCH(5,Calc!$C$28:$C$299,0)),"") -> Escalate: high-risk account carrying a 90+ balance. Hold further shipments and agree a payment plan or refer for recovery.
A15: =IF(6>MIN(QueueRowsShown,$F$4),"",6) -> 6 | B15: =IFERROR(INDEX(tQueue[CustomerName],MATCH(6,Calc!$C$28:$C$299,0)),"") -> Pioneer Construction | C15: =IFERROR(INDEX(tQueue[Segment],MATCH(6,Calc!$C$28:$C$299,0)),"") -> Contractor | D15: =IFERROR(INDEX(tQueue[RiskTier],MATCH(6,Calc!$C$28:$C$299,0)),"") -> High | E15: =IFERROR(INDEX(tQueue[CollectorName],MATCH(6,Calc!$C$28:$C$299,0)),"") -> Elena Ruiz | F15: =IFERROR(INDEX(tQueue[TermsCode],MATCH(6,Calc!$C$28:$C$299,0)),"") -> 2/10NET30 | G15: =IFERROR(INDEX(tQueue[OpenBalance],MATCH(6,Calc!$C$28:$C$299,0)),"") -> 65460.37 | H15: =IFERROR(INDEX(tQueue[PastDueBalance],MATCH(6,Calc!$C$28:$C$299,0)),"") -> 51420.43 | I15: =IFERROR(INDEX(tQueue[Balance90Plus],MATCH(6,Calc!$C$28:$C$299,0)),"") -> 18333.73 | J15: =IFERROR(INDEX(tQueue[DisputedBalance],MATCH(6,Calc!$C$28:$C$299,0)),"") -> 7692.27 | K15: =IFERROR(INDEX(tQueue[CollectableExposure],MATCH(6,Calc!$C$28:$C$299,0)),"") -> 32505.02 | L15: =IFERROR(INDEX(tQueue[OldestDaysPastDue],MATCH(6,Calc!$C$28:$C$299,0)),"") -> 140 | M15: =IFERROR(INDEX(tQueue[CreditUtilizationPct],MATCH(6,Calc!$C$28:$C$299,0)),"") -> 45.15 | N15: =IFERROR(INDEX(tQueue[CreditHoldFlag],MATCH(6,Calc!$C$28:$C$299,0)),"") -> 0 | O15: =IFERROR(INDEX(tQueue[ActionCode],MATCH(6,Calc!$C$28:$C$299,0)),"") -> ESCALATE | P15: =IFERROR(INDEX(tQueue[RecommendedAction],MATCH(6,Calc!$C$28:$C$299,0)),"") -> Escalate: high-risk account carrying a 90+ balance. Hold further shipments and agree a payment plan or refer for recovery.
A16: =IF(7>MIN(QueueRowsShown,$F$4),"",7) -> 7 | B16: =IFERROR(INDEX(tQueue[CustomerName],MATCH(7,Calc!$C$28:$C$299,0)),"") -> Apex Mechanical | C16: =IFERROR(INDEX(tQueue[Segment],MATCH(7,Calc!$C$28:$C$299,0)),"") -> Contractor | D16: =IFERROR(INDEX(tQueue[RiskTier],MATCH(7,Calc!$C$28:$C$299,0)),"") -> High | E16: =IFERROR(INDEX(tQueue[CollectorName],MATCH(7,Calc!$C$28:$C$299,0)),"") -> Marcus Bell | F16: =IFERROR(INDEX(tQueue[TermsCode],MATCH(7,Calc!$C$28:$C$299,0)),"") -> NET30 | G16: =IFERROR(INDEX(tQueue[OpenBalance],MATCH(7,Calc!$C$28:$C$299,0)),"") -> 53593.68 | H16: =IFERROR(INDEX(tQueue[PastDueBalance],MATCH(7,Calc!$C$28:$C$299,0)),"") -> 45881.37 | I16: =IFERROR(INDEX(tQueue[Balance90Plus],MATCH(7,Calc!$C$28:$C$299,0)),"") -> 16968.16 | J16: =IFERROR(INDEX(tQueue[DisputedBalance],MATCH(7,Calc!$C$28:$C$299,0)),"") -> 0 | K16: =IFERROR(INDEX(tQueue[CollectableExposure],MATCH(7,Calc!$C$28:$C$299,0)),"") -> 31940.25 | L16: =IFERROR(INDEX(tQueue[OldestDaysPastDue],MATCH(7,Calc!$C$28:$C$299,0)),"") -> 143 | M16: =IFERROR(INDEX(tQueue[CreditUtilizationPct],MATCH(7,Calc!$C$28:$C$299,0)),"") -> 35.73 | N16: =IFERROR(INDEX(tQueue[CreditHoldFlag],MATCH(7,Calc!$C$28:$C$299,0)),"") -> 0 | O16: =IFERROR(INDEX(tQueue[ActionCode],MATCH(7,Calc!$C$28:$C$299,0)),"") -> ESCALATE | P16: =IFERROR(INDEX(tQueue[RecommendedAction],MATCH(7,Calc!$C$28:$C$299,0)),"") -> Escalate: high-risk account carrying a 90+ balance. Hold further shipments and agree a payment plan or refer for recovery.
A17: =IF(8>MIN(QueueRowsShown,$F$4),"",8) -> 8 | B17: =IFERROR(INDEX(tQueue[CustomerName],MATCH(8,Calc!$C$28:$C$299,0)),"") -> Stonegate Machine Works | C17: =IFERROR(INDEX(tQueue[Segment],MATCH(8,Calc!$C$28:$C$299,0)),"") -> OEM Manufacturer | D17: =IFERROR(INDEX(tQueue[RiskTier],MATCH(8,Calc!$C$28:$C$299,0)),"") -> Low | E17: =IFERROR(INDEX(tQueue[CollectorName],MATCH(8,Calc!$C$28:$C$299,0)),"") -> Marcus Bell | F17: =IFERROR(INDEX(tQueue[TermsCode],MATCH(8,Calc!$C$28:$C$299,0)),"") -> NET60 | G17: =IFERROR(INDEX(tQueue[OpenBalance],MATCH(8,Calc!$C$28:$C$299,0)),"") -> 150926.78 | H17: =IFERROR(INDEX(tQueue[PastDueBalance],MATCH(8,Calc!$C$28:$C$299,0)),"") -> 85720.95 | I17: =IFERROR(INDEX(tQueue[Balance90Plus],MATCH(8,Calc!$C$28:$C$299,0)),"") -> 1675.15 | J17: =IFERROR(INDEX(tQueue[DisputedBalance],MATCH(8,Calc!$C$28:$C$299,0)),"") -> 0 | K17: =IFERROR(INDEX(tQueue[CollectableExposure],MATCH(8,Calc!$C$28:$C$299,0)),"") -> 31517.91 | L17: =IFERROR(INDEX(tQueue[OldestDaysPastDue],MATCH(8,Calc!$C$28:$C$299,0)),"") -> 274 | M17: =IFERROR(INDEX(tQueue[CreditUtilizationPct],MATCH(8,Calc!$C$28:$C$299,0)),"") -> 29.31 | N17: =IFERROR(INDEX(tQueue[CreditHoldFlag],MATCH(8,Calc!$C$28:$C$299,0)),"") -> 0 | O17: =IFERROR(INDEX(tQueue[ActionCode],MATCH(8,Calc!$C$28:$C$299,0)),"") -> FINAL_NOTICE | P17: =IFERROR(INDEX(tQueue[RecommendedAction],MATCH(8,Calc!$C$28:$C$299,0)),"") -> Issue a final notice on the 90+ balance and confirm a payment date in writing.
A18: =IF(9>MIN(QueueRowsShown,$F$4),"",9) -> 9 | B18: =IFERROR(INDEX(tQueue[CustomerName],MATCH(9,Calc!$C$28:$C$299,0)),"") -> Riverbend Electric - Midwest 3 | C18: =IFERROR(INDEX(tQueue[Segment],MATCH(9,Calc!$C$28:$C$299,0)),"") -> Contractor | D18: =IFERROR(INDEX(tQueue[RiskTier],MATCH(9,Calc!$C$28:$C$299,0)),"") -> High | E18: =IFERROR(INDEX(tQueue[CollectorName],MATCH(9,Calc!$C$28:$C$299,0)),"") -> Elena Ruiz | F18: =IFERROR(INDEX(tQueue[TermsCode],MATCH(9,Calc!$C$28:$C$299,0)),"") -> 2/10NET30 | G18: =IFERROR(INDEX(tQueue[OpenBalance],MATCH(9,Calc!$C$28:$C$299,0)),"") -> 59342.1 | H18: =IFERROR(INDEX(tQueue[PastDueBalance],MATCH(9,Calc!$C$28:$C$299,0)),"") -> 46818.72 | I18: =IFERROR(INDEX(tQueue[Balance90Plus],MATCH(9,Calc!$C$28:$C$299,0)),"") -> 14609.63 | J18: =IFERROR(INDEX(tQueue[DisputedBalance],MATCH(9,Calc!$C$28:$C$299,0)),"") -> 0 | K18: =IFERROR(INDEX(tQueue[CollectableExposure],MATCH(9,Calc!$C$28:$C$299,0)),"") -> 27084.27 | L18: =IFERROR(INDEX(tQueue[OldestDaysPastDue],MATCH(9,Calc!$C$28:$C$299,0)),"") -> 140 | M18: =IFERROR(INDEX(tQueue[CreditUtilizationPct],MATCH(9,Calc!$C$28:$C$299,0)),"") -> 42.39 | N18: =IFERROR(INDEX(tQueue[CreditHoldFlag],MATCH(9,Calc!$C$28:$C$299,0)),"") -> 0 | O18: =IFERROR(INDEX(tQueue[ActionCode],MATCH(9,Calc!$C$28:$C$299,0)),"") -> ESCALATE | P18: =IFERROR(INDEX(tQueue[RecommendedAction],MATCH(9,Calc!$C$28:$C$299,0)),"") -> Escalate: high-risk account carrying a 90+ balance. Hold further shipments and agree a payment plan or refer for recovery.
A19: =IF(10>MIN(QueueRowsShown,$F$4),"",10) -> 10 | B19: =IFERROR(INDEX(tQueue[CustomerName],MATCH(10,Calc!$C$28:$C$299,0)),"") -> Apex Mechanical - Southeast 3 | C19: =IFERROR(INDEX(tQueue[Segment],MATCH(10,Calc!$C$28:$C$299,0)),"") -> Contractor | D19: =IFERROR(INDEX(tQueue[RiskTier],MATCH(10,Calc!$C$28:$C$299,0)),"") -> High | E19: =IFERROR(INDEX(tQueue[CollectorName],MATCH(10,Calc!$C$28:$C$299,0)),"") -> Tomas Okafor | F19: =IFERROR(INDEX(tQueue[TermsCode],MATCH(10,Calc!$C$28:$C$299,0)),"") -> NET30 | G19: =IFERROR(INDEX(tQueue[OpenBalance],MATCH(10,Calc!$C$28:$C$299,0)),"") -> 31830.69 | H19: =IFERROR(INDEX(tQueue[PastDueBalance],MATCH(10,Calc!$C$28:$C$299,0)),"") -> 28601.28 | I19: =IFERROR(INDEX(tQueue[Balance90Plus],MATCH(10,Calc!$C$28:$C$299,0)),"") -> 26001.78 | J19: =IFERROR(INDEX(tQueue[DisputedBalance],MATCH(10,Calc!$C$28:$C$299,0)),"") -> 0 | K19: =IFERROR(INDEX(tQueue[CollectableExposure],MATCH(10,Calc!$C$28:$C$299,0)),"") -> 27073.54 | L19: =IFERROR(INDEX(tQueue[OldestDaysPastDue],MATCH(10,Calc!$C$28:$C$299,0)),"") -> 138 | M19: =IFERROR(INDEX(tQueue[CreditUtilizationPct],MATCH(10,Calc!$C$28:$C$299,0)),"") -> 106.1 | N19: =IFERROR(INDEX(tQueue[CreditHoldFlag],MATCH(10,Calc!$C$28:$C$299,0)),"") -> 1 | O19: =IFERROR(INDEX(tQueue[ActionCode],MATCH(10,Calc!$C$28:$C$299,0)),"") -> ESCALATE | P19: =IFERROR(INDEX(tQueue[RecommendedAction],MATCH(10,Calc!$C$28:$C$299,0)),"") -> Escalate: high-risk account carrying a 90+ balance. Hold further shipments and agree a payment plan or refer for recovery. Also place a credit hold: the account is at or over its credit limit.
A20: =IF(11>MIN(QueueRowsShown,$F$4),"",11) -> 11 | B20: =IFERROR(INDEX(tQueue[CustomerName],MATCH(11,Calc!$C$28:$C$299,0)),"") -> Keystone Contracting | C20: =IFERROR(INDEX(tQueue[Segment],MATCH(11,Calc!$C$28:$C$299,0)),"") -> Contractor | D20: =IFERROR(INDEX(tQueue[RiskTier],MATCH(11,Calc!$C$28:$C$299,0)),"") -> High | E20: =IFERROR(INDEX(tQueue[CollectorName],MATCH(11,Calc!$C$28:$C$299,0)),"") -> Tomas Okafor | F20: =IFERROR(INDEX(tQueue[TermsCode],MATCH(11,Calc!$C$28:$C$299,0)),"") -> NET60 | G20: =IFERROR(INDEX(tQueue[OpenBalance],MATCH(11,Calc!$C$28:$C$299,0)),"") -> 84970.22 | H20: =IFERROR(INDEX(tQueue[PastDueBalance],MATCH(11,Calc!$C$28:$C$299,0)),"") -> 41199.26 | I20: =IFERROR(INDEX(tQueue[Balance90Plus],MATCH(11,Calc!$C$28:$C$299,0)),"") -> 9337.53 | J20: =IFERROR(INDEX(tQueue[DisputedBalance],MATCH(11,Calc!$C$28:$C$299,0)),"") -> 0 | K20: =IFERROR(INDEX(tQueue[CollectableExposure],MATCH(11,Calc!$C$28:$C$299,0)),"") -> 25099.35 | L20: =IFERROR(INDEX(tQueue[OldestDaysPastDue],MATCH(11,Calc!$C$28:$C$299,0)),"") -> 122 | M20: =IFERROR(INDEX(tQueue[CreditUtilizationPct],MATCH(11,Calc!$C$28:$C$299,0)),"") -> 80.92 | N20: =IFERROR(INDEX(tQueue[CreditHoldFlag],MATCH(11,Calc!$C$28:$C$299,0)),"") -> 0 | O20: =IFERROR(INDEX(tQueue[ActionCode],MATCH(11,Calc!$C$28:$C$299,0)),"") -> ESCALATE | P20: =IFERROR(INDEX(tQueue[RecommendedAction],MATCH(11,Calc!$C$28:$C$299,0)),"") -> Escalate: high-risk account carrying a 90+ balance. Hold further shipments and agree a payment plan or refer for recovery.
A21: =IF(12>MIN(QueueRowsShown,$F$4),"",12) -> 12 | B21: =IFERROR(INDEX(tQueue[CustomerName],MATCH(12,Calc!$C$28:$C$299,0)),"") -> Bluewater Industries - Southeast | C21: =IFERROR(INDEX(tQueue[Segment],MATCH(12,Calc!$C$28:$C$299,0)),"") -> OEM Manufacturer | D21: =IFERROR(INDEX(tQueue[RiskTier],MATCH(12,Calc!$C$28:$C$299,0)),"") -> Low | E21: =IFERROR(INDEX(tQueue[CollectorName],MATCH(12,Calc!$C$28:$C$299,0)),"") -> Marcus Bell | F21: =IFERROR(INDEX(tQueue[TermsCode],MATCH(12,Calc!$C$28:$C$299,0)),"") -> NET45 | G21: =IFERROR(INDEX(tQueue[OpenBalance],MATCH(12,Calc!$C$28:$C$299,0)),"") -> 125485.34 | H21: =IFERROR(INDEX(tQueue[PastDueBalance],MATCH(12,Calc!$C$28:$C$299,0)),"") -> 87648.64 | I21: =IFERROR(INDEX(tQueue[Balance90Plus],MATCH(12,Calc!$C$28:$C$299,0)),"") -> 0 | J21: =IFERROR(INDEX(tQueue[DisputedBalance],MATCH(12,Calc!$C$28:$C$299,0)),"") -> 17811.56 | K21: =IFERROR(INDEX(tQueue[CollectableExposure],MATCH(12,Calc!$C$28:$C$299,0)),"") -> 24700.44 | L21: =IFERROR(INDEX(tQueue[OldestDaysPastDue],MATCH(12,Calc!$C$28:$C$299,0)),"") -> 69 | M21: =IFERROR(INDEX(tQueue[CreditUtilizationPct],MATCH(12,Calc!$C$28:$C$299,0)),"") -> 23.46 | N21: =IFERROR(INDEX(tQueue[CreditHoldFlag],MATCH(12,Calc!$C$28:$C$299,0)),"") -> 0 | O21: =IFERROR(INDEX(tQueue[ActionCode],MATCH(12,Calc!$C$28:$C$299,0)),"") -> COLLECTION_CALL | P21: =IFERROR(INDEX(tQueue[RecommendedAction],MATCH(12,Calc!$C$28:$C$299,0)),"") -> Collection call: oldest item is more than 30 days past due.
A22: =IF(13>MIN(QueueRowsShown,$F$4),"",13) -> 13 | B22: =IFERROR(INDEX(tQueue[CustomerName],MATCH(13,Calc!$C$28:$C$299,0)),"") -> Redline Industries - Northeast | C22: =IFERROR(INDEX(tQueue[Segment],MATCH(13,Calc!$C$28:$C$299,0)),"") -> OEM Manufacturer | D22: =IFERROR(INDEX(tQueue[RiskTier],MATCH(13,Calc!$C$28:$C$299,0)),"") -> Low | E22: =IFERROR(INDEX(tQueue[CollectorName],MATCH(13,Calc!$C$28:$C$299,0)),"") -> Marcus Bell | F22: =IFERROR(INDEX(tQueue[TermsCode],MATCH(13,Calc!$C$28:$C$299,0)),"") -> NET45 | G22: =IFERROR(INDEX(tQueue[OpenBalance],MATCH(13,Calc!$C$28:$C$299,0)),"") -> 152726.53 | H22: =IFERROR(INDEX(tQueue[PastDueBalance],MATCH(13,Calc!$C$28:$C$299,0)),"") -> 58576.86 | I22: =IFERROR(INDEX(tQueue[Balance90Plus],MATCH(13,Calc!$C$28:$C$299,0)),"") -> 0 | J22: =IFERROR(INDEX(tQueue[DisputedBalance],MATCH(13,Calc!$C$28:$C$299,0)),"") -> 0 | K22: =IFERROR(INDEX(tQueue[CollectableExposure],MATCH(13,Calc!$C$28:$C$299,0)),"") -> 21504.84 | L22: =IFERROR(INDEX(tQueue[OldestDaysPastDue],MATCH(13,Calc!$C$28:$C$299,0)),"") -> 44 | M22: =IFERROR(INDEX(tQueue[CreditUtilizationPct],MATCH(13,Calc!$C$28:$C$299,0)),"") -> 45.59 | N22: =IFERROR(INDEX(tQueue[CreditHoldFlag],MATCH(13,Calc!$C$28:$C$299,0)),"") -> 0 | O22: =IFERROR(INDEX(tQueue[ActionCode],MATCH(13,Calc!$C$28:$C$299,0)),"") -> COLLECTION_CALL | P22: =IFERROR(INDEX(tQueue[RecommendedAction],MATCH(13,Calc!$C$28:$C$299,0)),"") -> Collection call: oldest item is more than 30 days past due.
A23: =IF(14>MIN(QueueRowsShown,$F$4),"",14) -> 14 | B23: =IFERROR(INDEX(tQueue[CustomerName],MATCH(14,Calc!$C$28:$C$299,0)),"") -> Lakeshore Fabrication | C23: =IFERROR(INDEX(tQueue[Segment],MATCH(14,Calc!$C$28:$C$299,0)),"") -> OEM Manufacturer | D23: =IFERROR(INDEX(tQueue[RiskTier],MATCH(14,Calc!$C$28:$C$299,0)),"") -> Medium | E23: =IFERROR(INDEX(tQueue[CollectorName],MATCH(14,Calc!$C$28:$C$299,0)),"") -> Priya Natarajan | F23: =IFERROR(INDEX(tQueue[TermsCode],MATCH(14,Calc!$C$28:$C$299,0)),"") -> NET45 | G23: =IFERROR(INDEX(tQueue[OpenBalance],MATCH(14,Calc!$C$28:$C$299,0)),"") -> 127031.86 | H23: =IFERROR(INDEX(tQueue[PastDueBalance],MATCH(14,Calc!$C$28:$C$299,0)),"") -> 51164.87 | I23: =IFERROR(INDEX(tQueue[Balance90Plus],MATCH(14,Calc!$C$28:$C$299,0)),"") -> 0 | J23: =IFERROR(INDEX(tQueue[DisputedBalance],MATCH(14,Calc!$C$28:$C$299,0)),"") -> 15908.3 | K23: =IFERROR(INDEX(tQueue[CollectableExposure],MATCH(14,Calc!$C$28:$C$299,0)),"") -> 20707.5 | L23: =IFERROR(INDEX(tQueue[OldestDaysPastDue],MATCH(14,Calc!$C$28:$C$299,0)),"") -> 47 | M23: =IFERROR(INDEX(tQueue[CreditUtilizationPct],MATCH(14,Calc!$C$28:$C$299,0)),"") -> 52.93 | N23: =IFERROR(INDEX(tQueue[CreditHoldFlag],MATCH(14,Calc!$C$28:$C$299,0)),"") -> 0 | O23: =IFERROR(INDEX(tQueue[ActionCode],MATCH(14,Calc!$C$28:$C$299,0)),"") -> COLLECTION_CALL | P23: =IFERROR(INDEX(tQueue[RecommendedAction],MATCH(14,Calc!$C$28:$C$299,0)),"") -> Collection call: oldest item is more than 30 days past due.
A24: =IF(15>MIN(QueueRowsShown,$F$4),"",15) -> 15 | B24: =IFERROR(INDEX(tQueue[CustomerName],MATCH(15,Calc!$C$28:$C$299,0)),"") -> Riverbend Fabrication | C24: =IFERROR(INDEX(tQueue[Segment],MATCH(15,Calc!$C$28:$C$299,0)),"") -> OEM Manufacturer | D24: =IFERROR(INDEX(tQueue[RiskTier],MATCH(15,Calc!$C$28:$C$299,0)),"") -> Low | E24: =IFERROR(INDEX(tQueue[CollectorName],MATCH(15,Calc!$C$28:$C$299,0)),"") -> Marcus Bell | F24: =IFERROR(INDEX(tQueue[TermsCode],MATCH(15,Calc!$C$28:$C$299,0)),"") -> NET60 | G24: =IFERROR(INDEX(tQueue[OpenBalance],MATCH(15,Calc!$C$28:$C$299,0)),"") -> 90154.01 | H24: =IFERROR(INDEX(tQueue[PastDueBalance],MATCH(15,Calc!$C$28:$C$299,0)),"") -> 52664.06 | I24: =IFERROR(INDEX(tQueue[Balance90Plus],MATCH(15,Calc!$C$28:$C$299,0)),"") -> 0 | J24: =IFERROR(INDEX(tQueue[DisputedBalance],MATCH(15,Calc!$C$28:$C$299,0)),"") -> 9987.4 | K24: =IFERROR(INDEX(tQueue[CollectableExposure],MATCH(15,Calc!$C$28:$C$299,0)),"") -> 13961.98 | L24: =IFERROR(INDEX(tQueue[OldestDaysPastDue],MATCH(15,Calc!$C$28:$C$299,0)),"") -> 47 | M24: =IFERROR(INDEX(tQueue[CreditUtilizationPct],MATCH(15,Calc!$C$28:$C$299,0)),"") -> 36.8 | N24: =IFERROR(INDEX(tQueue[CreditHoldFlag],MATCH(15,Calc!$C$28:$C$299,0)),"") -> 0 | O24: =IFERROR(INDEX(tQueue[ActionCode],MATCH(15,Calc!$C$28:$C$299,0)),"") -> COLLECTION_CALL | P24: =IFERROR(INDEX(tQueue[RecommendedAction],MATCH(15,Calc!$C$28:$C$299,0)),"") -> Collection call: oldest item is more than 30 days past due.
A25: =IF(16>MIN(QueueRowsShown,$F$4),"",16) -> 16 | B25: =IFERROR(INDEX(tQueue[CustomerName],MATCH(16,Calc!$C$28:$C$299,0)),"") -> Cedar Ridge Machine Works - Southwest | C25: =IFERROR(INDEX(tQueue[Segment],MATCH(16,Calc!$C$28:$C$299,0)),"") -> OEM Manufacturer | D25: =IFERROR(INDEX(tQueue[RiskTier],MATCH(16,Calc!$C$28:$C$299,0)),"") -> High | E25: =IFERROR(INDEX(tQueue[CollectorName],MATCH(16,Calc!$C$28:$C$299,0)),"") -> Priya Natarajan | F25: =IFERROR(INDEX(tQueue[TermsCode],MATCH(16,Calc!$C$28:$C$299,0)),"") -> NET60 | G25: =IFERROR(INDEX(tQueue[OpenBalance],MATCH(16,Calc!$C$28:$C$299,0)),"") -> 159690.8 | H25: =IFERROR(INDEX(tQueue[PastDueBalance],MATCH(16,Calc!$C$28:$C$299,0)),"") -> 50936.25 | I25: =IFERROR(INDEX(tQueue[Balance90Plus],MATCH(16,Calc!$C$28:$C$299,0)),"") -> 0 | J25: =IFERROR(INDEX(tQueue[DisputedBalance],MATCH(16,Calc!$C$28:$C$299,0)),"") -> 0 | K25: =IFERROR(INDEX(tQueue[CollectableExposure],MATCH(16,Calc!$C$28:$C$299,0)),"") -> 12734.06 | L25: =IFERROR(INDEX(tQueue[OldestDaysPastDue],MATCH(16,Calc!$C$28:$C$299,0)),"") -> 18 | M25: =IFERROR(INDEX(tQueue[CreditUtilizationPct],MATCH(16,Calc!$C$28:$C$299,0)),"") -> 29.85 | N25: =IFERROR(INDEX(tQueue[CreditHoldFlag],MATCH(16,Calc!$C$28:$C$299,0)),"") -> 0 | O25: =IFERROR(INDEX(tQueue[ActionCode],MATCH(16,Calc!$C$28:$C$299,0)),"") -> STANDARD_DUNNING | P25: =IFERROR(INDEX(tQueue[RecommendedAction],MATCH(16,Calc!$C$28:$C$299,0)),"") -> Standard dunning letter and follow-up call.
A26: =IF(17>MIN(QueueRowsShown,$F$4),"",17) -> 17 | B26: =IFERROR(INDEX(tQueue[CustomerName],MATCH(17,Calc!$C$28:$C$299,0)),"") -> Lakeshore Construction - West | C26: =IFERROR(INDEX(tQueue[Segment],MATCH(17,Calc!$C$28:$C$299,0)),"") -> Contractor | D26: =IFERROR(INDEX(tQueue[RiskTier],MATCH(17,Calc!$C$28:$C$299,0)),"") -> High | E26: =IFERROR(INDEX(tQueue[CollectorName],MATCH(17,Calc!$C$28:$C$299,0)),"") -> Tomas Okafor | F26: =IFERROR(INDEX(tQueue[TermsCode],MATCH(17,Calc!$C$28:$C$299,0)),"") -> 2/10NET30 | G26: =IFERROR(INDEX(tQueue[OpenBalance],MATCH(17,Calc!$C$28:$C$299,0)),"") -> 24570.62 | H26: =IFERROR(INDEX(tQueue[PastDueBalance],MATCH(17,Calc!$C$28:$C$299,0)),"") -> 16849.82 | I26: =IFERROR(INDEX(tQueue[Balance90Plus],MATCH(17,Calc!$C$28:$C$299,0)),"") -> 8126.02 | J26: =IFERROR(INDEX(tQueue[DisputedBalance],MATCH(17,Calc!$C$28:$C$299,0)),"") -> 0 | K26: =IFERROR(INDEX(tQueue[CollectableExposure],MATCH(17,Calc!$C$28:$C$299,0)),"") -> 12487.92 | L26: =IFERROR(INDEX(tQueue[OldestDaysPastDue],MATCH(17,Calc!$C$28:$C$299,0)),"") -> 111 | M26: =IFERROR(INDEX(tQueue[CreditUtilizationPct],MATCH(17,Calc!$C$28:$C$299,0)),"") -> 98.28 | N26: =IFERROR(INDEX(tQueue[CreditHoldFlag],MATCH(17,Calc!$C$28:$C$299,0)),"") -> 0 | O26: =IFERROR(INDEX(tQueue[ActionCode],MATCH(17,Calc!$C$28:$C$299,0)),"") -> ESCALATE | P26: =IFERROR(INDEX(tQueue[RecommendedAction],MATCH(17,Calc!$C$28:$C$299,0)),"") -> Escalate: high-risk account carrying a 90+ balance. Hold further shipments and agree a payment plan or refer for recovery.
A27: =IF(18>MIN(QueueRowsShown,$F$4),"",18) -> 18 | B27: =IFERROR(INDEX(tQueue[CustomerName],MATCH(18,Calc!$C$28:$C$299,0)),"") -> Bluewater Industries | C27: =IFERROR(INDEX(tQueue[Segment],MATCH(18,Calc!$C$28:$C$299,0)),"") -> OEM Manufacturer | D27: =IFERROR(INDEX(tQueue[RiskTier],MATCH(18,Calc!$C$28:$C$299,0)),"") -> High | E27: =IFERROR(INDEX(tQueue[CollectorName],MATCH(18,Calc!$C$28:$C$299,0)),"") -> Priya Natarajan | F27: =IFERROR(INDEX(tQueue[TermsCode],MATCH(18,Calc!$C$28:$C$299,0)),"") -> NET60 | G27: =IFERROR(INDEX(tQueue[OpenBalance],MATCH(18,Calc!$C$28:$C$299,0)),"") -> 93887.29 | H27: =IFERROR(INDEX(tQueue[PastDueBalance],MATCH(18,Calc!$C$28:$C$299,0)),"") -> 53541.39 | I27: =IFERROR(INDEX(tQueue[Balance90Plus],MATCH(18,Calc!$C$28:$C$299,0)),"") -> 3658.04 | J27: =IFERROR(INDEX(tQueue[DisputedBalance],MATCH(18,Calc!$C$28:$C$299,0)),"") -> 0 | K27: =IFERROR(INDEX(tQueue[CollectableExposure],MATCH(18,Calc!$C$28:$C$299,0)),"") -> 12470.84 | L27: =IFERROR(INDEX(tQueue[OldestDaysPastDue],MATCH(18,Calc!$C$28:$C$299,0)),"") -> 502 | M27: =IFERROR(INDEX(tQueue[CreditUtilizationPct],MATCH(18,Calc!$C$28:$C$299,0)),"") -> 26.45 | N27: =IFERROR(INDEX(tQueue[CreditHoldFlag],MATCH(18,Calc!$C$28:$C$299,0)),"") -> 0 | O27: =IFERROR(INDEX(tQueue[ActionCode],MATCH(18,Calc!$C$28:$C$299,0)),"") -> ESCALATE | P27: =IFERROR(INDEX(tQueue[RecommendedAction],MATCH(18,Calc!$C$28:$C$299,0)),"") -> Escalate: high-risk account carrying a 90+ balance. Hold further shipments and agree a payment plan or refer for recovery.
A28: =IF(19>MIN(QueueRowsShown,$F$4),"",19) -> 19 | B28: =IFERROR(INDEX(tQueue[CustomerName],MATCH(19,Calc!$C$28:$C$299,0)),"") -> Frontier Fabrication | C28: =IFERROR(INDEX(tQueue[Segment],MATCH(19,Calc!$C$28:$C$299,0)),"") -> OEM Manufacturer | D28: =IFERROR(INDEX(tQueue[RiskTier],MATCH(19,Calc!$C$28:$C$299,0)),"") -> Medium | E28: =IFERROR(INDEX(tQueue[CollectorName],MATCH(19,Calc!$C$28:$C$299,0)),"") -> Priya Natarajan | F28: =IFERROR(INDEX(tQueue[TermsCode],MATCH(19,Calc!$C$28:$C$299,0)),"") -> NET45 | G28: =IFERROR(INDEX(tQueue[OpenBalance],MATCH(19,Calc!$C$28:$C$299,0)),"") -> 116620.23 | H28: =IFERROR(INDEX(tQueue[PastDueBalance],MATCH(19,Calc!$C$28:$C$299,0)),"") -> 44023.4 | I28: =IFERROR(INDEX(tQueue[Balance90Plus],MATCH(19,Calc!$C$28:$C$299,0)),"") -> 0 | J28: =IFERROR(INDEX(tQueue[DisputedBalance],MATCH(19,Calc!$C$28:$C$299,0)),"") -> 11224.6 | K28: =IFERROR(INDEX(tQueue[CollectableExposure],MATCH(19,Calc!$C$28:$C$299,0)),"") -> 11005.85 | L28: =IFERROR(INDEX(tQueue[OldestDaysPastDue],MATCH(19,Calc!$C$28:$C$299,0)),"") -> 4 | M28: =IFERROR(INDEX(tQueue[CreditUtilizationPct],MATCH(19,Calc!$C$28:$C$299,0)),"") -> 19.44 | N28: =IFERROR(INDEX(tQueue[CreditHoldFlag],MATCH(19,Calc!$C$28:$C$299,0)),"") -> 0 | O28: =IFERROR(INDEX(tQueue[ActionCode],MATCH(19,Calc!$C$28:$C$299,0)),"") -> STANDARD_DUNNING | P28: =IFERROR(INDEX(tQueue[RecommendedAction],MATCH(19,Calc!$C$28:$C$299,0)),"") -> Standard dunning letter and follow-up call.
A29: =IF(20>MIN(QueueRowsShown,$F$4),"",20) -> 20 | B29: =IFERROR(INDEX(tQueue[CustomerName],MATCH(20,Calc!$C$28:$C$299,0)),"") -> Stonegate Fabrication - West | C29: =IFERROR(INDEX(tQueue[Segment],MATCH(20,Calc!$C$28:$C$299,0)),"") -> OEM Manufacturer | D29: =IFERROR(INDEX(tQueue[RiskTier],MATCH(20,Calc!$C$28:$C$299,0)),"") -> High | E29: =IFERROR(INDEX(tQueue[CollectorName],MATCH(20,Calc!$C$28:$C$299,0)),"") -> Marcus Bell | F29: =IFERROR(INDEX(tQueue[TermsCode],MATCH(20,Calc!$C$28:$C$299,0)),"") -> NET60 | G29: =IFERROR(INDEX(tQueue[OpenBalance],MATCH(20,Calc!$C$28:$C$299,0)),"") -> 75601.21 | H29: =IFERROR(INDEX(tQueue[PastDueBalance],MATCH(20,Calc!$C$28:$C$299,0)),"") -> 47161.13 | I29: =IFERROR(INDEX(tQueue[Balance90Plus],MATCH(20,Calc!$C$28:$C$299,0)),"") -> 3522.98 | J29: =IFERROR(INDEX(tQueue[DisputedBalance],MATCH(20,Calc!$C$28:$C$299,0)),"") -> 0 | K29: =IFERROR(INDEX(tQueue[CollectableExposure],MATCH(20,Calc!$C$28:$C$299,0)),"") -> 10909.54 | L29: =IFERROR(INDEX(tQueue[OldestDaysPastDue],MATCH(20,Calc!$C$28:$C$299,0)),"") -> 277 | M29: =IFERROR(INDEX(tQueue[CreditUtilizationPct],MATCH(20,Calc!$C$28:$C$299,0)),"") -> 19.9 | N29: =IFERROR(INDEX(tQueue[CreditHoldFlag],MATCH(20,Calc!$C$28:$C$299,0)),"") -> 0 | O29: =IFERROR(INDEX(tQueue[ActionCode],MATCH(20,Calc!$C$28:$C$299,0)),"") -> ESCALATE | P29: =IFERROR(INDEX(tQueue[RecommendedAction],MATCH(20,Calc!$C$28:$C$299,0)),"") -> Escalate: high-risk account carrying a 90+ balance. Hold further shipments and agree a payment plan or refer for recovery.
A30: =IF(21>MIN(QueueRowsShown,$F$4),"",21) -> 21 | B30: =IFERROR(INDEX(tQueue[CustomerName],MATCH(21,Calc!$C$28:$C$299,0)),"") -> Northfield School District - Midwest | C30: =IFERROR(INDEX(tQueue[Segment],MATCH(21,Calc!$C$28:$C$299,0)),"") -> Institutional | D30: =IFERROR(INDEX(tQueue[RiskTier],MATCH(21,Calc!$C$28:$C$299,0)),"") -> Low | E30: =IFERROR(INDEX(tQueue[CollectorName],MATCH(21,Calc!$C$28:$C$299,0)),"") -> Priya Natarajan | F30: =IFERROR(INDEX(tQueue[TermsCode],MATCH(21,Calc!$C$28:$C$299,0)),"") -> NET90 | G30: =IFERROR(INDEX(tQueue[OpenBalance],MATCH(21,Calc!$C$28:$C$299,0)),"") -> 65440.55 | H30: =IFERROR(INDEX(tQueue[PastDueBalance],MATCH(21,Calc!$C$28:$C$299,0)),"") -> 31983.14 | I30: =IFERROR(INDEX(tQueue[Balance90Plus],MATCH(21,Calc!$C$28:$C$299,0)),"") -> 0 | J30: =IFERROR(INDEX(tQueue[DisputedBalance],MATCH(21,Calc!$C$28:$C$299,0)),"") -> 0 | K30: =IFERROR(INDEX(tQueue[CollectableExposure],MATCH(21,Calc!$C$28:$C$299,0)),"") -> 7995.79 | L30: =IFERROR(INDEX(tQueue[OldestDaysPastDue],MATCH(21,Calc!$C$28:$C$299,0)),"") -> 24 | M30: =IFERROR(INDEX(tQueue[CreditUtilizationPct],MATCH(21,Calc!$C$28:$C$299,0)),"") -> 28.45 | N30: =IFERROR(INDEX(tQueue[CreditHoldFlag],MATCH(21,Calc!$C$28:$C$299,0)),"") -> 0 | O30: =IFERROR(INDEX(tQueue[ActionCode],MATCH(21,Calc!$C$28:$C$299,0)),"") -> STANDARD_DUNNING | P30: =IFERROR(INDEX(tQueue[RecommendedAction],MATCH(21,Calc!$C$28:$C$299,0)),"") -> Standard dunning letter and follow-up call.
A31: =IF(22>MIN(QueueRowsShown,$F$4),"",22) -> 22 | B31: =IFERROR(INDEX(tQueue[CustomerName],MATCH(22,Calc!$C$28:$C$299,0)),"") -> Keystone Fabrication | C31: =IFERROR(INDEX(tQueue[Segment],MATCH(22,Calc!$C$28:$C$299,0)),"") -> OEM Manufacturer | D31: =IFERROR(INDEX(tQueue[RiskTier],MATCH(22,Calc!$C$28:$C$299,0)),"") -> Medium | E31: =IFERROR(INDEX(tQueue[CollectorName],MATCH(22,Calc!$C$28:$C$299,0)),"") -> Priya Natarajan | F31: =IFERROR(INDEX(tQueue[TermsCode],MATCH(22,Calc!$C$28:$C$299,0)),"") -> NET60 | G31: =IFERROR(INDEX(tQueue[OpenBalance],MATCH(22,Calc!$C$28:$C$299,0)),"") -> 93975.84 | H31: =IFERROR(INDEX(tQueue[PastDueBalance],MATCH(22,Calc!$C$28:$C$299,0)),"") -> 36293.49 | I31: =IFERROR(INDEX(tQueue[Balance90Plus],MATCH(22,Calc!$C$28:$C$299,0)),"") -> 6170.49 | J31: =IFERROR(INDEX(tQueue[DisputedBalance],MATCH(22,Calc!$C$28:$C$299,0)),"") -> 9126.86 | K31: =IFERROR(INDEX(tQueue[CollectableExposure],MATCH(22,Calc!$C$28:$C$299,0)),"") -> 7530.75 | L31: =IFERROR(INDEX(tQueue[OldestDaysPastDue],MATCH(22,Calc!$C$28:$C$299,0)),"") -> 102 | M31: =IFERROR(INDEX(tQueue[CreditUtilizationPct],MATCH(22,Calc!$C$28:$C$299,0)),"") -> 15.66 | N31: =IFERROR(INDEX(tQueue[CreditHoldFlag],MATCH(22,Calc!$C$28:$C$299,0)),"") -> 0 | O31: =IFERROR(INDEX(tQueue[ActionCode],MATCH(22,Calc!$C$28:$C$299,0)),"") -> FINAL_NOTICE | P31: =IFERROR(INDEX(tQueue[RecommendedAction],MATCH(22,Calc!$C$28:$C$299,0)),"") -> Issue a final notice on the 90+ balance and confirm a payment date in writing.
A32: =IF(23>MIN(QueueRowsShown,$F$4),"",23) -> 23 | B32: =IFERROR(INDEX(tQueue[CustomerName],MATCH(23,Calc!$C$28:$C$299,0)),"") -> Stonegate Industries | C32: =IFERROR(INDEX(tQueue[Segment],MATCH(23,Calc!$C$28:$C$299,0)),"") -> OEM Manufacturer | D32: =IFERROR(INDEX(tQueue[RiskTier],MATCH(23,Calc!$C$28:$C$299,0)),"") -> Medium | E32: =IFERROR(INDEX(tQueue[CollectorName],MATCH(23,Calc!$C$28:$C$299,0)),"") -> Priya Natarajan | F32: =IFERROR(INDEX(tQueue[TermsCode],MATCH(23,Calc!$C$28:$C$299,0)),"") -> NET45 | G32: =IFERROR(INDEX(tQueue[OpenBalance],MATCH(23,Calc!$C$28:$C$299,0)),"") -> 78932.51 | H32: =IFERROR(INDEX(tQueue[PastDueBalance],MATCH(23,Calc!$C$28:$C$299,0)),"") -> 29973.52 | I32: =IFERROR(INDEX(tQueue[Balance90Plus],MATCH(23,Calc!$C$28:$C$299,0)),"") -> 1838.06 | J32: =IFERROR(INDEX(tQueue[DisputedBalance],MATCH(23,Calc!$C$28:$C$299,0)),"") -> 0 | K32: =IFERROR(INDEX(tQueue[CollectableExposure],MATCH(23,Calc!$C$28:$C$299,0)),"") -> 7033.87 | L32: =IFERROR(INDEX(tQueue[OldestDaysPastDue],MATCH(23,Calc!$C$28:$C$299,0)),"") -> 185 | M32: =IFERROR(INDEX(tQueue[CreditUtilizationPct],MATCH(23,Calc!$C$28:$C$299,0)),"") -> 19.02 | N32: =IFERROR(INDEX(tQueue[CreditHoldFlag],MATCH(23,Calc!$C$28:$C$299,0)),"") -> 0 | O32: =IFERROR(INDEX(tQueue[ActionCode],MATCH(23,Calc!$C$28:$C$299,0)),"") -> FINAL_NOTICE | P32: =IFERROR(INDEX(tQueue[RecommendedAction],MATCH(23,Calc!$C$28:$C$299,0)),"") -> Issue a final notice on the 90+ balance and confirm a payment date in writing.
A33: =IF(24>MIN(QueueRowsShown,$F$4),"",24) -> 24 | B33: =IFERROR(INDEX(tQueue[CustomerName],MATCH(24,Calc!$C$28:$C$299,0)),"") -> Northfield Machine Works | C33: =IFERROR(INDEX(tQueue[Segment],MATCH(24,Calc!$C$28:$C$299,0)),"") -> OEM Manufacturer | D33: =IFERROR(INDEX(tQueue[RiskTier],MATCH(24,Calc!$C$28:$C$299,0)),"") -> High | E33: =IFERROR(INDEX(tQueue[CollectorName],MATCH(24,Calc!$C$28:$C$299,0)),"") -> Marcus Bell | F33: =IFERROR(INDEX(tQueue[TermsCode],MATCH(24,Calc!$C$28:$C$299,0)),"") -> NET60 | G33: =IFERROR(INDEX(tQueue[OpenBalance],MATCH(24,Calc!$C$28:$C$299,0)),"") -> 50863.84 | H33: =IFERROR(INDEX(tQueue[PastDueBalance],MATCH(24,Calc!$C$28:$C$299,0)),"") -> 21628.98 | I33: =IFERROR(INDEX(tQueue[Balance90Plus],MATCH(24,Calc!$C$28:$C$299,0)),"") -> 0 | J33: =IFERROR(INDEX(tQueue[DisputedBalance],MATCH(24,Calc!$C$28:$C$299,0)),"") -> 16359.42 | K33: =IFERROR(INDEX(tQueue[CollectableExposure],MATCH(24,Calc!$C$28:$C$299,0)),"") -> 6762.21 | L33: =IFERROR(INDEX(tQueue[OldestDaysPastDue],MATCH(24,Calc!$C$28:$C$299,0)),"") -> 33 | M33: =IFERROR(INDEX(tQueue[CreditUtilizationPct],MATCH(24,Calc!$C$28:$C$299,0)),"") -> 31.79 | N33: =IFERROR(INDEX(tQueue[CreditHoldFlag],MATCH(24,Calc!$C$28:$C$299,0)),"") -> 0 | O33: =IFERROR(INDEX(tQueue[ActionCode],MATCH(24,Calc!$C$28:$C$299,0)),"") -> RESOLVE_DISPUTE | P33: =IFERROR(INDEX(tQueue[RecommendedAction],MATCH(24,Calc!$C$28:$C$299,0)),"") -> Route to billing/sales: most of this balance is disputed and will not pay until the dispute closes.
A34: =IF(25>MIN(QueueRowsShown,$F$4),"",25) -> 25 | B34: =IFERROR(INDEX(tQueue[CustomerName],MATCH(25,Calc!$C$28:$C$299,0)),"") -> Ironbridge Medical Center - Northeast | C34: =IFERROR(INDEX(tQueue[Segment],MATCH(25,Calc!$C$28:$C$299,0)),"") -> Institutional | D34: =IFERROR(INDEX(tQueue[RiskTier],MATCH(25,Calc!$C$28:$C$299,0)),"") -> Low | E34: =IFERROR(INDEX(tQueue[CollectorName],MATCH(25,Calc!$C$28:$C$299,0)),"") -> Marcus Bell | F34: =IFERROR(INDEX(tQueue[TermsCode],MATCH(25,Calc!$C$28:$C$299,0)),"") -> NET90 | G34: =IFERROR(INDEX(tQueue[OpenBalance],MATCH(25,Calc!$C$28:$C$299,0)),"") -> 44688.48 | H34: =IFERROR(INDEX(tQueue[PastDueBalance],MATCH(25,Calc!$C$28:$C$299,0)),"") -> 25939.03 | I34: =IFERROR(INDEX(tQueue[Balance90Plus],MATCH(25,Calc!$C$28:$C$299,0)),"") -> 0 | J34: =IFERROR(INDEX(tQueue[DisputedBalance],MATCH(25,Calc!$C$28:$C$299,0)),"") -> 0 | K34: =IFERROR(INDEX(tQueue[CollectableExposure],MATCH(25,Calc!$C$28:$C$299,0)),"") -> 6484.76 | L34: =IFERROR(INDEX(tQueue[OldestDaysPastDue],MATCH(25,Calc!$C$28:$C$299,0)),"") -> 20 | M34: =IFERROR(INDEX(tQueue[CreditUtilizationPct],MATCH(25,Calc!$C$28:$C$299,0)),"") -> 28.83 | N34: =IFERROR(INDEX(tQueue[CreditHoldFlag],MATCH(25,Calc!$C$28:$C$299,0)),"") -> 0 | O34: =IFERROR(INDEX(tQueue[ActionCode],MATCH(25,Calc!$C$28:$C$299,0)),"") -> STANDARD_DUNNING | P34: =IFERROR(INDEX(tQueue[RecommendedAction],MATCH(25,Calc!$C$28:$C$299,0)),"") -> Standard dunning letter and follow-up call.

Sheet Cash Application
A1: CASH APPLICATION WORKLIST
A2: Money already in the bank that nobody has matched to an invoice. Until it is applied, these invoices read as unpaid and the call list will chase customers who have already paid.
B4: Accounts holding unapplied cash | F4: =COUNTA(tCashApp[CustomerID]) -> 97
B5: Cash banked and unmatched | F5: =SUM(tCashApp[UnappliedCash]) -> 419392.13
B6: Of which fully unapplied receipts | F6: =SUM(tCashApp[FullyUnappliedReceipts]) -> 57
B7: Past due that would be WRONGLY chased | F7: =SUM(tCashApp[WronglyChaseable]) -> 409639.85 | H7: ="This is cash Vantage already holds -- recovering it needs no customer conversation at all." -> This is cash Vantage already holds -- recovering it needs no customer conversation at all.
B8: Oldest unmatched receipt (days) | F8: =MAX(tCashApp[OldestUnappliedDays]) -> 679
A10: # | B10: Customer | C10: Segment | D10: Region | E10: Collector | F10: Unapplied cash | G10: Receipts | H10: Fully unapplied | I10: No remittance | J10: Oldest days | K10: Open balance | L10: Past due | M10: Net exposure | N10: Wrongly chaseable | O10: Root cause
A11: =IF(1>COUNTA(tCashApp[CustomerID]),"",1) -> 1 | B11: =IFERROR(INDEX(tCashApp[CustomerName],1),"") -> Pioneer Manufacturing | C11: =IFERROR(INDEX(tCashApp[Segment],1),"") -> OEM Manufacturer | D11: =IFERROR(INDEX(tCashApp[Region],1),"") -> Northeast | E11: =IFERROR(INDEX(tCashApp[CollectorName],1),"") -> Priya Natarajan | F11: =IFERROR(INDEX(tCashApp[UnappliedCash],1),"") -> 3702.23 | G11: =IFERROR(INDEX(tCashApp[UnappliedReceipts],1),"") -> 2 | H11: =IFERROR(INDEX(tCashApp[FullyUnappliedReceipts],1),"") -> 1 | I11: =IFERROR(INDEX(tCashApp[NoRemittanceAdvice],1),"") -> 2 | J11: =IFERROR(INDEX(tCashApp[OldestUnappliedDays],1),"") -> 679 | K11: =IFERROR(INDEX(tCashApp[OpenBalance],1),"") -> 65312.72 | L11: =IFERROR(INDEX(tCashApp[PastDueBalance],1),"") -> 3702.23 | M11: =IFERROR(INDEX(tCashApp[NetExposure],1),"") -> 61610.49 | N11: =IFERROR(INDEX(tCashApp[WronglyChaseable],1),"") -> 3702.23 | O11: =IFERROR(IF(INDEX(tCashApp[NoRemittanceAdvice],1)>0,"No remittance advice -- request it, then apply","Advice received; the cash simply has not been matched"),"") -> No remittance advice -- request it, then apply
A12: =IF(2>COUNTA(tCashApp[CustomerID]),"",2) -> 2 | B12: =IFERROR(INDEX(tCashApp[CustomerName],2),"") -> Silverline Fabrication - Southwest | C12: =IFERROR(INDEX(tCashApp[Segment],2),"") -> OEM Manufacturer | D12: =IFERROR(INDEX(tCashApp[Region],2),"") -> Southwest | E12: =IFERROR(INDEX(tCashApp[CollectorName],2),"") -> Priya Natarajan | F12: =IFERROR(INDEX(tCashApp[UnappliedCash],2),"") -> 10190.22 | G12: =IFERROR(INDEX(tCashApp[UnappliedReceipts],2),"") -> 2 | H12: =IFERROR(INDEX(tCashApp[FullyUnappliedReceipts],2),"") -> 1 | I12: =IFERROR(INDEX(tCashApp[NoRemittanceAdvice],2),"") -> 2 | J12: =IFERROR(INDEX(tCashApp[OldestUnappliedDays],2),"") -> 668 | K12: =IFERROR(INDEX(tCashApp[OpenBalance],2),"") -> 120937.72 | L12: =IFERROR(INDEX(tCashApp[PastDueBalance],2),"") -> 26147.37 | M12: =IFERROR(INDEX(tCashApp[NetExposure],2),"") -> 110747.5 | N12: =IFERROR(INDEX(tCashApp[WronglyChaseable],2),"") -> 10190.22 | O12: =IFERROR(IF(INDEX(tCashApp[NoRemittanceAdvice],2)>0,"No remittance advice -- request it, then apply","Advice received; the cash simply has not been matched"),"") -> No remittance advice -- request it, then apply
A13: =IF(3>COUNTA(tCashApp[CustomerID]),"",3) -> 3 | B13: =IFERROR(INDEX(tCashApp[CustomerName],3),"") -> Granite MRO Services | C13: =IFERROR(INDEX(tCashApp[Segment],3),"") -> MRO Reseller | D13: =IFERROR(INDEX(tCashApp[Region],3),"") -> Southeast | E13: =IFERROR(INDEX(tCashApp[CollectorName],3),"") -> Grace Lindqvist | F13: =IFERROR(INDEX(tCashApp[UnappliedCash],3),"") -> 504.6 | G13: =IFERROR(INDEX(tCashApp[UnappliedReceipts],3),"") -> 1 | H13: =IFERROR(INDEX(tCashApp[FullyUnappliedReceipts],3),"") -> 1 | I13: =IFERROR(INDEX(tCashApp[NoRemittanceAdvice],3),"") -> 1 | J13: =IFERROR(INDEX(tCashApp[OldestUnappliedDays],3),"") -> 652 | K13: =IFERROR(INDEX(tCashApp[OpenBalance],3),"") -> 2847.25 | L13: =IFERROR(INDEX(tCashApp[PastDueBalance],3),"") -> 1339.14 | M13: =IFERROR(INDEX(tCashApp[NetExposure],3),"") -> 2342.65 | N13: =IFERROR(INDEX(tCashApp[WronglyChaseable],3),"") -> 504.6 | O13: =IFERROR(IF(INDEX(tCashApp[NoRemittanceAdvice],3)>0,"No remittance advice -- request it, then apply","Advice received; the cash simply has not been matched"),"") -> No remittance advice -- request it, then apply
A14: =IF(4>COUNTA(tCashApp[CustomerID]),"",4) -> 4 | B14: =IFERROR(INDEX(tCashApp[CustomerName],4),"") -> Lakeshore MRO Services - Midwest | C14: =IFERROR(INDEX(tCashApp[Segment],4),"") -> MRO Reseller | D14: =IFERROR(INDEX(tCashApp[Region],4),"") -> Midwest | E14: =IFERROR(INDEX(tCashApp[CollectorName],4),"") -> Sam Horowitz | F14: =IFERROR(INDEX(tCashApp[UnappliedCash],4),"") -> 4202.45 | G14: =IFERROR(INDEX(tCashApp[UnappliedReceipts],4),"") -> 2 | H14: =IFERROR(INDEX(tCashApp[FullyUnappliedReceipts],4),"") -> 1 | I14: =IFERROR(INDEX(tCashApp[NoRemittanceAdvice],4),"") -> 2 | J14: =IFERROR(INDEX(tCashApp[OldestUnappliedDays],4),"") -> 652 | K14: =IFERROR(INDEX(tCashApp[OpenBalance],4),"") -> 4212.75 | L14: =IFERROR(INDEX(tCashApp[PastDueBalance],4),"") -> 4212.75 | M14: =IFERROR(INDEX(tCashApp[NetExposure],4),"") -> 10.3 | N14: =IFERROR(INDEX(tCashApp[WronglyChaseable],4),"") -> 4202.45 | O14: =IFERROR(IF(INDEX(tCashApp[NoRemittanceAdvice],4)>0,"No remittance advice -- request it, then apply","Advice received; the cash simply has not been matched"),"") -> No remittance advice -- request it, then apply
A15: =IF(5>COUNTA(tCashApp[CustomerID]),"",5) -> 5 | B15: =IFERROR(INDEX(tCashApp[CustomerName],5),"") -> Harbor Fabrication | C15: =IFERROR(INDEX(tCashApp[Segment],5),"") -> OEM Manufacturer | D15: =IFERROR(INDEX(tCashApp[Region],5),"") -> West | E15: =IFERROR(INDEX(tCashApp[CollectorName],5),"") -> Priya Natarajan | F15: =IFERROR(INDEX(tCashApp[UnappliedCash],5),"") -> 12428.36 | G15: =IFERROR(INDEX(tCashApp[UnappliedReceipts],5),"") -> 1 | H15: =IFERROR(INDEX(tCashApp[FullyUnappliedReceipts],5),"") -> 0 | I15: =IFERROR(INDEX(tCashApp[NoRemittanceAdvice],5),"") -> 1 | J15: =IFERROR(INDEX(tCashApp[OldestUnappliedDays],5),"") -> 647 | K15: =IFERROR(INDEX(tCashApp[OpenBalance],5),"") -> 103438.85 | L15: =IFERROR(INDEX(tCashApp[PastDueBalance],5),"") -> 34815.87 | M15: =IFERROR(INDEX(tCashApp[NetExposure],5),"") -> 91010.49 | N15: =IFERROR(INDEX(tCashApp[WronglyChaseable],5),"") -> 12428.36 | O15: =IFERROR(IF(INDEX(tCashApp[NoRemittanceAdvice],5)>0,"No remittance advice -- request it, then apply","Advice received; the cash simply has not been matched"),"") -> No remittance advice -- request it, then apply
